File: !!!Рисунки/Магнитная восприимчивость/Cu3SbS3_206_4_m_61_21mg_H_1000_Oe_m_T_2_rso.dat
[Header]
TITLE,MPMS RSO Measurement
BYAPP,MPMS Measurement,1.1,Summary
FILEOPENTIME, 1438336434.390000 7/31/2015, 2:53:54 PM

INFO, APPNAME, MPMS MultiVu Application, Revision 1.58,  Build 076

INFO, NAME, Unnamed
INFO, WEIGHT, 1.000
INFO, AREA, 1.000
INFO, LENGTH, 1.000
INFO, SHAPE, 0
INFO, COMMENT,
INFO, SEQUENCE FILE: m(T).seq


INFO, BACKGROUND DATA FILE:, None


STARTUPAXIS,X,4,LINEAR,AUTO,0.000000,0.000000
STARTUPAXIS,Y1,5,LINEAR,AUTO,0.000000,0.000000


STARTUPGROUP,Longitudinal
FIELDGROUP,Longitudinal,1,2,3,4,5,6,7,8,9,10,11,19,20,21,22,23,35
FIELDGROUP,Transverse,1,2,3,4,12,13,14,15,16,17,18,24,25,26,27,28,35

PLOT_APPEARANCE,ALL,HORZ_GRID_ON,VERT_GRID_ON,MARKERS_AND_LINES

[Data]
Time,Comment,Field (Oe),Temperature (K),Long Moment (emu),Long Scan Std Dev,Long Offset (cm),Long Offset Std Dev,Long Algorithm,Long Reg Fit,Long Reg Factor,Trans Moment (emu),Trans Scan Std Dev,Trans Offset (cm),Trans Offset Std Dev,Trans Algorithm,Trans Reg Fit,Trans Reg Factor,Long Moment [w/o ABS] (emu),Long Scan Std Dev [w/o ABS],Long Offset [w/o ABS] (cm),Long Offset Std Dev [w/o ABS],Long Reg Fit [w/o ABS],Trans Moment [w/o ABS] (emu),Trans Scan Std Dev [w/o ABS],Trans Offset [w/o ABS] (cm),Trans Offset Std Dev [w/o ABS],Trans Reg Fit [w/o ABS],RSO Position (deg),Amplitude (cm),Frequency,Cycles to Average,Scans per Measurement,Delta Temp (K),Error,EC Comp. Running,Using ABS,
1438336434.390,,9.999999e+002,1.999568e+000,3.435513e-005,0.000000e+000,8.446981e-004,0.000000e+000,3,9.745428e-001,1.825000e+000,,,,,,,,,,,,,,,,,,0,4.000000e+000,1.000000e+000,20,1,3.304005e-003,0,0,0,
1438336594.203,,9.999999e+002,4.129124e+000,1.601563e-005,0.000000e+000,-4.186587e-002,0.000000e+000,3,9.508091e-001,1.825000e+000,,,,,,,,,,,,,,,,,,0,4.000000e+000,1.000000e+000,20,1,1.374049e-001,0,1,0,
1438336683.906,,9.999999e+002,6.337474e+000,1.012994e-005,0.000000e+000,-9.139418e-002,0.000000e+000,3,9.268041e-001,1.825000e+000,,,,,,,,,,,,,,,,,,0,4.000000e+000,1.000000e+000,20,1,5.938139e-001,0,1,0,
1438336764.703,,9.999999e+002,8.384188e+000,7.073803e-006,0.000000e+000,-1.519169e-001,0.000000e+000,3,8.983358e-001,1.825000e+000,,,,,,,,,,,,,,,,,,0,4.000000e+000,1.000000e+000,20,1,6.142397e-001,0,1,0,
1438336853.062,,9.999999e+002,1.050364e+001,5.083020e-006,0.000000e+000,-2.441306e-001,0.000000e+000,3,8.679349e-001,1.825000e+000,,,,,,,,,,,,,,,,,,0,4.000000e+000,1.000000e+000,20,1,6.071997e-001,0,1,0,
1438336933.172,,9.999999e+002,1.240745e+001,3.965816e-006,0.000000e+000,-3.520888e-001,0.000000e+000,3,8.438144e-001,1.825000e+000,,,,,,,,,,,,,,,,,,0,4.000000e+000,1.000000e+000,20,1,6.318197e-001,0,0,0,
1438337020.078,,9.999999e+002,1.451893e+001,3.270477e-006,0.000000e+000,-4.879846e-001,0.000000e+000,3,8.399700e-001,1.825000e+000,,,,,,,,,,,,,,,,,,0,4.000000e+000,1.000000e+000,20,1,6.337595e-001,0,0,0,
1438337100.875,,9.999999e+002,1.640617e+001,2.941445e-006,0.000000e+000,-6.171420e-001,0.000000e+000,3,8.446300e-001,1.825000e+000,,,,,,,,,,,,,,,,,,0,4.000000e+000,1.000000e+000,20,1,6.451893e-001,0,0,0,
1438337182.922,,9.999999e+002,1.845541e+001,2.809705e-006,0.000000e+000,-7.361391e-001,0.000000e+000,3,8.620045e-001,1.825000e+000,,,,,,,,,,,,,,,,,,0,4.000000e+000,1.000000e+000,20,1,6.317501e-001,0,0,0,
1438337263.375,,9.999999e+002,2.040058e+001,4.398232e-007,0.000000e+000,0.000000e+000,0.000000e+000,3,0.000000e+000,1.825000e+000,,,,,,,,,,,,,,,,,,0,4.000000e+000,1.000000e+000,20,1,6.748791e-001,0,0,0,
1438337348.437,,9.999999e+002,2.250076e+001,-2.421386e-006,0.000000e+000,1.008555e+000,0.000000e+000,3,5.536771e-001,1.825000e+000,,,,,,,,,,,,,,,,,,0,4.000000e+000,1.000000e+000,20,1,5.563087e-001,0,0,0,
1438337432.765,,9.999999e+002,2.457913e+001,-2.391658e-007,0.000000e+000,0.000000e+000,0.000000e+000,3,0.000000e+000,1.825000e+000,,,,,,,,,,,,,,,,,,0,4.000000e+000,1.000000e+000,20,1,6.318207e-001,0,0,0,
1438337511.312,,9.999999e+002,2.655924e+001,-2.462149e-006,0.000000e+000,9.006224e-001,0.000000e+000,3,5.768234e-001,1.825000e+000,,,,,,,,,,,,,,,,,,0,4.000000e+000,1.000000e+000,20,1,6.262398e-001,0,1,0,
1438337584.968,,9.999999e+002,2.841824e+001,-2.518762e-006,0.000000e+000,8.603948e-001,0.000000e+000,3,5.830227e-001,1.825000e+000,,,,,,,,,,,,,,,,,,0,4.000000e+000,1.000000e+000,20,1,6.516399e-001,0,1,0,
1438337666.250,,9.999999e+002,3.042165e+001,-2.555507e-006,0.000000e+000,8.110502e-001,0.000000e+000,3,5.895283e-001,1.825000e+000,,,,,,,,,,,,,,,,,,0,4.000000e+000,1.000000e+000,20,1,5.916786e-001,0,1,0,
1438337752.047,,9.999999e+002,3.250976e+001,-2.604824e-006,0.000000e+000,7.773019e-001,0.000000e+000,3,6.004337e-001,1.825000e+000,,,,,,,,,,,,,,,,,,0,4.000000e+000,1.000000e+000,20,1,5.721779e-001,0,1,0,
1438337836.093,,9.999999e+002,3.448226e+001,-2.650016e-006,0.000000e+000,7.472110e-001,0.000000e+000,3,6.134837e-001,1.825000e+000,,,,,,,,,,,,,,,,,,0,4.000000e+000,1.000000e+000,20,1,6.236992e-001,0,1,0,
1438337915.703,,9.999999e+002,3.638508e+001,-2.697568e-006,0.000000e+000,7.252438e-001,0.000000e+000,3,6.241334e-001,1.825000e+000,,,,,,,,,,,,,,,,,,0,4.000000e+000,1.000000e+000,20,1,6.666794e-001,0,0,0,
1438338002.250,,9.999999e+002,3.848065e+001,-2.718633e-006,0.000000e+000,7.053621e-001,0.000000e+000,3,6.285527e-001,1.825000e+000,,,,,,,,,,,,,,,,,,0,4.000000e+000,1.000000e+000,20,1,6.610603e-001,0,0,0,
1438338081.797,,9.999999e+002,4.037969e+001,-2.763351e-006,0.000000e+000,6.861636e-001,0.000000e+000,3,6.394899e-001,1.825000e+000,,,,,,,,,,,,,,,,,,0,4.000000e+000,1.000000e+000,20,1,6.169701e-001,0,0,0,
1438338164.422,,9.999999e+002,4.256456e+001,-2.795220e-006,0.000000e+000,6.706276e-001,0.000000e+000,3,6.443861e-001,1.825000e+000,,,,,,,,,,,,,,,,,,0,4.000000e+000,1.000000e+000,20,1,6.469498e-001,0,0,0,
1438338241.250,,9.999999e+002,4.445050e+001,-2.834262e-006,0.000000e+000,6.437049e-001,0.000000e+000,3,6.529409e-001,1.825000e+000,,,,,,,,,,,,,,,,,,0,4.000000e+000,1.000000e+000,20,1,6.802979e-001,0,0,0,
1438338321.047,,9.999999e+002,4.643771e+001,-2.889422e-006,0.000000e+000,6.262332e-001,0.000000e+000,3,6.564901e-001,1.825000e+000,,,,,,,,,,,,,,,,,,0,4.000000e+000,1.000000e+000,20,1,6.006699e-001,0,0,0,
1438338404.843,,9.999999e+002,4.846614e+001,-2.935129e-006,0.000000e+000,6.022265e-001,0.000000e+000,3,6.658989e-001,1.825000e+000,,,,,,,,,,,,,,,,,,0,4.000000e+000,1.000000e+000,20,1,6.078491e-001,0,0,0,
1438338490.468,,9.999999e+002,5.057531e+001,-2.992378e-006,0.000000e+000,5.831388e-001,0.000000e+000,3,6.730812e-001,1.825000e+000,,,,,,,,,,,,,,,,,,0,4.000000e+000,1.000000e+000,20,1,5.736771e-001,0,1,0,
1438338567.843,,9.999999e+002,5.242304e+001,-3.059862e-006,0.000000e+000,5.689124e-001,0.000000e+000,3,6.783316e-001,1.825000e+000,,,,,,,,,,,,,,,,,,0,4.000000e+000,1.000000e+000,20,1,6.268005e-001,0,1,0,
1438338649.375,,9.999999e+002,5.450150e+001,-3.092675e-006,0.000000e+000,5.498081e-001,0.000000e+000,3,6.849015e-001,1.825000e+000,,,,,,,,,,,,,,,,,,0,4.000000e+000,1.000000e+000,20,1,6.333389e-001,0,1,0,
1438338723.922,,9.999999e+002,5.631895e+001,-3.120541e-006,0.000000e+000,5.392535e-001,0.000000e+000,3,6.847799e-001,1.825000e+000,,,,,,,,,,,,,,,,,,0,4.000000e+000,1.000000e+000,20,1,6.357307e-001,0,1,0,
1438338844.172,,9.999999e+002,5.928733e+001,-3.124982e-006,0.000000e+000,5.409657e-001,0.000000e+000,3,6.848277e-001,1.825000e+000,,,,,,,,,,,,,,,,,,0,4.000000e+000,1.000000e+000,20,1,6.334000e-001,0,1,0,
1438338890.984,,9.999999e+002,6.047570e+001,-3.101105e-006,0.000000e+000,5.471985e-001,0.000000e+000,3,6.861838e-001,1.825000e+000,,,,,,,,,,,,,,,,,,0,4.000000e+000,1.000000e+000,20,1,6.279907e-001,0,0,0,
1438338971.031,,9.999999e+002,6.242769e+001,-3.077548e-006,0.000000e+000,5.613479e-001,0.000000e+000,3,6.816651e-001,1.825000e+000,,,,,,,,,,,,,,,,,,0,4.000000e+000,1.000000e+000,20,1,5.736198e-001,0,0,0,
1438339053.375,,9.999999e+002,6.439589e+001,-3.004975e-006,0.000000e+000,5.816339e-001,0.000000e+000,3,6.698776e-001,1.825000e+000,,,,,,,,,,,,,,,,,,0,4.000000e+000,1.000000e+000,20,1,6.365356e-001,0,0,0,
1438339131.156,,9.999999e+002,6.629542e+001,-2.945928e-006,0.000000e+000,6.132332e-001,0.000000e+000,3,6.612927e-001,1.825000e+000,,,,,,,,,,,,,,,,,,0,4.000000e+000,1.000000e+000,20,1,5.857697e-001,0,0,0,
1438339219.265,,9.999999e+002,6.850891e+001,-2.834922e-006,0.000000e+000,6.563949e-001,0.000000e+000,3,6.461016e-001,1.825000e+000,,,,,,,,,,,,,,,,,,0,4.000000e+000,1.000000e+000,20,1,5.645752e-001,0,0,0,
1438339303.062,,9.999999e+002,7.050307e+001,-2.742409e-006,0.000000e+000,7.201267e-001,0.000000e+000,3,6.286663e-001,1.825000e+000,,,,,,,,,,,,,,,,,,0,4.000000e+000,1.000000e+000,20,1,6.805267e-001,0,0,0,
1438339379.156,,9.999999e+002,7.233505e+001,-2.645368e-006,0.000000e+000,7.943572e-001,0.000000e+000,3,6.034039e-001,1.825000e+000,,,,,,,,,,,,,,,,,,0,4.000000e+000,1.000000e+000,20,1,5.929337e-001,0,0,0,
1438339468.203,,9.999999e+002,7.459759e+001,-2.542274e-006,0.000000e+000,9.114183e-001,0.000000e+000,3,5.700281e-001,1.825000e+000,,,,,,,,,,,,,,,,,,0,4.000000e+000,1.000000e+000,20,1,6.234589e-001,0,1,0,
1438339539.797,,9.999999e+002,7.641213e+001,8.758764e-008,0.000000e+000,0.000000e+000,0.000000e+000,3,0.000000e+000,1.825000e+000,,,,,,,,,,,,,,,,,,0,4.000000e+000,1.000000e+000,20,1,6.660004e-001,0,1,0,
1438339617.593,,9.999999e+002,7.839264e+001,2.922081e-006,0.000000e+000,-7.458215e-001,0.000000e+000,3,8.779696e-001,1.825000e+000,,,,,,,,,,,,,,,,,,0,4.000000e+000,1.000000e+000,20,1,6.123962e-001,0,1,0,
1438339702.390,,9.999999e+002,8.048497e+001,3.222721e-006,0.000000e+000,-5.616767e-001,0.000000e+000,3,8.504174e-001,1.825000e+000,,,,,,,,,,,,,,,,,,0,4.000000e+000,1.000000e+000,20,1,5.411224e-001,0,1,0,
1438339778.218,,9.999999e+002,8.235838e+001,3.519960e-006,0.000000e+000,-4.655958e-001,0.000000e+000,3,8.435005e-001,1.825000e+000,,,,,,,,,,,,,,,,,,0,4.000000e+000,1.000000e+000,20,1,6.015701e-001,0,1,0,
1438339863.765,,9.999999e+002,8.436974e+001,3.770439e-006,0.000000e+000,-4.250444e-001,0.000000e+000,3,8.476068e-001,1.825000e+000,,,,,,,,,,,,,,,,,,0,4.000000e+000,1.000000e+000,20,1,5.489578e-001,0,1,0,
1438339955.625,,9.999999e+002,8.658781e+001,3.878388e-006,0.000000e+000,-3.975831e-001,0.000000e+000,3,8.418353e-001,1.825000e+000,,,,,,,,,,,,,,,,,,0,4.000000e+000,1.000000e+000,20,1,5.611877e-001,0,0,0,
1438340031.922,,9.999999e+002,8.841145e+001,4.003993e-006,0.000000e+000,-3.804573e-001,0.000000e+000,3,8.491106e-001,1.825000e+000,,,,,,,,,,,,,,,,,,0,4.000000e+000,1.000000e+000,20,1,5.740738e-001,0,0,0,
1438340112.781,,9.999999e+002,9.046992e+001,4.122324e-006,0.000000e+000,-3.629333e-001,0.000000e+000,3,8.511205e-001,1.825000e+000,,,,,,,,,,,,,,,,,,0,4.000000e+000,1.000000e+000,20,1,6.274033e-001,0,0,0,
1438340185.828,,9.999999e+002,9.230821e+001,4.221492e-006,0.000000e+000,-3.481498e-001,0.000000e+000,3,8.509853e-001,1.825000e+000,,,,,,,,,,,,,,,,,,0,4.000000e+000,1.000000e+000,20,1,6.043091e-001,0,0,0,
1438340268.422,,9.999999e+002,9.437804e+001,4.318559e-006,0.000000e+000,-3.373861e-001,0.000000e+000,3,8.505357e-001,1.825000e+000,,,,,,,,,,,,,,,,,,0,4.000000e+000,1.000000e+000,20,1,6.318283e-001,0,0,0,
1438340354.468,,9.999999e+002,9.647498e+001,4.387435e-006,0.000000e+000,-3.273199e-001,0.000000e+000,3,8.494838e-001,1.825000e+000,,,,,,,,,,,,,,,,,,0,4.000000e+000,1.000000e+000,20,1,5.653687e-001,0,0,0,
1438340437.531,,9.999999e+002,9.849149e+001,4.458879e-006,0.000000e+000,-3.194793e-001,0.000000e+000,3,8.475164e-001,1.825000e+000,,,,,,,,,,,,,,,,,,0,4.000000e+000,1.000000e+000,20,1,5.697250e-001,0,1,0,
1438340517.578,,9.999999e+002,1.004246e+002,4.524531e-006,0.000000e+000,-3.145801e-001,0.000000e+000,3,8.485528e-001,1.825000e+000,,,,,,,,,,,,,,,,,,0,4.000000e+000,1.000000e+000,20,1,6.444016e-001,0,1,0,
1438340597.672,,9.999999e+002,1.024358e+002,4.571198e-006,0.000000e+000,-3.056481e-001,0.000000e+000,3,8.446498e-001,1.825000e+000,,,,,,,,,,,,,,,,,,0,4.000000e+000,1.000000e+000,20,1,6.055984e-001,0,1,0,
1438340680.218,,9.999999e+002,1.044697e+002,4.603540e-006,0.000000e+000,-3.018417e-001,0.000000e+000,3,8.457476e-001,1.825000e+000,,,,,,,,,,,,,,,,,,0,4.000000e+000,1.000000e+000,20,1,6.210938e-001,0,1,0,
1438340760.047,,9.999999e+002,1.063621e+002,4.638413e-006,0.000000e+000,-2.982254e-001,0.000000e+000,3,8.424213e-001,1.825000e+000,,,,,,,,,,,,,,,,,,0,4.000000e+000,1.000000e+000,20,1,6.049957e-001,0,1,0,
1438340844.093,,9.999999e+002,1.084995e+002,4.680452e-006,0.000000e+000,-2.996910e-001,0.000000e+000,3,8.507280e-001,1.825000e+000,,,,,,,,,,,,,,,,,,0,4.000000e+000,1.000000e+000,20,1,5.926971e-001,0,1,0,
1438340926.218,,9.999999e+002,1.105660e+002,4.696790e-006,0.000000e+000,-2.948467e-001,0.000000e+000,3,8.449914e-001,1.825000e+000,,,,,,,,,,,,,,,,,,0,4.000000e+000,1.000000e+000,20,1,6.278000e-001,0,1,0,
1438341000.781,,9.999999e+002,1.123209e+002,4.683284e-006,0.000000e+000,-2.954185e-001,0.000000e+000,3,8.393940e-001,1.825000e+000,,,,,,,,,,,,,,,,,,0,4.000000e+000,1.000000e+000,20,1,6.179962e-001,0,0,0,
1438341089.593,,9.999999e+002,1.145041e+002,4.703079e-006,0.000000e+000,-2.946796e-001,0.000000e+000,3,8.426791e-001,1.825000e+000,,,,,,,,,,,,,,,,,,0,4.000000e+000,1.000000e+000,20,1,5.772018e-001,0,0,0,
1438341164.672,,9.999999e+002,1.163325e+002,4.712477e-006,0.000000e+000,-2.948988e-001,0.000000e+000,3,8.415799e-001,1.825000e+000,,,,,,,,,,,,,,,,,,0,4.000000e+000,1.000000e+000,20,1,5.979004e-001,0,0,0,
1438341245.750,,9.999999e+002,1.183562e+002,4.704811e-006,0.000000e+000,-2.938644e-001,0.000000e+000,3,8.400671e-001,1.825000e+000,,,,,,,,,,,,,,,,,,0,4.000000e+000,1.000000e+000,20,1,6.614990e-001,0,0,0,
1438341331.047,,9.999999e+002,1.204256e+002,4.712752e-006,0.000000e+000,-2.967652e-001,0.000000e+000,3,8.421040e-001,1.825000e+000,,,,,,,,,,,,,,,,,,0,4.000000e+000,1.000000e+000,20,1,6.323013e-001,0,0,0,
1438341419.843,,9.999999e+002,1.225834e+002,4.692223e-006,0.000000e+000,-2.983196e-001,0.000000e+000,3,8.412125e-001,1.825000e+000,,,,,,,,,,,,,,,,,,0,4.000000e+000,1.000000e+000,20,1,6.184998e-001,0,0,0,
1438341492.281,,9.999999e+002,1.243580e+002,4.677979e-006,0.000000e+000,-2.995531e-001,0.000000e+000,3,8.381611e-001,1.825000e+000,,,,,,,,,,,,,,,,,,0,4.000000e+000,1.000000e+000,20,1,6.436996e-001,0,0,0,
1438341571.828,,9.999999e+002,1.264494e+002,4.682928e-006,0.000000e+000,-3.005691e-001,0.000000e+000,3,8.330932e-001,1.825000e+000,,,,,,,,,,,,,,,,,,0,4.000000e+000,1.000000e+000,20,1,5.904007e-001,0,1,0,
1438341650.156,,9.999999e+002,1.283547e+002,4.668542e-006,0.000000e+000,-3.025442e-001,0.000000e+000,3,8.351926e-001,1.825000e+000,,,,,,,,,,,,,,,,,,0,4.000000e+000,1.000000e+000,20,1,6.533966e-001,0,1,0,
1438341731.937,,9.999999e+002,1.303878e+002,4.658342e-006,0.000000e+000,-3.049319e-001,0.000000e+000,3,8.363771e-001,1.825000e+000,,,,,,,,,,,,,,,,,,0,4.000000e+000,1.000000e+000,20,1,5.802002e-001,0,1,0,
1438341815.812,,9.999999e+002,1.324545e+002,4.635969e-006,0.000000e+000,-3.080802e-001,0.000000e+000,3,8.347917e-001,1.825000e+000,,,,,,,,,,,,,,,,,,0,4.000000e+000,1.000000e+000,20,1,5.718994e-001,0,1,0,
1438341905.359,,9.999999e+002,1.345478e+002,4.638282e-006,0.000000e+000,-3.115471e-001,0.000000e+000,3,8.299925e-001,1.825000e+000,,,,,,,,,,,,,,,,,,0,4.000000e+000,1.000000e+000,20,1,6.190033e-001,0,1,0,
1438341983.656,,9.999999e+002,1.364071e+002,4.615395e-006,0.000000e+000,-3.149924e-001,0.000000e+000,3,8.346044e-001,1.825000e+000,,,,,,,,,,,,,,,,,,0,4.000000e+000,1.000000e+000,20,1,6.764069e-001,0,0,0,
1438342062.297,,9.999999e+002,1.383667e+002,4.578120e-006,0.000000e+000,-3.178146e-001,0.000000e+000,3,8.241340e-001,1.825000e+000,,,,,,,,,,,,,,,,,,0,4.000000e+000,1.000000e+000,20,1,5.863953e-001,0,0,0,
1438342146.093,,9.999999e+002,1.404993e+002,4.583146e-006,0.000000e+000,-3.203310e-001,0.000000e+000,3,8.259561e-001,1.825000e+000,,,,,,,,,,,,,,,,,,0,4.000000e+000,1.000000e+000,20,1,6.027985e-001,0,0,0,
1438342223.187,,9.999999e+002,1.423772e+002,4.565082e-006,0.000000e+000,-3.229299e-001,0.000000e+000,3,8.333184e-001,1.825000e+000,,,,,,,,,,,,,,,,,,0,4.000000e+000,1.000000e+000,20,1,6.231079e-001,0,0,0,
1438342309.750,,9.999999e+002,1.444449e+002,4.526227e-006,0.000000e+000,-3.263475e-001,0.000000e+000,3,8.276898e-001,1.825000e+000,,,,,,,,,,,,,,,,,,0,4.000000e+000,1.000000e+000,20,1,6.282043e-001,0,0,0,
1438342395.093,,9.999999e+002,1.465522e+002,4.500901e-006,0.000000e+000,-3.292488e-001,0.000000e+000,3,8.267576e-001,1.825000e+000,,,,,,,,,,,,,,,,,,0,4.000000e+000,1.000000e+000,20,1,5.794983e-001,0,0,0,
1438342470.390,,9.999999e+002,1.483958e+002,4.487604e-006,0.000000e+000,-3.312932e-001,0.000000e+000,3,8.293100e-001,1.825000e+000,,,,,,,,,,,,,,,,,,0,4.000000e+000,1.000000e+000,20,1,6.665039e-001,0,0,0,
1438342552.687,,9.999999e+002,1.503512e+002,4.459747e-006,0.000000e+000,-3.337207e-001,0.000000e+000,3,8.288350e-001,1.825000e+000,,,,,,,,,,,,,,,,,,0,4.000000e+000,1.000000e+000,20,1,5.825958e-001,0,1,0,
1438342641.547,,9.999999e+002,1.525125e+002,4.431541e-006,0.000000e+000,-3.386077e-001,0.000000e+000,3,8.235971e-001,1.825000e+000,,,,,,,,,,,,,,,,,,0,4.000000e+000,1.000000e+000,20,1,5.789032e-001,0,1,0,
1438342721.172,,9.999999e+002,1.543795e+002,4.428519e-006,0.000000e+000,-3.415198e-001,0.000000e+000,3,8.262473e-001,1.825000e+000,,,,,,,,,,,,,,,,,,0,4.000000e+000,1.000000e+000,20,1,6.446991e-001,0,1,0,
1438342802.718,,9.999999e+002,1.564444e+002,4.404853e-006,0.000000e+000,-3.459006e-001,0.000000e+000,3,8.238485e-001,1.825000e+000,,,,,,,,,,,,,,,,,,0,4.000000e+000,1.000000e+000,20,1,6.473083e-001,0,1,0,
1438342883.265,,9.999999e+002,1.585020e+002,4.347007e-006,0.000000e+000,-3.484131e-001,0.000000e+000,3,8.192233e-001,1.825000e+000,,,,,,,,,,,,,,,,,,0,4.000000e+000,1.000000e+000,20,1,6.010895e-001,0,1,0,
1438342956.328,,9.999999e+002,1.603103e+002,4.359887e-006,0.000000e+000,-3.507229e-001,0.000000e+000,3,8.227248e-001,1.825000e+000,,,,,,,,,,,,,,,,,,0,4.000000e+000,1.000000e+000,20,1,5.997009e-001,0,1,0,
1438343041.656,,9.999999e+002,1.623992e+002,4.308292e-006,0.000000e+000,-3.569767e-001,0.000000e+000,3,8.233387e-001,1.825000e+000,,,,,,,,,,,,,,,,,,0,4.000000e+000,1.000000e+000,20,1,6.217957e-001,0,0,0,
1438343120.937,,9.999999e+002,1.643255e+002,4.305989e-006,0.000000e+000,-3.628832e-001,0.000000e+000,3,8.218160e-001,1.825000e+000,,,,,,,,,,,,,,,,,,0,4.000000e+000,1.000000e+000,20,1,6.430969e-001,0,0,0,
1438343209.234,,9.999999e+002,1.665033e+002,4.256541e-006,0.000000e+000,-3.673640e-001,0.000000e+000,3,8.216061e-001,1.825000e+000,,,,,,,,,,,,,,,,,,0,4.000000e+000,1.000000e+000,20,1,6.289063e-001,0,0,0,
1438343288.343,,9.999999e+002,1.684142e+002,4.248007e-006,0.000000e+000,-3.721812e-001,0.000000e+000,3,8.192461e-001,1.825000e+000,,,,,,,,,,,,,,,,,,0,4.000000e+000,1.000000e+000,20,1,6.349030e-001,0,0,0,
1438343375.890,,9.999999e+002,1.705058e+002,4.204616e-006,0.000000e+000,-3.742226e-001,0.000000e+000,3,8.232763e-001,1.825000e+000,,,,,,,,,,,,,,,,,,0,4.000000e+000,1.000000e+000,20,1,6.181030e-001,0,0,0,
1438343457.937,,9.999999e+002,1.725413e+002,4.186741e-006,0.000000e+000,-3.792662e-001,0.000000e+000,3,8.193905e-001,1.825000e+000,,,,,,,,,,,,,,,,,,0,4.000000e+000,1.000000e+000,20,1,5.836029e-001,0,0,0,
1438343529.531,,9.999999e+002,1.743792e+002,4.156962e-006,0.000000e+000,-3.830782e-001,0.000000e+000,3,8.163542e-001,1.825000e+000,,,,,,,,,,,,,,,,,,0,4.000000e+000,1.000000e+000,20,1,6.367035e-001,0,0,0,
1438343609.656,,9.999999e+002,1.763935e+002,4.135081e-006,0.000000e+000,-3.846373e-001,0.000000e+000,3,8.164970e-001,1.825000e+000,,,,,,,,,,,,,,,,,,0,4.000000e+000,1.000000e+000,20,1,5.153961e-001,0,1,0,
1438343695.937,,9.999999e+002,1.784870e+002,4.118087e-006,0.000000e+000,-3.961878e-001,0.000000e+000,3,8.152071e-001,1.825000e+000,,,,,,,,,,,,,,,,,,0,4.000000e+000,1.000000e+000,20,1,5.444031e-001,0,1,0,
1438343779.015,,9.999999e+002,1.804517e+002,4.081958e-006,0.000000e+000,-3.978964e-001,0.000000e+000,3,8.106137e-001,1.825000e+000,,,,,,,,,,,,,,,,,,0,4.000000e+000,1.000000e+000,20,1,6.970062e-001,0,1,0,
1438343856.109,,9.999999e+002,1.823564e+002,4.040892e-006,0.000000e+000,-4.009418e-001,0.000000e+000,3,8.151522e-001,1.825000e+000,,,,,,,,,,,,,,,,,,0,4.000000e+000,1.000000e+000,20,1,7.068939e-001,0,1,0,
1438343936.515,,9.999999e+002,1.844143e+002,4.066187e-006,0.000000e+000,-4.035827e-001,0.000000e+000,3,8.185858e-001,1.825000e+000,,,,,,,,,,,,,,,,,,0,4.000000e+000,1.000000e+000,20,1,5.699921e-001,0,1,0,
1438344024.062,,9.999999e+002,1.865380e+002,4.034393e-006,0.000000e+000,-4.128143e-001,0.000000e+000,3,8.139609e-001,1.825000e+000,,,,,,,,,,,,,,,,,,0,4.000000e+000,1.000000e+000,20,1,5.731964e-001,0,0,0,
1438344094.843,,9.999999e+002,1.883495e+002,3.958794e-006,0.000000e+000,-4.136717e-001,0.000000e+000,3,8.124611e-001,1.825000e+000,,,,,,,,,,,,,,,,,,0,4.000000e+000,1.000000e+000,20,1,6.794891e-001,0,0,0,
1438344175.468,,9.999999e+002,1.904678e+002,3.936461e-006,0.000000e+000,-4.210033e-001,0.000000e+000,3,8.110033e-001,1.825000e+000,,,,,,,,,,,,,,,,,,0,4.000000e+000,1.000000e+000,20,1,5.767975e-001,0,0,0,
1438344252.297,,9.999999e+002,1.923130e+002,3.927868e-006,0.000000e+000,-4.265549e-001,0.000000e+000,3,8.125042e-001,1.825000e+000,,,,,,,,,,,,,,,,,,0,4.000000e+000,1.000000e+000,20,1,6.075134e-001,0,0,0,
1438344343.593,,9.999999e+002,1.945177e+002,3.895299e-006,0.000000e+000,-4.311034e-001,0.000000e+000,3,8.128770e-001,1.825000e+000,,,,,,,,,,,,,,,,,,0,4.000000e+000,1.000000e+000,20,1,6.004944e-001,0,0,0,
1438344424.422,,9.999999e+002,1.964286e+002,3.871799e-006,0.000000e+000,-4.345744e-001,0.000000e+000,3,8.094566e-001,1.825000e+000,,,,,,,,,,,,,,,,,,0,4.000000e+000,1.000000e+000,20,1,6.324921e-001,0,0,0,
1438344507.015,,9.999999e+002,1.984124e+002,3.845947e-006,0.000000e+000,-4.407989e-001,0.000000e+000,3,8.111138e-001,1.825000e+000,,,,,,,,,,,,,,,,,,0,4.000000e+000,1.000000e+000,20,1,5.919037e-001,0,0,0,
1438344596.062,,9.999999e+002,2.005210e+002,3.827917e-006,0.000000e+000,-4.480071e-001,0.000000e+000,3,8.065430e-001,1.825000e+000,,,,,,,,,,,,,,,,,,0,4.000000e+000,1.000000e+000,20,1,5.500031e-001,0,1,0,
1438344674.843,,9.999999e+002,2.024036e+002,3.801956e-006,0.000000e+000,-4.504206e-001,0.000000e+000,3,8.034216e-001,1.825000e+000,,,,,,,,,,,,,,,,,,0,4.000000e+000,1.000000e+000,20,1,6.258087e-001,0,1,0,
1438344755.390,,9.999999e+002,2.044321e+002,3.772906e-006,0.000000e+000,-4.541079e-001,0.000000e+000,3,8.112354e-001,1.825000e+000,,,,,,,,,,,,,,,,,,0,4.000000e+000,1.000000e+000,20,1,6.155090e-001,0,1,0,
1438344835.234,,9.999999e+002,2.064680e+002,3.769194e-006,0.000000e+000,-4.620084e-001,0.000000e+000,3,8.122380e-001,1.825000e+000,,,,,,,,,,,,,,,,,,0,4.000000e+000,1.000000e+000,20,1,5.641022e-001,0,1,0,
1438344909.531,,9.999999e+002,2.083058e+002,3.732400e-006,0.000000e+000,-4.662500e-001,0.000000e+000,3,8.136626e-001,1.825000e+000,,,,,,,,,,,,,,,,,,0,4.000000e+000,1.000000e+000,20,1,6.035004e-001,0,1,0,
1438344999.578,,9.999999e+002,2.104866e+002,3.718609e-006,0.000000e+000,-4.757484e-001,0.000000e+000,3,8.065444e-001,1.825000e+000,,,,,,,,,,,,,,,,,,0,4.000000e+000,1.000000e+000,20,1,5.803986e-001,0,1,0,
1438345082.203,,9.999999e+002,2.123925e+002,3.701604e-006,0.000000e+000,-4.808981e-001,0.000000e+000,3,8.014081e-001,1.825000e+000,,,,,,,,,,,,,,,,,,0,4.000000e+000,1.000000e+000,20,1,5.785980e-001,0,0,0,
1438345163.234,,9.999999e+002,2.144184e+002,3.645564e-006,0.000000e+000,-4.909601e-001,0.000000e+000,3,8.016534e-001,1.825000e+000,,,,,,,,,,,,,,,,,,0,4.000000e+000,1.000000e+000,20,1,6.018066e-001,0,0,0,
1438345244.062,,9.999999e+002,2.163260e+002,3.644959e-006,0.000000e+000,-4.918890e-001,0.000000e+000,3,8.080422e-001,1.825000e+000,,,,,,,,,,,,,,,,,,0,4.000000e+000,1.000000e+000,20,1,5.622864e-001,0,0,0,
1438345334.109,,9.999999e+002,2.184963e+002,3.620574e-006,0.000000e+000,-4.952382e-001,0.000000e+000,3,8.116515e-001,1.825000e+000,,,,,,,,,,,,,,,,,,0,4.000000e+000,1.000000e+000,20,1,5.734100e-001,0,0,0,
1438345414.203,,9.999999e+002,2.204986e+002,3.589628e-006,0.000000e+000,-5.016530e-001,0.000000e+000,3,8.086402e-001,1.825000e+000,,,,,,,,,,,,,,,,,,0,4.000000e+000,1.000000e+000,20,1,6.419983e-001,0,0,0,
1438345489.515,,9.999999e+002,2.223819e+002,3.586591e-006,0.000000e+000,-5.081688e-001,0.000000e+000,3,8.096648e-001,1.825000e+000,,,,,,,,,,,,,,,,,,0,4.000000e+000,1.000000e+000,20,1,6.264954e-001,0,0,0,