File: !!!Рисунки/Магнитная восприимчивость/Cu3SbSe3_137_1_m_60_40_mg_H_1000_Oe_m_T_2_rso.dat
[Header]
TITLE,MPMS RSO Measurement
BYAPP,MPMS Measurement,1.1,Summary
FILEOPENTIME, 1451043593.562000 12/25/2015, 4:39:53 PM

INFO, APPNAME, MPMS MultiVu Application, Revision 1.58,  Build 076

INFO, NAME, Unnamed
INFO, WEIGHT, 1.000
INFO, AREA, 1.000
INFO, LENGTH, 1.000
INFO, SHAPE, 0
INFO, COMMENT,
INFO, SEQUENCE FILE: Seq.471_m(T).seq


INFO, BACKGROUND DATA FILE:, None


STARTUPAXIS,X,4,LINEAR,AUTO,0.000000,0.000000
STARTUPAXIS,Y1,5,LINEAR,AUTO,0.000000,0.000000


STARTUPGROUP,Longitudinal
FIELDGROUP,Longitudinal,1,2,3,4,5,6,7,8,9,10,11,19,20,21,22,23,35
FIELDGROUP,Transverse,1,2,3,4,12,13,14,15,16,17,18,24,25,26,27,28,35

PLOT_APPEARANCE,ALL,HORZ_GRID_ON,VERT_GRID_ON,MARKERS_AND_LINES

[Data]
Time,Comment,Field (Oe),Temperature (K),Long Moment (emu),Long Scan Std Dev,Long Offset (cm),Long Offset Std Dev,Long Algorithm,Long Reg Fit,Long Reg Factor,Trans Moment (emu),Trans Scan Std Dev,Trans Offset (cm),Trans Offset Std Dev,Trans Algorithm,Trans Reg Fit,Trans Reg Factor,Long Moment [w/o ABS] (emu),Long Scan Std Dev [w/o ABS],Long Offset [w/o ABS] (cm),Long Offset Std Dev [w/o ABS],Long Reg Fit [w/o ABS],Trans Moment [w/o ABS] (emu),Trans Scan Std Dev [w/o ABS],Trans Offset [w/o ABS] (cm),Trans Offset Std Dev [w/o ABS],Trans Reg Fit [w/o ABS],RSO Position (deg),Amplitude (cm),Frequency,Cycles to Average,Scans per Measurement,Delta Temp (K),Error,EC Comp. Running,Using ABS,
1451043593.562,,9.999999e+002,2.005094e+000,-7.811577e-006,0.000000e+000,-1.205677e-002,0.000000e+000,3,9.420816e-001,1.825000e+000,,,,,,,,,,,,,,,,,,0,4.000000e+000,1.000000e+000,20,1,2.235889e-003,0,1,0,
1451043883.812,,9.999999e+002,6.422831e+000,-1.072082e-005,0.000000e+000,-3.222220e-003,0.000000e+000,3,9.686277e-001,1.825000e+000,,,,,,,,,,,,,,,,,,0,4.000000e+000,1.000000e+000,20,1,4.323969e-001,0,1,0,
1451043994.203,,9.999999e+002,8.258753e+000,-1.108334e-005,0.000000e+000,-2.344062e-003,0.000000e+000,3,9.705414e-001,1.825000e+000,,,,,,,,,,,,,,,,,,0,4.000000e+000,1.000000e+000,20,1,4.023991e-001,0,0,0,
1451044183.203,,9.999999e+002,1.127524e+001,-1.146877e-005,0.000000e+000,-1.716220e-003,0.000000e+000,3,9.722422e-001,1.825000e+000,,,,,,,,,,,,,,,,,,0,4.000000e+000,1.000000e+000,20,1,4.339104e-001,0,0,0,
1451044393.046,,9.999999e+002,1.466624e+001,-1.171966e-005,0.000000e+000,-1.793058e-003,0.000000e+000,3,9.706948e-001,1.825000e+000,,,,,,,,,,,,,,,,,,0,4.000000e+000,1.000000e+000,20,1,4.029799e-001,0,1,0,
1451044550.859,,9.999999e+002,1.725451e+001,-1.187624e-005,0.000000e+000,-1.100311e-003,0.000000e+000,3,9.715705e-001,1.825000e+000,,,,,,,,,,,,,,,,,,0,4.000000e+000,1.000000e+000,20,1,4.557800e-001,0,1,0,
1451044761.156,,9.999999e+002,2.071927e+001,-1.201684e-005,0.000000e+000,-8.506402e-004,0.000000e+000,3,9.725905e-001,1.825000e+000,,,,,,,,,,,,,,,,,,0,4.000000e+000,1.000000e+000,20,1,4.006195e-001,0,0,0,
1451044960.734,,9.999999e+002,2.400552e+001,-1.211996e-005,0.000000e+000,-7.830808e-004,0.000000e+000,3,9.723023e-001,1.825000e+000,,,,,,,,,,,,,,,,,,0,4.000000e+000,1.000000e+000,20,1,4.133701e-001,0,0,0,
1451045129.468,,9.999999e+002,2.678750e+001,-1.219497e-005,0.000000e+000,-3.123909e-004,0.000000e+000,3,9.708250e-001,1.825000e+000,,,,,,,,,,,,,,,,,,0,4.000000e+000,1.000000e+000,20,1,4.155407e-001,0,0,0,
1451045280.953,,9.999999e+002,2.925113e+001,-1.225935e-005,0.000000e+000,4.319749e-004,0.000000e+000,3,9.714586e-001,1.825000e+000,,,,,,,,,,,,,,,,,,0,4.000000e+000,1.000000e+000,20,1,3.926201e-001,0,0,0,
1451045468.843,,9.999999e+002,3.228400e+001,-1.232236e-005,0.000000e+000,-5.489462e-004,0.000000e+000,3,9.701074e-001,1.825000e+000,,,,,,,,,,,,,,,,,,0,4.000000e+000,1.000000e+000,20,1,3.901329e-001,0,1,0,
1451045656.531,,9.999999e+002,3.524258e+001,-1.241039e-005,0.000000e+000,-4.532828e-004,0.000000e+000,3,9.704923e-001,1.825000e+000,,,,,,,,,,,,,,,,,,0,4.000000e+000,1.000000e+000,20,1,4.166794e-001,0,1,0,
1451045842.765,,9.999999e+002,3.824201e+001,-1.245755e-005,0.000000e+000,2.540933e-004,0.000000e+000,3,9.685585e-001,1.825000e+000,,,,,,,,,,,,,,,,,,0,4.000000e+000,1.000000e+000,20,1,4.148369e-001,0,1,0,
1451046029.750,,9.999999e+002,4.125533e+001,-1.255455e-005,0.000000e+000,6.801001e-004,0.000000e+000,3,9.688197e-001,1.825000e+000,,,,,,,,,,,,,,,,,,0,4.000000e+000,1.000000e+000,20,1,4.308014e-001,0,0,0,
1451046218.031,,9.999999e+002,4.429230e+001,-1.261445e-005,0.000000e+000,5.456724e-004,0.000000e+000,3,9.678383e-001,1.825000e+000,,,,,,,,,,,,,,,,,,0,4.000000e+000,1.000000e+000,20,1,4.228134e-001,0,0,0,
1451046400.000,,9.999999e+002,4.728021e+001,-1.264734e-005,0.000000e+000,6.237256e-004,0.000000e+000,3,9.680351e-001,1.825000e+000,,,,,,,,,,,,,,,,,,0,4.000000e+000,1.000000e+000,20,1,4.188499e-001,0,0,0,
1451046585.937,,9.999999e+002,5.028179e+001,-1.265131e-005,0.000000e+000,1.107132e-003,0.000000e+000,3,9.680564e-001,1.825000e+000,,,,,,,,,,,,,,,,,,0,4.000000e+000,1.000000e+000,20,1,4.146004e-001,0,0,0,
1451046768.125,,9.999999e+002,5.325835e+001,-1.267368e-005,0.000000e+000,1.244117e-004,0.000000e+000,3,9.682063e-001,1.825000e+000,,,,,,,,,,,,,,,,,,0,4.000000e+000,1.000000e+000,20,1,3.949699e-001,0,1,0,
1451046953.765,,9.999999e+002,5.623496e+001,-1.266422e-005,0.000000e+000,1.021614e-003,0.000000e+000,3,9.685849e-001,1.825000e+000,,,,,,,,,,,,,,,,,,0,4.000000e+000,1.000000e+000,20,1,4.507484e-001,0,1,0,
1451047136.437,,9.999999e+002,5.931097e+001,-1.271654e-005,0.000000e+000,1.604868e-003,0.000000e+000,3,9.682471e-001,1.825000e+000,,,,,,,,,,,,,,,,,,0,4.000000e+000,1.000000e+000,20,1,4.504318e-001,0,1,0,
1451047316.031,,9.999999e+002,6.224912e+001,-1.271374e-005,0.000000e+000,7.134304e-004,0.000000e+000,3,9.686810e-001,1.825000e+000,,,,,,,,,,,,,,,,,,0,4.000000e+000,1.000000e+000,20,1,4.336891e-001,0,1,0,
1451047503.015,,9.999999e+002,6.524097e+001,-1.277487e-005,0.000000e+000,8.098960e-004,0.000000e+000,3,9.714563e-001,1.825000e+000,,,,,,,,,,,,,,,,,,0,4.000000e+000,1.000000e+000,20,1,4.142609e-001,0,0,0,
1451047689.109,,9.999999e+002,6.830492e+001,-1.279283e-005,0.000000e+000,1.304630e-003,0.000000e+000,3,9.710714e-001,1.825000e+000,,,,,,,,,,,,,,,,,,0,4.000000e+000,1.000000e+000,20,1,4.203644e-001,0,0,0,
1451047865.265,,9.999999e+002,7.126289e+001,-1.281456e-005,0.000000e+000,1.738235e-003,0.000000e+000,3,9.710976e-001,1.825000e+000,,,,,,,,,,,,,,,,,,0,4.000000e+000,1.000000e+000,20,1,4.733810e-001,0,0,0,
1451048051.734,,9.999999e+002,7.426843e+001,-1.282578e-005,0.000000e+000,4.995404e-004,0.000000e+000,3,9.697943e-001,1.825000e+000,,,,,,,,,,,,,,,,,,0,4.000000e+000,1.000000e+000,20,1,4.402618e-001,0,1,0,
1451048231.937,,9.999999e+002,7.722995e+001,-1.284233e-005,0.000000e+000,6.721215e-004,0.000000e+000,3,9.721676e-001,1.825000e+000,,,,,,,,,,,,,,,,,,0,4.000000e+000,1.000000e+000,20,1,4.501724e-001,0,1,0,
1451048412.921,,9.999999e+002,8.023019e+001,-1.288571e-005,0.000000e+000,1.237548e-003,0.000000e+000,3,9.701152e-001,1.825000e+000,,,,,,,,,,,,,,,,,,0,4.000000e+000,1.000000e+000,20,1,4.497299e-001,0,1,0,
1451048596.875,,9.999999e+002,8.322952e+001,-1.294082e-005,0.000000e+000,1.931754e-003,0.000000e+000,3,9.708627e-001,1.825000e+000,,,,,,,,,,,,,,,,,,0,4.000000e+000,1.000000e+000,20,1,4.286270e-001,0,1,0,
1451048788.312,,9.999999e+002,8.623340e+001,-1.293064e-005,0.000000e+000,8.113276e-004,0.000000e+000,3,9.725942e-001,1.825000e+000,,,,,,,,,,,,,,,,,,0,4.000000e+000,1.000000e+000,20,1,4.292221e-001,0,0,0,
1451048975.000,,9.999999e+002,8.921181e+001,-1.292868e-005,0.000000e+000,9.607065e-004,0.000000e+000,3,9.723961e-001,1.825000e+000,,,,,,,,,,,,,,,,,,0,4.000000e+000,1.000000e+000,20,1,3.931885e-001,0,0,0,
1451049213.250,,9.999999e+002,9.322595e+001,-1.296566e-005,0.000000e+000,2.079503e-004,0.000000e+000,3,9.729770e-001,1.825000e+000,,,,,,,,,,,,,,,,,,0,4.000000e+000,1.000000e+000,20,1,3.995972e-001,0,0,0,
1451049341.390,,9.999999e+002,9.528026e+001,-1.297027e-005,0.000000e+000,-2.034181e-004,0.000000e+000,3,9.707106e-001,1.825000e+000,,,,,,,,,,,,,,,,,,0,4.000000e+000,1.000000e+000,20,1,4.158173e-001,0,1,0,
1451049528.578,,9.999999e+002,9.826875e+001,-1.301010e-005,0.000000e+000,5.463310e-005,0.000000e+000,3,9.708391e-001,1.825000e+000,,,,,,,,,,,,,,,,,,0,4.000000e+000,1.000000e+000,20,1,4.110413e-001,0,1,0,
1451049715.531,,9.999999e+002,1.012961e+002,-1.298396e-005,0.000000e+000,-4.916745e-004,0.000000e+000,3,9.715623e-001,1.825000e+000,,,,,,,,,,,,,,,,,,0,4.000000e+000,1.000000e+000,20,1,4.403992e-001,0,1,0,
1451049896.968,,9.999999e+002,1.042859e+002,-1.299674e-005,0.000000e+000,-1.027465e-003,0.000000e+000,3,9.730040e-001,1.825000e+000,,,,,,,,,,,,,,,,,,0,4.000000e+000,1.000000e+000,20,1,4.257050e-001,0,0,0,
1451050084.640,,9.999999e+002,1.072177e+002,-1.300349e-005,0.000000e+000,-1.266945e-003,0.000000e+000,3,9.730579e-001,1.825000e+000,,,,,,,,,,,,,,,,,,0,4.000000e+000,1.000000e+000,20,1,3.899994e-001,0,0,0,
1451050275.046,,9.999999e+002,1.102729e+002,-1.301685e-005,0.000000e+000,-1.553380e-003,0.000000e+000,3,9.731012e-001,1.825000e+000,,,,,,,,,,,,,,,,,,0,4.000000e+000,1.000000e+000,20,1,4.819031e-001,0,0,0,
1451050454.703,,9.999999e+002,1.131936e+002,-1.302576e-005,0.000000e+000,-2.091781e-003,0.000000e+000,3,9.730430e-001,1.825000e+000,,,,,,,,,,,,,,,,,,0,4.000000e+000,1.000000e+000,20,1,3.818970e-001,0,1,0,
1451050645.609,,9.999999e+002,1.162403e+002,-1.306039e-005,0.000000e+000,-2.997865e-003,0.000000e+000,3,9.727811e-001,1.825000e+000,,,,,,,,,,,,,,,,,,0,4.000000e+000,1.000000e+000,20,1,3.810043e-001,0,1,0,
1451050833.093,,9.999999e+002,1.192964e+002,-1.305629e-005,0.000000e+000,-3.311981e-003,0.000000e+000,3,9.746064e-001,1.825000e+000,,,,,,,,,,,,,,,,,,0,4.000000e+000,1.000000e+000,20,1,3.992996e-001,0,1,0,
1451051016.531,,9.999999e+002,1.222769e+002,-1.309296e-005,0.000000e+000,-3.405402e-003,0.000000e+000,3,9.740725e-001,1.825000e+000,,,,,,,,,,,,,,,,,,0,4.000000e+000,1.000000e+000,20,1,3.745041e-001,0,0,0,
1451051199.250,,9.999999e+002,1.253260e+002,-1.310306e-005,0.000000e+000,-3.941198e-003,0.000000e+000,3,9.730359e-001,1.825000e+000,,,,,,,,,,,,,,,,,,0,4.000000e+000,1.000000e+000,20,1,4.141998e-001,0,0,0,
1451051382.171,,9.999999e+002,1.282747e+002,-1.311297e-005,0.000000e+000,-3.861621e-003,0.000000e+000,3,9.735943e-001,1.825000e+000,,,,,,,,,,,,,,,,,,0,4.000000e+000,1.000000e+000,20,1,4.367065e-001,0,0,0,
1451051563.375,,9.999999e+002,1.312802e+002,-1.313526e-005,0.000000e+000,-4.419122e-003,0.000000e+000,3,9.743685e-001,1.825000e+000,,,,,,,,,,,,,,,,,,0,4.000000e+000,1.000000e+000,20,1,3.867035e-001,0,0,0,
1451051749.343,,9.999999e+002,1.342285e+002,-1.316103e-005,0.000000e+000,-4.711233e-003,0.000000e+000,3,9.740986e-001,1.825000e+000,,,,,,,,,,,,,,,,,,0,4.000000e+000,1.000000e+000,20,1,3.973999e-001,0,1,0,
1451051934.843,,9.999999e+002,1.372396e+002,-1.317278e-005,0.000000e+000,-6.052726e-003,0.000000e+000,3,9.753496e-001,1.825000e+000,,,,,,,,,,,,,,,,,,0,4.000000e+000,1.000000e+000,20,1,4.293976e-001,0,1,0,
1451052122.453,,9.999999e+002,1.402505e+002,-1.323318e-005,0.000000e+000,-5.457919e-003,0.000000e+000,3,9.734656e-001,1.825000e+000,,,,,,,,,,,,,,,,,,0,4.000000e+000,1.000000e+000,20,1,4.134064e-001,0,1,0,
1451052310.390,,9.999999e+002,1.432288e+002,-1.322066e-005,0.000000e+000,-5.523541e-003,0.000000e+000,3,9.747854e-001,1.825000e+000,,,,,,,,,,,,,,,,,,0,4.000000e+000,1.000000e+000,20,1,3.964996e-001,0,0,0,
1451052490.812,,9.999999e+002,1.462059e+002,-1.321888e-005,0.000000e+000,-6.370593e-003,0.000000e+000,3,9.755608e-001,1.825000e+000,,,,,,,,,,,,,,,,,,0,4.000000e+000,1.000000e+000,20,1,3.984985e-001,0,0,0,
1451052676.453,,9.999999e+002,1.492462e+002,-1.321345e-005,0.000000e+000,-7.767913e-003,0.000000e+000,3,9.749687e-001,1.825000e+000,,,,,,,,,,,,,,,,,,0,4.000000e+000,1.000000e+000,20,1,4.449005e-001,0,0,0,
1451052864.390,,9.999999e+002,1.522870e+002,-1.321067e-005,0.000000e+000,-7.611172e-003,0.000000e+000,3,9.708924e-001,1.825000e+000,,,,,,,,,,,,,,,,,,0,4.000000e+000,1.000000e+000,20,1,4.105072e-001,0,1,0,
1451053048.562,,9.999999e+002,1.553013e+002,-1.322466e-005,0.000000e+000,-8.307013e-003,0.000000e+000,3,9.732087e-001,1.825000e+000,,,,,,,,,,,,,,,,,,0,4.000000e+000,1.000000e+000,20,1,4.057007e-001,0,1,0,
1451053236.750,,9.999999e+002,1.583181e+002,-1.321796e-005,0.000000e+000,-9.030676e-003,0.000000e+000,3,9.747381e-001,1.825000e+000,,,,,,,,,,,,,,,,,,0,4.000000e+000,1.000000e+000,20,1,4.136047e-001,0,1,0,
1451053417.937,,9.999999e+002,1.612777e+002,-1.320984e-005,0.000000e+000,-8.509581e-003,0.000000e+000,3,9.729699e-001,1.825000e+000,,,,,,,,,,,,,,,,,,0,4.000000e+000,1.000000e+000,20,1,4.138031e-001,0,1,0,
1451053603.468,,9.999999e+002,1.642908e+002,-1.319897e-005,0.000000e+000,-1.000043e-002,0.000000e+000,3,9.734609e-001,1.825000e+000,,,,,,,,,,,,,,,,,,0,4.000000e+000,1.000000e+000,20,1,4.284973e-001,0,0,0,
1451053781.437,,9.999999e+002,1.673010e+002,-1.317982e-005,0.000000e+000,-1.062609e-002,0.000000e+000,3,9.742856e-001,1.825000e+000,,,,,,,,,,,,,,,,,,0,4.000000e+000,1.000000e+000,20,1,4.358063e-001,0,0,0,
1451053959.218,,9.999999e+002,1.702390e+002,-1.314953e-005,0.000000e+000,-1.068364e-002,0.000000e+000,3,9.732146e-001,1.825000e+000,,,,,,,,,,,,,,,,,,0,4.000000e+000,1.000000e+000,20,1,4.346008e-001,0,0,0,
1451054142.937,,9.999999e+002,1.732475e+002,-1.315431e-005,0.000000e+000,-1.139028e-002,0.000000e+000,3,9.736058e-001,1.825000e+000,,,,,,,,,,,,,,,,,,0,4.000000e+000,1.000000e+000,20,1,4.411011e-001,0,1,0,
1451054328.375,,9.999999e+002,1.762481e+002,-1.313665e-005,0.000000e+000,-1.221805e-002,0.000000e+000,3,9.745268e-001,1.825000e+000,,,,,,,,,,,,,,,,,,0,4.000000e+000,1.000000e+000,20,1,3.964996e-001,0,1,0,
1451054510.031,,9.999999e+002,1.792660e+002,-1.311590e-005,0.000000e+000,-1.325977e-002,0.000000e+000,3,9.747017e-001,1.825000e+000,,,,,,,,,,,,,,,,,,0,4.000000e+000,1.000000e+000,20,1,3.921051e-001,0,1,0,
1451054694.953,,9.999999e+002,1.822617e+002,-1.310848e-005,0.000000e+000,-1.324949e-002,0.000000e+000,3,9.736346e-001,1.825000e+000,,,,,,,,,,,,,,,,,,0,4.000000e+000,1.000000e+000,20,1,4.495087e-001,0,0,0,
1451054878.187,,9.999999e+002,1.852105e+002,-1.308522e-005,0.000000e+000,-1.372539e-002,0.000000e+000,3,9.750660e-001,1.825000e+000,,,,,,,,,,,,,,,,,,0,4.000000e+000,1.000000e+000,20,1,4.170990e-001,0,0,0,
1451055060.375,,9.999999e+002,1.882224e+002,-1.308073e-005,0.000000e+000,-1.441294e-002,0.000000e+000,3,9.740176e-001,1.825000e+000,,,,,,,,,,,,,,,,,,0,4.000000e+000,1.000000e+000,20,1,4.300995e-001,0,0,0,
1451055249.296,,9.999999e+002,1.913440e+002,-1.309033e-005,0.000000e+000,-1.579217e-002,0.000000e+000,3,9.741156e-001,1.825000e+000,,,,,,,,,,,,,,,,,,0,4.000000e+000,1.000000e+000,20,1,4.141998e-001,0,0,0,
1451055432.218,,9.999999e+002,1.942811e+002,-1.308298e-005,0.000000e+000,-1.553341e-002,0.000000e+000,3,9.740422e-001,1.825000e+000,,,,,,,,,,,,,,,,,,0,4.000000e+000,1.000000e+000,20,1,3.757019e-001,0,1,0,
1451055620.203,,9.999999e+002,1.972949e+002,-1.307367e-005,0.000000e+000,-1.761947e-002,0.000000e+000,3,9.718236e-001,1.825000e+000,,,,,,,,,,,,,,,,,,0,4.000000e+000,1.000000e+000,20,1,3.973999e-001,0,1,0,
1451055804.406,,9.999999e+002,2.002970e+002,-1.304404e-005,0.000000e+000,-1.848164e-002,0.000000e+000,3,9.731870e-001,1.825000e+000,,,,,,,,,,,,,,,,,,0,4.000000e+000,1.000000e+000,20,1,4.304047e-001,0,1,0,
1451055984.046,,9.999999e+002,2.032268e+002,-1.307937e-005,0.000000e+000,-1.868945e-002,0.000000e+000,3,9.723961e-001,1.825000e+000,,,,,,,,,,,,,,,,,,0,4.000000e+000,1.000000e+000,20,1,4.315033e-001,0,0,0,
1451056168.562,,9.999999e+002,2.062708e+002,-1.305155e-005,0.000000e+000,-1.886068e-002,0.000000e+000,3,9.714413e-001,1.825000e+000,,,,,,,,,,,,,,,,,,0,4.000000e+000,1.000000e+000,20,1,3.808899e-001,0,0,0,
1451056346.250,,9.999999e+002,2.092463e+002,-1.306110e-005,0.000000e+000,-1.934418e-002,0.000000e+000,3,9.726567e-001,1.825000e+000,,,,,,,,,,,,,,,,,,0,4.000000e+000,1.000000e+000,20,1,4.565887e-001,0,0,0,
1451056527.015,,9.999999e+002,2.122350e+002,-1.307602e-005,0.000000e+000,-1.911438e-002,0.000000e+000,3,9.713338e-001,1.825000e+000,,,,,,,,,,,,,,,,,,0,4.000000e+000,1.000000e+000,20,1,4.272919e-001,0,1,0,
1451056710.312,,9.999999e+002,2.152309e+002,-1.309082e-005,0.000000e+000,-2.028085e-002,0.000000e+000,3,9.710795e-001,1.825000e+000,,,,,,,,,,,,,,,,,,0,4.000000e+000,1.000000e+000,20,1,4.269104e-001,0,1,0,
1451056892.218,,9.999999e+002,2.182215e+002,-1.310393e-005,0.000000e+000,-2.028668e-002,0.000000e+000,3,9.712409e-001,1.825000e+000,,,,,,,,,,,,,,,,,,0,4.000000e+000,1.000000e+000,20,1,4.257965e-001,0,1,0,
1451057077.437,,9.999999e+002,2.213173e+002,-1.310653e-005,0.000000e+000,-2.100023e-002,0.000000e+000,3,9.696266e-001,1.825000e+000,,,,,,,,,,,,,,,,,,0,4.000000e+000,1.000000e+000,20,1,4.441986e-001,0,1,0,
1451057259.593,,9.999999e+002,2.242919e+002,-1.311669e-005,0.000000e+000,-2.013340e-002,0.000000e+000,3,9.722680e-001,1.825000e+000,,,,,,,,,,,,,,,,,,0,4.000000e+000,1.000000e+000,20,1,3.822021e-001,0,0,0,
1451057446.015,,9.999999e+002,2.272459e+002,-1.312906e-005,0.000000e+000,-2.097610e-002,0.000000e+000,3,9.725037e-001,1.825000e+000,,,,,,,,,,,,,,,,,,0,4.000000e+000,1.000000e+000,20,1,4.196014e-001,0,0,0,
1451057632.640,,9.999999e+002,2.302944e+002,-1.314590e-005,0.000000e+000,-2.131194e-002,0.000000e+000,3,9.725668e-001,1.825000e+000,,,,,,,,,,,,,,,,,,0,4.000000e+000,1.000000e+000,20,1,3.952942e-001,0,0,0,
1451057817.156,,9.999999e+002,2.332461e+002,-1.314372e-005,0.000000e+000,-2.215708e-002,0.000000e+000,3,9.732448e-001,1.825000e+000,,,,,,,,,,,,,,,,,,0,4.000000e+000,1.000000e+000,20,1,4.054108e-001,0,1,0,
1451058009.578,,9.999999e+002,2.362744e+002,-1.316887e-005,0.000000e+000,-2.131636e-002,0.000000e+000,3,9.704968e-001,1.825000e+000,,,,,,,,,,,,,,,,,,0,4.000000e+000,1.000000e+000,20,1,4.010010e-001,0,1,0,
1451058188.265,,9.999999e+002,2.392110e+002,-1.318617e-005,0.000000e+000,-2.066115e-002,0.000000e+000,3,9.687564e-001,1.825000e+000,,,,,,,,,,,,,,,,,,0,4.000000e+000,1.000000e+000,20,1,4.035034e-001,0,1,0,
1451058367.171,,9.999999e+002,2.422525e+002,-1.315333e-005,0.000000e+000,-2.284296e-002,0.000000e+000,3,9.707043e-001,1.825000e+000,,,,,,,,,,,,,,,,,,0,4.000000e+000,1.000000e+000,20,1,4.371948e-001,0,0,0,
1451058554.328,,9.999999e+002,2.452762e+002,-1.320485e-005,0.000000e+000,-2.220991e-002,0.000000e+000,3,9.727522e-001,1.825000e+000,,,,,,,,,,,,,,,,,,0,4.000000e+000,1.000000e+000,20,1,4.243011e-001,0,0,0,
1451058744.750,,9.999999e+002,2.482487e+002,-1.321795e-005,0.000000e+000,-2.206568e-002,0.000000e+000,3,9.721181e-001,1.825000e+000,,,,,,,,,,,,,,,,,,0,4.000000e+000,1.000000e+000,20,1,3.852997e-001,0,0,0,
1451058934.234,,9.999999e+002,2.512984e+002,-1.324079e-005,0.000000e+000,-2.242871e-002,0.000000e+000,3,9.721682e-001,1.825000e+000,,,,,,,,,,,,,,,,,,0,4.000000e+000,1.000000e+000,20,1,4.200134e-001,0,1,0,
1451059118.968,,9.999999e+002,2.542858e+002,-1.326219e-005,0.000000e+000,-2.267973e-002,0.000000e+000,3,9.730183e-001,1.825000e+000,,,,,,,,,,,,,,,,,,0,4.000000e+000,1.000000e+000,20,1,4.214020e-001,0,1,0,
1451059305.640,,9.999999e+002,2.573138e+002,-1.331097e-005,0.000000e+000,-2.378198e-002,0.000000e+000,3,9.724400e-001,1.825000e+000,,,,,,,,,,,,,,,,,,0,4.000000e+000,1.000000e+000,20,1,3.962097e-001,0,1,0,
1451059487.656,,9.999999e+002,2.602297e+002,-1.329888e-005,0.000000e+000,-2.269015e-002,0.000000e+000,3,9.729539e-001,1.825000e+000,,,,,,,,,,,,,,,,,,0,4.000000e+000,1.000000e+000,20,1,4.140930e-001,0,1,0,
1451059674.875,,9.999999e+002,2.632173e+002,-1.335736e-005,0.000000e+000,-2.275450e-002,0.000000e+000,3,9.745295e-001,1.825000e+000,,,,,,,,,,,,,,,,,,0,4.000000e+000,1.000000e+000,20,1,4.069214e-001,0,0,0,
1451059860.296,,9.999999e+002,2.662631e+002,-1.332543e-005,0.000000e+000,-2.215994e-002,0.000000e+000,3,9.724483e-001,1.825000e+000,,,,,,,,,,,,,,,,,,0,4.000000e+000,1.000000e+000,20,1,3.681030e-001,0,0,0,
1451060041.234,,9.999999e+002,2.692231e+002,-1.335255e-005,0.000000e+000,-2.270839e-002,0.000000e+000,3,9.731890e-001,1.825000e+000,,,,,,,,,,,,,,,,,,0,4.000000e+000,1.000000e+000,20,1,4.346008e-001,0,0,0,
1451060224.968,,9.999999e+002,2.722625e+002,-1.335820e-005,0.000000e+000,-2.293084e-002,0.000000e+000,3,9.709850e-001,1.825000e+000,,,,,,,,,,,,,,,,,,0,4.000000e+000,1.000000e+000,20,1,3.856812e-001,0,1,0,
1451060411.437,,9.999999e+002,2.752224e+002,-1.338164e-005,0.000000e+000,-2.173457e-002,0.000000e+000,3,9.703658e-001,1.825000e+000,,,,,,,,,,,,,,,,,,0,4.000000e+000,1.000000e+000,20,1,4.145813e-001,0,1,0,
1451060602.437,,9.999999e+002,2.782810e+002,-1.341665e-005,0.000000e+000,-2.108830e-002,0.000000e+000,3,9.703357e-001,1.825000e+000,,,,,,,,,,,,,,,,,,0,4.000000e+000,1.000000e+000,20,1,4.035950e-001,0,1,0,
1451060786.890,,9.999999e+002,2.813052e+002,-1.348204e-005,0.000000e+000,-2.085419e-002,0.000000e+000,3,9.688960e-001,1.825000e+000,,,,,,,,,,,,,,,,,,0,4.000000e+000,1.000000e+000,20,1,4.128113e-001,0,1,0,
1451060968.156,,9.999999e+002,2.842521e+002,-1.352116e-005,0.000000e+000,-2.058617e-002,0.000000e+000,3,9.739239e-001,1.825000e+000,,,,,,,,,,,,,,,,,,0,4.000000e+000,1.000000e+000,20,1,4.109192e-001,0,0,0,
1451061153.875,,9.999999e+002,2.872306e+002,-1.358249e-005,0.000000e+000,-1.882388e-002,0.000000e+000,3,9.728822e-001,1.825000e+000,,,,,,,,,,,,,,,,,,0,4.000000e+000,1.000000e+000,20,1,4.309082e-001,0,0,0,
1451061397.500,,9.999999e+002,2.911802e+002,-1.364947e-005,0.000000e+000,-1.710905e-002,0.000000e+000,3,9.711373e-001,1.825000e+000,,,,,,,,,,,,,,,,,,0,4.000000e+000,1.000000e+000,20,1,4.317932e-001,0,0,0,
1451061522.546,,9.999999e+002,2.932347e+002,-1.364980e-005,0.000000e+000,-1.672726e-002,0.000000e+000,3,9.708640e-001,1.825000e+000,,,,,,,,,,,,,,,,,,0,4.000000e+000,1.000000e+000,20,1,4.035950e-001,0,1,0,
1451061703.968,,9.999999e+002,2.962464e+002,-1.372961e-005,0.000000e+000,-1.444282e-002,0.000000e+000,3,9.717739e-001,1.825000e+000,,,,,,,,,,,,,,,,,,0,4.000000e+000,1.000000e+000,20,1,4.238281e-001,0,1,0,
1451061887.156,,9.999999e+002,2.992285e+002,-1.374591e-005,0.000000e+000,-1.161395e-002,0.000000e+000,3,9.706574e-001,1.825000e+000,,,,,,,,,,,,,,,,,,0,4.000000e+000,1.000000e+000,20,1,4.092102e-001,0,1,0,
1451062620.875,,9.999999e+002,2.987778e+002,-1.373242e-005,0.000000e+000,-1.070845e-002,0.000000e+000,3,9.721279e-001,1.825000e+000,,,,,,,,,,,,,,,,,,0,4.000000e+000,1.000000e+000,20,1,3.719177e-001,0,0,0,
1451062782.640,,9.999999e+002,2.943582e+002,-1.372787e-005,0.000000e+000,-1.027985e-002,0.000000e+000,3,9.724846e-001,1.825000e+000,,,,,,,,,,,,,,,,,,0,4.000000e+000,1.000000e+000,20,1,9.877014e-001,0,1,0,
1451062868.968,,9.999999e+002,2.916414e+002,-1.375015e-005,0.000000e+000,-1.005298e-002,0.000000e+000,3,9.736511e-001,1.825000e+000,,,,,,,,,,,,,,,,,,0,4.000000e+000,1.000000e+000,20,1,6.725769e-001,0,1,0,
1451062979.437,,9.999999e+002,2.898737e+002,-1.369115e-005,0.000000e+000,-1.117416e-002,0.000000e+000,3,9.718145e-001,1.825000e+000,,,,,,,,,,,,,,,,,,0,4.000000e+000,1.000000e+000,20,1,1.914978e-001,0,1,0,
1451063274.578,,9.999999e+002,2.867948e+002,-1.374158e-005,0.000000e+000,-1.467983e-002,0.000000e+000,3,9.729417e-001,1.825000e+000,,,,,,,,,,,,,,,,,,0,4.000000e+000,1.000000e+000,20,1,3.964233e-001,0,1,0,
1451063477.562,,9.999999e+002,2.837341e+002,-1.370208e-005,0.000000e+000,-1.559463e-002,0.000000e+000,3,9.714912e-001,1.825000e+000,,,,,,,,,,,,,,,,,,0,4.000000e+000,1.000000e+000,20,1,4.094238e-001,0,1,0,
1451063673.750,,9.999999e+002,2.807191e+002,-1.370421e-005,0.000000e+000,-1.772308e-002,0.000000e+000,3,9.715158e-001,1.825000e+000,,,,,,,,,,,,,,,,,,0,4.000000e+000,1.000000e+000,20,1,4.214172e-001,0,1,0,
1451063867.140,,9.999999e+002,2.777338e+002,-1.367173e-005,0.000000e+000,-1.694498e-002,0.000000e+000,3,9.719502e-001,1.825000e+000,,,,,,,,,,,,,,,,,,0,4.000000e+000,1.000000e+000,20,1,4.225159e-001,0,1,0,
1451064060.625,,9.999999e+002,2.747127e+002,-1.369641e-005,0.000000e+000,-1.869688e-002,0.000000e+000,3,9.727794e-001,1.825000e+000,,,,,,,,,,,,,,,,,,0,4.000000e+000,1.000000e+000,20,1,4.030151e-001,0,1,0,
1451064251.359,,9.999999e+002,2.716853e+002,-1.367508e-005,0.000000e+000,-1.773655e-002,0.000000e+000,3,9.719889e-001,1.825000e+000,,,,,,,,,,,,,,,,,,0,4.000000e+000,1.000000e+000,20,1,4.331970e-001,0,1,0,
1451064439.203,,9.999999e+002,2.687169e+002,-1.356952e-005,0.000000e+000,-1.973011e-002,0.000000e+000,3,9.679729e-001,1.825000e+000,,,,,,,,,,,,,,,,,,0,4.000000e+000,1.000000e+000,20,1,4.041138e-001,0,1,0,
1451064630.640,,9.999999e+002,2.657026e+002,-1.364667e-005,0.000000e+000,-1.981903e-002,0.000000e+000,3,9.711400e-001,1.825000e+000,,,,,,,,,,,,,,,,,,0,4.000000e+000,1.000000e+000,20,1,4.134827e-001,0,1,0,
1451064822.859,,9.999999e+002,2.627614e+002,-1.369737e-005,0.000000e+000,-1.800856e-002,0.000000e+000,3,9.715196e-001,1.825000e+000,,,,,,,,,,,,,,,,,,0,4.000000e+000,1.000000e+000,20,1,4.129944e-001,0,1,0,
1451065012.781,,9.999999e+002,2.597354e+002,-1.365046e-005,0.000000e+000,-1.952590e-002,0.000000e+000,3,9.736108e-001,1.825000e+000,,,,,,,,,,,,,,,,,,0,4.000000e+000,1.000000e+000,20,1,4.484863e-001,0,1,0,
1451065197.546,,9.999999e+002,2.567516e+002,-1.366348e-005,0.000000e+000,-1.963452e-002,0.000000e+000,3,9.729121e-001,1.825000e+000,,,,,,,,,,,,,,,,,,0,4.000000e+000,1.000000e+000,20,1,4.469910e-001,0,0,0,
1451065374.750,,9.999999e+002,2.537366e+002,-1.358718e-005,0.000000e+000,-2.080060e-002,0.000000e+000,3,9.720722e-001,1.825000e+000,,,,,,,,,,,,,,,,,,0,4.000000e+000,1.000000e+000,20,1,5.223083e-001,0,0,0,
1451065522.187,,9.999999e+002,2.506994e+002,-1.359668e-005,0.000000e+000,-2.137102e-002,0.000000e+000,3,9.723432e-001,1.825000e+000,,,,,,,,,,,,,,,,,,0,4.000000e+000,1.000000e+000,20,1,5.767975e-001,0,1,0,
1451065671.765,,9.999999e+002,2.477416e+002,-1.358223e-005,0.000000e+000,-2.002699e-002,0.000000e+000,3,9.724102e-001,1.825000e+000,,,,,,,,,,,,,,,,,,0,4.000000e+000,1.000000e+000,20,1,4.817047e-001,0,1,0,
1451065862.750,,9.999999e+002,2.447371e+002,-1.352153e-005,0.000000e+000,-2.061959e-002,0.000000e+000,3,9.710910e-001,1.825000e+000,,,,,,,,,,,,,,,,,,0,4.000000e+000,1.000000e+000,20,1,3.665009e-001,0,1,0,
1451066066.500,,9.999999e+002,2.417227e+002,-1.355374e-005,0.000000e+000,-1.984629e-002,0.000000e+000,3,9.711968e-001,1.825000e+000,,,,,,,,,,,,,,,,,,0,4.000000e+000,1.000000e+000,20,1,4.042053e-001,0,1,0,
1451066268.625,,9.999999e+002,2.387474e+002,-1.348863e-005,0.000000e+000,-1.946088e-002,0.000000e+000,3,9.701960e-001,1.825000e+000,,,,,,,,,,,,,,,,,,0,4.000000e+000,1.000000e+000,20,1,4.019928e-001,0,1,0,
1451066466.312,,9.999999e+002,2.358000e+002,-1.345960e-005,0.000000e+000,-1.983376e-002,0.000000e+000,3,9.697924e-001,1.825000e+000,,,,,,,,,,,,,,,,,,0,4.000000e+000,1.000000e+000,20,1,3.995056e-001,0,1,0,
1451066667.953,,9.999999e+002,2.327552e+002,-1.344482e-005,0.000000e+000,-2.089514e-002,0.000000e+000,3,9.741448e-001,1.825000e+000,,,,,,,,,,,,,,,,,,0,4.000000e+000,1.000000e+000,20,1,4.179993e-001,0,1,0,
1451066861.656,,9.999999e+002,2.297732e+002,-1.339269e-005,0.000000e+000,-1.865241e-002,0.000000e+000,3,9.705284e-001,1.825000e+000,,,,,,,,,,,,,,,,,,0,4.000000e+000,1.000000e+000,20,1,3.795013e-001,0,1,0,
1451067052.093,,9.999999e+002,2.267312e+002,-1.338525e-005,0.000000e+000,-2.044597e-002,0.000000e+000,3,9.716749e-001,1.825000e+000,,,,,,,,,,,,,,,,,,0,4.000000e+000,1.000000e+000,20,1,4.178009e-001,0,0,0,
1451067218.781,,9.999999e+002,2.236403e+002,-1.332322e-005,0.000000e+000,-1.916360e-002,0.000000e+000,3,9.709657e-001,1.825000e+000,,,,,,,,,,,,,,,,,,0,4.000000e+000,1.000000e+000,20,1,5.467072e-001,0,0,0,
1451067365.765,,9.999999e+002,2.205914e+002,-1.328431e-005,0.000000e+000,-1.875858e-002,0.000000e+000,3,9.705092e-001,1.825000e+000,,,,,,,,,,,,,,,,,,0,4.000000e+000,1.000000e+000,20,1,5.257874e-001,0,1,0,
1451067526.781,,9.999999e+002,2.177332e+002,-1.324646e-005,0.000000e+000,-1.839395e-002,0.000000e+000,3,9.710189e-001,1.825000e+000,,,,,,,,,,,,,,,,,,0,4.000000e+000,1.000000e+000,20,1,4.113007e-001,0,1,0,
1451067730.421,,9.999999e+002,2.147371e+002,-1.323321e-005,0.000000e+000,-1.868459e-002,0.000000e+000,3,9.711319e-001,1.825000e+000,,,,,,,,,,,,,,,,,,0,4.000000e+000,1.000000e+000,20,1,3.878937e-001,0,1,0,
1451067936.656,,9.999999e+002,2.117485e+002,-1.319459e-005,0.000000e+000,-1.743859e-002,0.000000e+000,3,9.695583e-001,1.825000e+000,,,,,,,,,,,,,,,,,,0,4.000000e+000,1.000000e+000,20,1,3.773956e-001,0,1,0,
1451068140.187,,9.999999e+002,2.087731e+002,-1.317359e-005,0.000000e+000,-1.920602e-002,0.000000e+000,3,9.683716e-001,1.825000e+000,,,,,,,,,,,,,,,,,,0,4.000000e+000,1.000000e+000,20,1,3.379974e-001,0,1,0,
1451068345.687,,9.999999e+002,2.057203e+002,-1.314931e-005,0.000000e+000,-1.690672e-002,0.000000e+000,3,9.690058e-001,1.825000e+000,,,,,,,,,,,,,,,,,,0,4.000000e+000,1.000000e+000,20,1,3.679962e-001,0,1,0,
1451068539.218,,9.999999e+002,2.027357e+002,-1.314270e-005,0.000000e+000,-1.682375e-002,0.000000e+000,3,9.709346e-001,1.825000e+000,,,,,,,,,,,,,,,,,,0,4.000000e+000,1.000000e+000,20,1,4.625092e-001,0,0,0,
1451068705.906,,9.999999e+002,1.996426e+002,-1.310040e-005,0.000000e+000,-1.729065e-002,0.000000e+000,3,9.705822e-001,1.825000e+000,,,,,,,,,,,,,,,,,,0,4.000000e+000,1.000000e+000,20,1,4.919891e-001,0,0,0,
1451068854.062,,9.999999e+002,1.966799e+002,-1.309741e-005,0.000000e+000,-1.666748e-002,0.000000e+000,3,9.705595e-001,1.825000e+000,,,,,,,,,,,,,,,,,,0,4.000000e+000,1.000000e+000,20,1,4.884949e-001,0,1,0,
1451069020.046,,9.999999e+002,1.937444e+002,-1.307122e-005,0.000000e+000,-1.682172e-002,0.000000e+000,3,9.703992e-001,1.825000e+000,,,,,,,,,,,,,,,,,,0,4.000000e+000,1.000000e+000,20,1,4.342041e-001,0,1,0,
1451069217.968,,9.999999e+002,1.907393e+002,-1.303584e-005,0.000000e+000,-1.652018e-002,0.000000e+000,3,9.709032e-001,1.825000e+000,,,,,,,,,,,,,,,,,,0,4.000000e+000,1.000000e+000,20,1,3.823090e-001,0,1,0,
1451069421.156,,9.999999e+002,1.877838e+002,-1.302939e-005,0.000000e+000,-1.630183e-002,0.000000e+000,3,9.715449e-001,1.825000e+000,,,,,,,,,,,,,,,,,,0,4.000000e+000,1.000000e+000,20,1,3.901062e-001,0,1,0,
1451069629.437,,9.999999e+002,1.847505e+002,-1.299971e-005,0.000000e+000,-1.671608e-002,0.000000e+000,3,9.703390e-001,1.825000e+000,,,,,,,,,,,,,,,,,,0,4.000000e+000,1.000000e+000,20,1,4.012909e-001,0,1,0,
1451069829.078,,9.999999e+002,1.817393e+002,-1.299810e-005,0.000000e+000,-1.548952e-002,0.000000e+000,3,9.715183e-001,1.825000e+000,,,,,,,,,,,,,,,,,,0,4.000000e+000,1.000000e+000,20,1,4.247131e-001,0,0,0,
1451070003.343,,9.999999e+002,1.787318e+002,-1.296703e-005,0.000000e+000,-1.455042e-002,0.000000e+000,3,9.707845e-001,1.825000e+000,,,,,,,,,,,,,,,,,,0,4.000000e+000,1.000000e+000,20,1,4.851074e-001,0,0,0,
1451070158.000,,9.999999e+002,1.756471e+002,-1.295388e-005,0.000000e+000,-1.399705e-002,0.000000e+000,3,9.706292e-001,1.825000e+000,,,,,,,,,,,,,,,,,,0,4.000000e+000,1.000000e+000,20,1,5.196991e-001,0,1,0,
1451070314.953,,9.999999e+002,1.727181e+002,-1.295527e-005,0.000000e+000,-1.330080e-002,0.000000e+000,3,9.705585e-001,1.825000e+000,,,,,,,,,,,,,,,,,,0,4.000000e+000,1.000000e+000,20,1,4.304047e-001,0,1,0,
1451070508.140,,9.999999e+002,1.697858e+002,-1.294070e-005,0.000000e+000,-1.366560e-002,0.000000e+000,3,9.701010e-001,1.825000e+000,,,,,,,,,,,,,,,,,,0,4.000000e+000,1.000000e+000,20,1,3.695068e-001,0,1,0,
1451070718.578,,9.999999e+002,1.667920e+002,-1.290338e-005,0.000000e+000,-1.274201e-002,0.000000e+000,3,9.706221e-001,1.825000e+000,,,,,,,,,,,,,,,,,,0,4.000000e+000,1.000000e+000,20,1,3.762970e-001,0,1,0,
1451070928.281,,9.999999e+002,1.637714e+002,-1.288362e-005,0.000000e+000,-1.176657e-002,0.000000e+000,3,9.700912e-001,1.825000e+000,,,,,,,,,,,,,,,,,,0,4.000000e+000,1.000000e+000,20,1,3.965912e-001,0,1,0,
1451071131.312,,9.999999e+002,1.607549e+002,-1.285362e-005,0.000000e+000,-1.258939e-002,0.000000e+000,3,9.703673e-001,1.825000e+000,,,,,,,,,,,,,,,,,,0,4.000000e+000,1.000000e+000,20,1,4.255066e-001,0,0,0,
1451071309.250,,9.999999e+002,1.576333e+002,-1.284944e-005,0.000000e+000,-1.153584e-002,0.000000e+000,3,9.705133e-001,1.825000e+000,,,,,,,,,,,,,,,,,,0,4.000000e+000,1.000000e+000,20,1,4.890137e-001,0,0,0,
1451071462.187,,9.999999e+002,1.546572e+002,-1.283986e-005,0.000000e+000,-1.148174e-002,0.000000e+000,3,9.706885e-001,1.825000e+000,,,,,,,,,,,,,,,,,,0,4.000000e+000,1.000000e+000,20,1,5.115051e-001,0,1,0,
1451071621.359,,9.999999e+002,1.517308e+002,-1.282284e-005,0.000000e+000,-1.065552e-002,0.000000e+000,3,9.716289e-001,1.825000e+000,,,,,,,,,,,,,,,,,,0,4.000000e+000,1.000000e+000,20,1,4.396057e-001,0,1,0,
1451071815.515,,9.999999e+002,1.487596e+002,-1.280521e-005,0.000000e+000,-1.000381e-002,0.000000e+000,3,9.710416e-001,1.825000e+000,,,,,,,,,,,,,,,,,,0,4.000000e+000,1.000000e+000,20,1,4.053040e-001,0,1,0,
1451072015.750,,9.999999e+002,1.457921e+002,-1.278047e-005,0.000000e+000,-9.864234e-003,0.000000e+000,3,9.712757e-001,1.825000e+000,,,,,,,,,,,,,,,,,,0,4.000000e+000,1.000000e+000,20,1,4.053955e-001,0,1,0,
1451072220.406,,9.999999e+002,1.427499e+002,-1.273944e-005,0.000000e+000,-8.049166e-003,0.000000e+000,3,9.701451e-001,1.825000e+000,,,,,,,,,,,,,,,,,,0,4.000000e+000,1.000000e+000,20,1,3.955994e-001,0,1,0,
1451072419.125,,9.999999e+002,1.397218e+002,-1.273114e-005,0.000000e+000,-8.852155e-003,0.000000e+000,3,9.702915e-001,1.825000e+000,,,,,,,,,,,,,,,,,,0,4.000000e+000,1.000000e+000,20,1,4.353027e-001,0,0,0,
1451072585.765,,9.999999e+002,1.367207e+002,-1.270693e-005,0.000000e+000,-8.694609e-003,0.000000e+000,3,9.702504e-001,1.825000e+000,,,,,,,,,,,,,,,,,,0,4.000000e+000,1.000000e+000,20,1,5.028076e-001,0,0,0,
1451072741.468,,9.999999e+002,1.336895e+002,-1.268850e-005,0.000000e+000,-8.567119e-003,0.000000e+000,3,9.718002e-001,1.825000e+000,,,,,,,,,,,,,,,,,,0,4.000000e+000,1.000000e+000,20,1,5.234070e-001,0,1,0,
1451072908.953,,9.999999e+002,1.307561e+002,-1.265819e-005,0.000000e+000,-7.572724e-003,0.000000e+000,3,9.707443e-001,1.825000e+000,,,,,,,,,,,,,,,,,,0,4.000000e+000,1.000000e+000,20,1,4.228058e-001,0,1,0,
1451073112.750,,9.999999e+002,1.277228e+002,-1.263459e-005,0.000000e+000,-8.731592e-003,0.000000e+000,3,9.704263e-001,1.825000e+000,,,,,,,,,,,,,,,,,,0,4.000000e+000,1.000000e+000,20,1,4.053955e-001,0,1,0,
1451073314.484,,9.999999e+002,1.247587e+002,-1.261041e-005,0.000000e+000,-7.784899e-003,0.000000e+000,3,9.698780e-001,1.825000e+000,,,,,,,,,,,,,,,,,,0,4.000000e+000,1.000000e+000,20,1,3.706970e-001,0,1,0,
1451073513.515,,9.999999e+002,1.217538e+002,-1.258891e-005,0.000000e+000,-6.105168e-003,0.000000e+000,3,9.693859e-001,1.825000e+000,,,,,,,,,,,,,,,,,,0,4.000000e+000,1.000000e+000,20,1,3.802032e-001,0,0,0,
1451073695.843,,9.999999e+002,1.187208e+002,-1.257301e-005,0.000000e+000,-6.582723e-003,0.000000e+000,3,9.696828e-001,1.825000e+000,,,,,,,,,,,,,,,,,,0,4.000000e+000,1.000000e+000,20,1,5.550003e-001,0,0,0,
1451073857.156,,9.999999e+002,1.156638e+002,-1.257337e-005,0.000000e+000,-6.225409e-003,0.000000e+000,3,9.694751e-001,1.825000e+000,,,,,,,,,,,,,,,,,,0,4.000000e+000,1.000000e+000,20,1,5.293961e-001,0,1,0,
1451074022.484,,9.999999e+002,1.126996e+002,-1.254843e-005,0.000000e+000,-5.494889e-003,0.000000e+000,3,9.703151e-001,1.825000e+000,,,,,,,,,,,,,,,,,,0,4.000000e+000,1.000000e+000,20,1,4.197998e-001,0,1,0,
1451074212.281,,9.999999e+002,1.097522e+002,-1.242449e-005,0.000000e+000,-4.347251e-003,0.000000e+000,3,9.726531e-001,1.825000e+000,,,,,,,,,,,,,,,,,,0,4.000000e+000,1.000000e+000,20,1,4.246979e-001,0,1,0,
1451074411.984,,9.999999e+002,1.067749e+002,-1.241772e-005,0.000000e+000,-3.721086e-003,0.000000e+000,3,9.733500e-001,1.825000e+000,,,,,,,,,,,,,,,,,,0,4.000000e+000,1.000000e+000,20,1,3.332977e-001,0,1,0,
1451074609.437,,9.999999e+002,1.037722e+002,-1.238387e-005,0.000000e+000,-3.182916e-003,0.000000e+000,3,9.730000e-001,1.825000e+000,,,,,,,,,,,,,,,,,,0,4.000000e+000,1.000000e+000,20,1,3.580017e-001,0,1,0,
1451074798.093,,9.999999e+002,1.007150e+002,-1.236285e-005,0.000000e+000,-2.405654e-003,0.000000e+000,3,9.726123e-001,1.825000e+000,,,,,,,,,,,,,,,,,,0,4.000000e+000,1.000000e+000,20,1,4.964066e-001,0,0,0,
1451074959.546,,9.999999e+002,9.766156e+001,-1.235369e-005,0.000000e+000,-3.247997e-003,0.000000e+000,3,9.720278e-001,1.825000e+000,,,,,,,,,,,,,,,,,,0,4.000000e+000,1.000000e+000,20,1,4.693527e-001,0,0,0,
1451075112.328,,9.999999e+002,9.473210e+001,-1.232835e-005,0.000000e+000,-2.394735e-003,0.000000e+000,3,9.722296e-001,1.825000e+000,,,,,,,,,,,,,,,,,,0,4.000000e+000,1.000000e+000,20,1,4.953690e-001,0,1,0,
1451075291.109,,9.999999e+002,9.173755e+001,-1.115187e-005,0.000000e+000,-1.837290e-002,0.000000e+000,3,9.137511e-001,1.825000e+000,,,,,,,,,,,,,,,,,,0,4.000000e+000,1.000000e+000,20,1,3.957291e-001,0,1,0,
1451075481.375,,9.999999e+002,8.872705e+001,-1.113593e-005,0.000000e+000,-1.758398e-002,0.000000e+000,3,9.140956e-001,1.825000e+000,,,,,,,,,,,,,,,,,,0,4.000000e+000,1.000000e+000,20,1,3.940430e-001,0,1,0,
1451075675.312,,9.999999e+002,8.572119e+001,-1.112880e-005,0.000000e+000,-1.797305e-002,0.000000e+000,3,9.140358e-001,1.825000e+000,,,,,,,,,,,,,,,,,,0,4.000000e+000,1.000000e+000,20,1,3.929901e-001,0,1,0,
1451075861.968,,9.999999e+002,8.270370e+001,-1.108787e-005,0.000000e+000,-1.764354e-002,0.000000e+000,3,9.141040e-001,1.825000e+000,,,,,,,,,,,,,,,,,,0,4.000000e+000,1.000000e+000,20,1,4.555359e-001,0,0,0,
1451076025.406,,9.999999e+002,7.967760e+001,-1.106221e-005,0.000000e+000,-1.753542e-002,0.000000e+000,3,9.137954e-001,1.825000e+000,,,,,,,,,,,,,,,,,,0,4.000000e+000,1.000000e+000,20,1,5.195084e-001,0,0,0,
1451076175.609,,9.999999e+002,7.673643e+001,-1.109638e-005,0.000000e+000,-6.382456e-003,0.000000e+000,3,9.137213e-001,1.825000e+000,,,,,,,,,,,,,,,,,,0,4.000000e+000,1.000000e+000,20,1,5.264282e-001,0,1,0,
1451076342.609,,9.999999e+002,7.373203e+001,-1.105647e-005,0.000000e+000,-6.247867e-003,0.000000e+000,3,9.135822e-001,1.825000e+000,,,,,,,,,,,,,,,,,,0,4.000000e+000,1.000000e+000,20,1,4.016800e-001,0,1,0,
1451076528.281,,9.999999e+002,7.077748e+001,-1.103969e-005,0.000000e+000,-6.405897e-003,0.000000e+000,3,9.124922e-001,1.825000e+000,,,,,,,,,,,,,,,,,,0,4.000000e+000,1.000000e+000,20,1,4.194565e-001,0,1,0,
1451076797.187,,9.999999e+002,6.642542e+001,-1.100637e-005,0.000000e+000,-6.491122e-003,0.000000e+000,3,9.131176e-001,1.825000e+000,,,,,,,,,,,,,,,,,,0,4.000000e+000,1.000000e+000,20,1,4.350967e-001,0,1,0,
1451076893.625,,9.999999e+002,6.471148e+001,-1.098035e-005,0.000000e+000,-5.814193e-003,0.000000e+000,3,9.141025e-001,1.825000e+000,,,,,,,,,,,,,,,,,,0,4.000000e+000,1.000000e+000,20,1,5.033417e-001,0,0,0,
1451077051.843,,9.999999e+002,6.170254e+001,-1.094045e-005,0.000000e+000,-5.878877e-003,0.000000e+000,3,9.136146e-001,1.825000e+000,,,,,,,,,,,,,,,,,,0,4.000000e+000,1.000000e+000,20,1,4.803810e-001,0,0,0,
1451077209.093,,9.999999e+002,5.865587e+001,-1.091699e-005,0.000000e+000,-4.583349e-003,0.000000e+000,3,9.172058e-001,1.825000e+000,,,,,,,,,,,,,,,,,,0,4.000000e+000,1.000000e+000,20,1,4.810905e-001,0,0,0,
1451077360.750,,9.999999e+002,5.575233e+001,-1.089247e-005,0.000000e+000,-4.055773e-003,0.000000e+000,3,9.180709e-001,1.825000e+000,,,,,,,,,,,,,,,,,,0,4.000000e+000,1.000000e+000,20,1,4.768906e-001,0,1,0,
1451077537.687,,9.999999e+002,5.270189e+001,-1.083154e-005,0.000000e+000,-4.155455e-003,0.000000e+000,3,9.197167e-001,1.825000e+000,,,,,,,,,,,,,,,,,,0,4.000000e+000,1.000000e+000,20,1,4.343491e-001,0,1,0,
1451077718.218,,9.999999e+002,4.966595e+001,-1.076157e-005,0.000000e+000,-4.444794e-003,0.000000e+000,3,9.200043e-001,1.825000e+000,,,,,,,,,,,,,,,,,,0,4.000000e+000,1.000000e+000,20,1,4.223518e-001,0,1,0,
1451077888.093,,9.999999e+002,4.666633e+001,-1.073437e-005,0.000000e+000,-4.790456e-003,0.000000e+000,3,9.185532e-001,1.825000e+000,,,,,,,,,,,,,,,,,,0,4.000000e+000,1.000000e+000,20,1,4.436226e-001,0,0,0,
1451078046.281,,9.999999e+002,4.369045e+001,-1.067997e-005,0.000000e+000,-4.374672e-003,0.000000e+000,3,9.207252e-001,1.825000e+000,,,,,,,,,,,,,,,,,,0,4.000000e+000,1.000000e+000,20,1,4.698982e-001,0,0,0,
1451078204.718,,9.999999e+002,4.071453e+001,-1.064783e-005,0.000000e+000,-4.973077e-003,0.000000e+000,3,9.218441e-001,1.825000e+000,,,,,,,,,,,,,,,,,,0,4.000000e+000,1.000000e+000,20,1,4.699783e-001,0,0,0,
1451078365.171,,9.999999e+002,3.776984e+001,-1.061290e-005,0.000000e+000,-5.409950e-003,0.000000e+000,3,9.218676e-001,1.825000e+000,,,,,,,,,,,,,,,,,,0,4.000000e+000,1.000000e+000,20,1,4.340210e-001,0,0,0,
1451078541.625,,9.999999e+002,3.475677e+001,-1.057397e-005,0.000000e+000,-5.425352e-003,0.000000e+000,3,9.205002e-001,1.825000e+000,,,,,,,,,,,,,,,,,,0,4.000000e+000,1.000000e+000,20,1,4.064484e-001,0,1,0,
1451078725.687,,9.999999e+002,3.175260e+001,-1.050901e-005,0.000000e+000,-4.744768e-003,0.000000e+000,3,9.227396e-001,1.825000e+000,,,,,,,,,,,,,,,,,,0,4.000000e+000,1.000000e+000,20,1,4.147797e-001,0,1,0,
1451078910.140,,9.999999e+002,2.872728e+001,-1.043899e-005,0.000000e+000,-4.663882e-003,0.000000e+000,3,9.214008e-001,1.825000e+000,,,,,,,,,,,,,,,,,,0,4.000000e+000,1.000000e+000,20,1,4.429207e-001,0,0,0,
1451079088.296,,9.999999e+002,2.572083e+001,-1.036319e-005,0.000000e+000,-5.310136e-003,0.000000e+000,3,9.210782e-001,1.825000e+000,,,,,,,,,,,,,,,,,,0,4.000000e+000,1.000000e+000,20,1,4.120712e-001,0,0,0,
1451079256.484,,9.999999e+002,2.270673e+001,-1.027542e-005,0.000000e+000,-5.736223e-003,0.000000e+000,3,9.199182e-001,1.825000e+000,,,,,,,,,,,,,,,,,,0,4.000000e+000,1.000000e+000,20,1,4.060688e-001,0,0,0,
1451079436.437,,9.999999e+002,1.971876e+001,-1.017696e-005,0.000000e+000,-5.542343e-003,0.000000e+000,3,9.195573e-001,1.825000e+000,,,,,,,,,,,,,,,,,,0,4.000000e+000,1.000000e+000,20,1,3.899803e-001,0,0,0,
1451079618.187,,9.999999e+002,1.676282e+001,-1.004610e-005,0.000000e+000,-5.436776e-003,0.000000e+000,3,9.167874e-001,1.825000e+000,,,,,,,,,,,,,,,,,,0,4.000000e+000,1.000000e+000,20,1,3.875694e-001,0,1,0,
1451079804.687,,9.999999e+002,1.378327e+001,-9.856948e-006,0.000000e+000,-7.233567e-003,0.000000e+000,3,9.187723e-001,1.825000e+000,,,,,,,,,,,,,,,,,,0,4.000000e+000,1.000000e+000,20,1,4.247894e-001,0,1,0,
1451079994.140,,9.999999e+002,1.073956e+001,-9.557224e-006,0.000000e+000,-7.441286e-003,0.000000e+000,3,9.193535e-001,1.825000e+000,,,,,,,,,,,,,,,,,,0,4.000000e+000,1.000000e+000,20,1,4.257898e-001,0,1,0,
1451080178.593,,9.999999e+002,7.757931e+000,-9.093005e-006,0.000000e+000,-7.831933e-003,0.000000e+000,3,9.163474e-001,1.825000e+000,,,,,,,,,,,,,,,,,,0,4.000000e+000,1.000000e+000,20,1,4.238486e-001,0,0,0,
1451080385.750,,9.999999e+002,4.737207e+000,-8.119539e-006,0.000000e+000,-1.131596e-002,0.000000e+000,3,9.125018e-001,1.825000e+000,,,,,,,,,,,,,,,,,,0,4.000000e+000,1.000000e+000,20,1,4.360533e-001,0,0,0,
1451080755.609,,9.999999e+002,2.008083e+000,-5.450779e-006,0.000000e+000,-2.768458e-002,0.000000e+000,3,8.780581e-001,1.825000e+000,,,,,,,,,,,,,,,,,,0,4.000000e+000,1.000000e+000,20,1,2.840006e-002,0,1,0,