File: !!!Рисунки/Магнитная восприимчивость/Cu3SbS3_206_4.rso._different_field.dat
[Header]
TITLE,MPMS RSO Measurement
BYAPP,MPMS Measurement,1.1,Summary
FILEOPENTIME, 1435317943.108000 6/26/2015, 4:25:43 PM

INFO, APPNAME, MPMS MultiVu Application, Revision 1.58,  Build 076

INFO, NAME, Unnamed
INFO, WEIGHT, 1.000
INFO, AREA, 1.000
INFO, LENGTH, 1.000
INFO, SHAPE, 0
INFO, COMMENT,
INFO, SEQUENCE FILE: 444.seq


INFO, BACKGROUND DATA FILE:, None


STARTUPAXIS,X,4,LINEAR,AUTO,0.000000,0.000000
STARTUPAXIS,Y1,5,LINEAR,AUTO,0.000000,0.000000


STARTUPGROUP,Longitudinal
FIELDGROUP,Longitudinal,1,2,3,4,5,6,7,8,9,10,11,19,20,21,22,23,35
FIELDGROUP,Transverse,1,2,3,4,12,13,14,15,16,17,18,24,25,26,27,28,35

PLOT_APPEARANCE,ALL,HORZ_GRID_ON,VERT_GRID_ON,MARKERS_AND_LINES

[Data]
Time,Comment,Field (Oe),Temperature (K),Long Moment (emu),Long Scan Std Dev,Long Offset (cm),Long Offset Std Dev,Long Algorithm,Long Reg Fit,Long Reg Factor,Trans Moment (emu),Trans Scan Std Dev,Trans Offset (cm),Trans Offset Std Dev,Trans Algorithm,Trans Reg Fit,Trans Reg Factor,Long Moment [w/o ABS] (emu),Long Scan Std Dev [w/o ABS],Long Offset [w/o ABS] (cm),Long Offset Std Dev [w/o ABS],Long Reg Fit [w/o ABS],Trans Moment [w/o ABS] (emu),Trans Scan Std Dev [w/o ABS],Trans Offset [w/o ABS] (cm),Trans Offset Std Dev [w/o ABS],Trans Reg Fit [w/o ABS],RSO Position (deg),Amplitude (cm),Frequency,Cycles to Average,Scans per Measurement,Delta Temp (K),Error,EC Comp. Running,Using ABS,
1435317943.108,,9.999999e+002,3.500038e+002,4.448777e-006,0.000000e+000,3.431443e-001,0.000000e+000,3,8.190591e-001,1.825000e+000,,,,,,,,,,,,,,,,,,0,4.000000e+000,1.000000e+000,20,1,0.000000e+000,0,0,0,
1435318356.139,,9.999999e+002,3.339799e+002,4.797821e-006,0.000000e+000,3.207705e-001,0.000000e+000,3,8.345666e-001,1.825000e+000,,,,,,,,,,,,,,,,,,0,4.000000e+000,1.000000e+000,20,1,9.143982e-001,0,1,0,
1435318519.139,,9.999999e+002,3.320102e+002,4.862271e-006,0.000000e+000,3.185201e-001,0.000000e+000,3,8.323200e-001,1.825000e+000,,,,,,,,,,,,,,,,,,0,4.000000e+000,1.000000e+000,20,1,1.203918e-001,0,1,0,
1435318686.826,,9.999999e+002,3.317472e+002,4.866555e-006,0.000000e+000,3.165023e-001,0.000000e+000,3,8.294472e-001,1.825000e+000,,,,,,,,,,,,,,,,,,0,4.000000e+000,1.000000e+000,20,1,4.057007e-001,0,1,0,
1435318883.529,,9.999999e+002,3.253376e+002,4.967342e-006,0.000000e+000,3.073491e-001,0.000000e+000,3,8.309115e-001,1.825000e+000,,,,,,,,,,,,,,,,,,0,4.000000e+000,1.000000e+000,20,1,8.073120e-001,0,1,0,
1435319106.779,,9.999999e+002,3.197057e+002,5.086228e-006,0.000000e+000,2.977946e-001,0.000000e+000,3,8.330550e-001,1.825000e+000,,,,,,,,,,,,,,,,,,0,4.000000e+000,1.000000e+000,20,1,5.833130e-001,0,1,0,
1435319347.092,,9.999999e+002,3.135376e+002,5.179868e-006,0.000000e+000,2.848212e-001,0.000000e+000,3,8.383942e-001,1.825000e+000,,,,,,,,,,,,,,,,,,0,4.000000e+000,1.000000e+000,20,1,7.326050e-001,0,1,0,
1435319569.279,,9.999999e+002,3.076329e+002,5.305528e-006,0.000000e+000,2.714015e-001,0.000000e+000,3,8.470986e-001,1.825000e+000,,,,,,,,,,,,,,,,,,0,4.000000e+000,1.000000e+000,20,1,6.647949e-001,0,1,0,
1435319797.451,,9.999999e+002,3.015656e+002,5.417179e-006,0.000000e+000,2.634889e-001,0.000000e+000,3,8.488361e-001,1.825000e+000,,,,,,,,,,,,,,,,,,0,4.000000e+000,1.000000e+000,20,1,6.609802e-001,0,1,0,
1435320020.451,,9.999999e+002,2.956360e+002,5.544873e-006,0.000000e+000,2.562597e-001,0.000000e+000,3,8.405904e-001,1.825000e+000,,,,,,,,,,,,,,,,,,0,4.000000e+000,1.000000e+000,20,1,7.151794e-001,0,1,0,
1435320240.217,,9.999999e+002,2.896212e+002,5.654698e-006,0.000000e+000,2.491482e-001,0.000000e+000,3,8.477505e-001,1.825000e+000,,,,,,,,,,,,,,,,,,0,4.000000e+000,1.000000e+000,20,1,6.855774e-001,0,1,0,
1435320463.404,,9.999999e+002,2.835411e+002,5.828748e-006,0.000000e+000,2.432328e-001,0.000000e+000,3,8.469420e-001,1.825000e+000,,,,,,,,,,,,,,,,,,0,4.000000e+000,1.000000e+000,20,1,6.777039e-001,0,1,0,
1435320687.623,,9.999999e+002,2.775286e+002,6.028188e-006,0.000000e+000,2.436051e-001,0.000000e+000,3,8.447329e-001,1.825000e+000,,,,,,,,,,,,,,,,,,0,4.000000e+000,1.000000e+000,20,1,6.996765e-001,0,1,0,
1435320912.592,,9.999999e+002,2.714943e+002,6.253936e-006,0.000000e+000,2.433169e-001,0.000000e+000,3,8.441995e-001,1.825000e+000,,,,,,,,,,,,,,,,,,0,4.000000e+000,1.000000e+000,20,1,6.879883e-001,0,1,0,
1435321132.983,,9.999999e+002,2.656190e+002,6.484146e-006,0.000000e+000,2.414122e-001,0.000000e+000,3,8.489548e-001,1.825000e+000,,,,,,,,,,,,,,,,,,0,4.000000e+000,1.000000e+000,20,1,6.854858e-001,0,1,0,
1435321361.467,,9.999999e+002,2.596511e+002,6.617989e-006,0.000000e+000,2.419078e-001,0.000000e+000,3,8.482732e-001,1.825000e+000,,,,,,,,,,,,,,,,,,0,4.000000e+000,1.000000e+000,20,1,6.632996e-001,0,1,0,
1435321591.670,,9.999999e+002,2.535323e+002,6.716868e-006,0.000000e+000,2.502978e-001,0.000000e+000,3,8.453854e-001,1.825000e+000,,,,,,,,,,,,,,,,,,0,4.000000e+000,1.000000e+000,20,1,6.668091e-001,0,1,0,
1435321824.123,,9.999999e+002,2.475549e+002,6.928543e-006,0.000000e+000,2.486691e-001,0.000000e+000,3,8.492547e-001,1.825000e+000,,,,,,,,,,,,,,,,,,0,4.000000e+000,1.000000e+000,20,1,6.033020e-001,0,1,0,
1435322048.608,,9.999999e+002,2.416656e+002,7.194328e-006,0.000000e+000,2.460067e-001,0.000000e+000,3,8.501452e-001,1.825000e+000,,,,,,,,,,,,,,,,,,0,4.000000e+000,1.000000e+000,20,1,6.215057e-001,0,1,0,
1435322278.139,,9.999999e+002,2.356312e+002,7.465441e-006,0.000000e+000,2.445715e-001,0.000000e+000,3,8.542170e-001,1.825000e+000,,,,,,,,,,,,,,,,,,0,4.000000e+000,1.000000e+000,20,1,6.721954e-001,0,1,0,
1435322511.123,,9.999999e+002,2.294973e+002,7.711595e-006,0.000000e+000,2.407073e-001,0.000000e+000,3,8.526078e-001,1.825000e+000,,,,,,,,,,,,,,,,,,0,4.000000e+000,1.000000e+000,20,1,6.871033e-001,0,1,0,
1435322734.389,,9.999999e+002,2.236481e+002,7.915235e-006,0.000000e+000,2.343665e-001,0.000000e+000,3,8.579434e-001,1.825000e+000,,,,,,,,,,,,,,,,,,0,4.000000e+000,1.000000e+000,20,1,7.001038e-001,0,1,0,
1435322970.170,,9.999999e+002,2.175986e+002,8.061635e-006,0.000000e+000,2.299257e-001,0.000000e+000,3,8.571002e-001,1.825000e+000,,,,,,,,,,,,,,,,,,0,4.000000e+000,1.000000e+000,20,1,6.004028e-001,0,1,0,
1435323209.623,,9.999999e+002,2.115255e+002,8.183356e-006,0.000000e+000,2.217744e-001,0.000000e+000,3,8.573192e-001,1.825000e+000,,,,,,,,,,,,,,,,,,0,4.000000e+000,1.000000e+000,20,1,6.159058e-001,0,1,0,
1435323436.279,,9.999999e+002,2.056425e+002,8.298532e-006,0.000000e+000,2.174296e-001,0.000000e+000,3,8.572950e-001,1.825000e+000,,,,,,,,,,,,,,,,,,0,4.000000e+000,1.000000e+000,20,1,6.337891e-001,0,1,0,
1435323666.467,,9.999999e+002,1.995878e+002,8.436042e-006,0.000000e+000,2.108563e-001,0.000000e+000,3,8.593949e-001,1.825000e+000,,,,,,,,,,,,,,,,,,0,4.000000e+000,1.000000e+000,20,1,6.199036e-001,0,1,0,
1435323896.983,,9.999999e+002,1.936400e+002,8.561411e-006,0.000000e+000,2.056374e-001,0.000000e+000,3,8.624173e-001,1.825000e+000,,,,,,,,,,,,,,,,,,0,4.000000e+000,1.000000e+000,20,1,6.609039e-001,0,1,0,
1435324127.764,,9.999999e+002,1.876118e+002,8.670444e-006,0.000000e+000,1.982203e-001,0.000000e+000,3,8.596759e-001,1.825000e+000,,,,,,,,,,,,,,,,,,0,4.000000e+000,1.000000e+000,20,1,6.555023e-001,0,1,0,
1435324361.920,,9.999999e+002,1.816404e+002,8.809938e-006,0.000000e+000,1.934240e-001,0.000000e+000,3,8.624164e-001,1.825000e+000,,,,,,,,,,,,,,,,,,0,4.000000e+000,1.000000e+000,20,1,6.565094e-001,0,1,0,
1435324596.326,,9.999999e+002,1.755836e+002,8.938100e-006,0.000000e+000,1.876533e-001,0.000000e+000,3,8.652194e-001,1.825000e+000,,,,,,,,,,,,,,,,,,0,4.000000e+000,1.000000e+000,20,1,6.616974e-001,0,1,0,
1435324831.733,,9.999999e+002,1.695500e+002,9.072116e-006,0.000000e+000,1.816477e-001,0.000000e+000,3,8.622651e-001,1.825000e+000,,,,,,,,,,,,,,,,,,0,4.000000e+000,1.000000e+000,20,1,6.585999e-001,0,1,0,
1435325061.217,,9.999999e+002,1.635877e+002,9.199523e-006,0.000000e+000,1.780658e-001,0.000000e+000,3,8.647268e-001,1.825000e+000,,,,,,,,,,,,,,,,,,0,4.000000e+000,1.000000e+000,20,1,6.009064e-001,0,1,0,
1435325293.608,,9.999999e+002,1.576231e+002,9.321796e-006,0.000000e+000,1.738714e-001,0.000000e+000,3,8.646595e-001,1.825000e+000,,,,,,,,,,,,,,,,,,0,4.000000e+000,1.000000e+000,20,1,7.281952e-001,0,1,0,
1435325525.811,,9.999999e+002,1.516053e+002,9.446167e-006,0.000000e+000,1.706456e-001,0.000000e+000,3,8.621186e-001,1.825000e+000,,,,,,,,,,,,,,,,,,0,4.000000e+000,1.000000e+000,20,1,6.901093e-001,0,1,0,
1435325760.311,,9.999999e+002,1.455265e+002,9.594655e-006,0.000000e+000,1.671710e-001,0.000000e+000,3,8.632326e-001,1.825000e+000,,,,,,,,,,,,,,,,,,0,4.000000e+000,1.000000e+000,20,1,6.280060e-001,0,1,0,
1435325988.748,,9.999999e+002,1.395443e+002,9.735316e-006,0.000000e+000,1.657529e-001,0.000000e+000,3,8.569643e-001,1.825000e+000,,,,,,,,,,,,,,,,,,0,4.000000e+000,1.000000e+000,20,1,6.472931e-001,0,1,0,
1435326214.311,,9.999999e+002,1.336721e+002,9.913690e-006,0.000000e+000,1.673926e-001,0.000000e+000,3,8.516507e-001,1.825000e+000,,,,,,,,,,,,,,,,,,0,4.000000e+000,1.000000e+000,20,1,6.292877e-001,0,1,0,
1435326445.811,,9.999999e+002,1.276512e+002,1.007576e-005,0.000000e+000,1.679774e-001,0.000000e+000,3,8.422862e-001,1.825000e+000,,,,,,,,,,,,,,,,,,0,4.000000e+000,1.000000e+000,20,1,6.563034e-001,0,1,0,
1435326672.795,,9.999999e+002,1.216882e+002,1.015899e-005,0.000000e+000,1.696089e-001,0.000000e+000,3,8.382412e-001,1.825000e+000,,,,,,,,,,,,,,,,,,0,4.000000e+000,1.000000e+000,20,1,6.102982e-001,0,1,0,
1435326905.529,,9.999999e+002,1.155845e+002,1.018113e-005,0.000000e+000,1.722574e-001,0.000000e+000,3,8.360045e-001,1.825000e+000,,,,,,,,,,,,,,,,,,0,4.000000e+000,1.000000e+000,20,1,6.221008e-001,0,1,0,
1435327134.264,,9.999999e+002,1.096646e+002,1.015621e-005,0.000000e+000,1.761261e-001,0.000000e+000,3,8.310906e-001,1.825000e+000,,,,,,,,,,,,,,,,,,0,4.000000e+000,1.000000e+000,20,1,6.538010e-001,0,1,0,
1435327358.201,,9.999999e+002,1.036473e+002,1.008421e-005,0.000000e+000,1.816094e-001,0.000000e+000,3,8.258064e-001,1.825000e+000,,,,,,,,,,,,,,,,,,0,4.000000e+000,1.000000e+000,20,1,6.952057e-001,0,1,0,
1435327584.170,,9.999999e+002,9.764261e+001,9.886627e-006,0.000000e+000,1.934098e-001,0.000000e+000,3,8.213234e-001,1.825000e+000,,,,,,,,,,,,,,,,,,0,4.000000e+000,1.000000e+000,20,1,6.894836e-001,0,1,0,
1435327811.436,,9.999999e+002,9.162278e+001,9.626568e-006,0.000000e+000,2.119709e-001,0.000000e+000,3,8.188760e-001,1.825000e+000,,,,,,,,,,,,,,,,,,0,4.000000e+000,1.000000e+000,20,1,6.699066e-001,0,1,0,
1435328036.342,,9.999999e+002,8.561290e+001,9.257013e-006,0.000000e+000,2.425101e-001,0.000000e+000,3,8.117369e-001,1.825000e+000,,,,,,,,,,,,,,,,,,0,4.000000e+000,1.000000e+000,20,1,6.084137e-001,0,1,0,
1435328260.983,,9.999999e+002,7.947408e+001,8.396358e-006,0.000000e+000,3.070184e-001,0.000000e+000,3,7.900848e-001,1.825000e+000,,,,,,,,,,,,,,,,,,0,4.000000e+000,1.000000e+000,20,1,7.066498e-001,0,1,0,
1435328480.186,,9.999999e+002,7.351768e+001,6.359544e-006,0.000000e+000,5.088795e-001,0.000000e+000,3,7.181627e-001,1.825000e+000,,,,,,,,,,,,,,,,,,0,4.000000e+000,1.000000e+000,20,1,6.567764e-001,0,1,0,
1435328687.014,,9.999999e+002,6.761912e+001,5.717870e-006,0.000000e+000,6.322460e-001,0.000000e+000,3,6.449633e-001,1.825000e+000,,,,,,,,,,,,,,,,,,0,4.000000e+000,1.000000e+000,20,1,7.545013e-001,0,1,0,
1435328898.764,,9.999999e+002,6.147907e+001,5.627367e-006,0.000000e+000,6.893240e-001,0.000000e+000,3,6.180370e-001,1.825000e+000,,,,,,,,,,,,,,,,,,0,4.000000e+000,1.000000e+000,20,1,6.338997e-001,0,1,0,
1435329098.904,,9.999999e+002,5.559778e+001,5.640140e-006,0.000000e+000,6.788360e-001,0.000000e+000,3,6.298417e-001,1.825000e+000,,,,,,,,,,,,,,,,,,0,4.000000e+000,1.000000e+000,20,1,7.570610e-001,0,1,0,
1435329301.936,,9.999999e+002,4.960552e+001,6.006312e-006,0.000000e+000,5.706912e-001,0.000000e+000,3,6.680585e-001,1.825000e+000,,,,,,,,,,,,,,,,,,0,4.000000e+000,1.000000e+000,20,1,7.067986e-001,0,1,0,
1435329525.420,,9.999999e+002,4.357139e+001,6.024568e-006,0.000000e+000,5.585611e-001,0.000000e+000,3,6.644027e-001,1.825000e+000,,,,,,,,,,,,,,,,,,0,4.000000e+000,1.000000e+000,20,1,6.468773e-001,0,1,0,
1435329749.061,,9.999999e+002,3.746855e+001,6.148127e-006,0.000000e+000,5.253015e-001,0.000000e+000,3,6.785387e-001,1.825000e+000,,,,,,,,,,,,,,,,,,0,4.000000e+000,1.000000e+000,20,1,6.906776e-001,0,1,0,
1435329950.983,,9.999999e+002,3.152108e+001,6.388048e-006,0.000000e+000,4.878526e-001,0.000000e+000,3,6.933036e-001,1.825000e+000,,,,,,,,,,,,,,,,,,0,4.000000e+000,1.000000e+000,20,1,7.423000e-001,0,0,0,
1435330171.170,,9.999999e+002,2.378045e+001,7.061882e-006,0.000000e+000,4.035914e-001,0.000000e+000,3,7.243074e-001,1.825000e+000,,,,,,,,,,,,,,,,,,0,4.000000e+000,1.000000e+000,20,1,9.693146e-002,0,0,0,
1435330341.326,,9.999999e+002,1.950447e+001,7.893046e-006,0.000000e+000,3.337795e-001,0.000000e+000,3,7.492358e-001,1.825000e+000,,,,,,,,,,,,,,,,,,0,4.000000e+000,1.000000e+000,20,1,6.393509e-001,0,0,0,
1435330559.873,,9.999999e+002,1.352924e+001,1.036660e-005,0.000000e+000,2.089097e-001,0.000000e+000,3,7.910415e-001,1.825000e+000,,,,,,,,,,,,,,,,,,0,4.000000e+000,1.000000e+000,20,1,7.114201e-001,0,0,0,
1435330786.561,,9.999999e+002,7.647327e+000,1.699055e-005,0.000000e+000,7.111025e-002,0.000000e+000,3,8.476528e-001,1.825000e+000,,,,,,,,,,,,,,,,,,0,4.000000e+000,1.000000e+000,20,1,6.746311e-001,0,1,0,
1435333734.342,,1.000000e+004,3.500461e+002,-1.032403e-004,0.000000e+000,-1.479665e-001,0.000000e+000,3,9.800139e-001,1.825000e+000,,,,,,,,,,,,,,,,,,0,4.000000e+000,1.000000e+000,20,1,1.681519e-002,0,1,0,
1435333959.998,,1.000000e+004,3.432742e+002,-1.024962e-004,0.000000e+000,-1.451588e-001,0.000000e+000,3,9.818626e-001,1.825000e+000,,,,,,,,,,,,,,,,,,0,4.000000e+000,1.000000e+000,20,1,1.342682e+000,0,1,0,
1435334089.248,,1.000000e+004,3.373912e+002,-1.017981e-004,0.000000e+000,-1.430849e-001,0.000000e+000,3,9.826336e-001,1.825000e+000,,,,,,,,,,,,,,,,,,0,4.000000e+000,1.000000e+000,20,1,8.415222e-001,0,1,0,
1435334460.029,,1.000000e+004,3.316198e+002,-1.006703e-004,0.000000e+000,-1.439002e-001,0.000000e+000,3,9.788263e-001,1.825000e+000,,,,,,,,,,,,,,,,,,0,4.000000e+000,1.000000e+000,20,1,6.906738e-001,0,1,0,
1435334671.029,,1.000000e+004,3.256838e+002,-1.000065e-004,0.000000e+000,-1.447301e-001,0.000000e+000,3,9.810269e-001,1.825000e+000,,,,,,,,,,,,,,,,,,0,4.000000e+000,1.000000e+000,20,1,6.069031e-001,0,1,0,
1435334916.717,,1.000000e+004,3.196501e+002,-9.887394e-005,0.000000e+000,-1.490569e-001,0.000000e+000,3,9.818225e-001,1.825000e+000,,,,,,,,,,,,,,,,,,0,4.000000e+000,1.000000e+000,20,1,6.385803e-001,0,1,0,
1435335145.154,,1.000000e+004,3.136041e+002,-9.778840e-005,0.000000e+000,-1.528315e-001,0.000000e+000,3,9.813460e-001,1.825000e+000,,,,,,,,,,,,,,,,,,0,4.000000e+000,1.000000e+000,20,1,6.530151e-001,0,1,0,
1435335372.389,,1.000000e+004,3.075562e+002,-9.697706e-005,0.000000e+000,-1.567792e-001,0.000000e+000,3,9.831765e-001,1.825000e+000,,,,,,,,,,,,,,,,,,0,4.000000e+000,1.000000e+000,20,1,6.643982e-001,0,1,0,
1435335601.561,,1.000000e+004,3.015350e+002,-9.581296e-005,0.000000e+000,-1.618090e-001,0.000000e+000,3,9.822357e-001,1.825000e+000,,,,,,,,,,,,,,,,,,0,4.000000e+000,1.000000e+000,20,1,6.732178e-001,0,1,0,
1435335831.373,,1.000000e+004,2.954543e+002,-9.477479e-005,0.000000e+000,-1.662630e-001,0.000000e+000,3,9.832593e-001,1.825000e+000,,,,,,,,,,,,,,,,,,0,4.000000e+000,1.000000e+000,20,1,6.087952e-001,0,1,0,
1435336049.561,,1.000000e+004,2.896157e+002,-9.365445e-005,0.000000e+000,-1.690313e-001,0.000000e+000,3,9.823460e-001,1.825000e+000,,,,,,,,,,,,,,,,,,0,4.000000e+000,1.000000e+000,20,1,7.416992e-001,0,1,0,
1435336274.717,,1.000000e+004,2.836487e+002,-9.286334e-005,0.000000e+000,-1.715149e-001,0.000000e+000,3,9.824792e-001,1.825000e+000,,,,,,,,,,,,,,,,,,0,4.000000e+000,1.000000e+000,20,1,6.782837e-001,0,1,0,
1435336503.889,,1.000000e+004,2.775028e+002,-9.172186e-005,0.000000e+000,-1.763564e-001,0.000000e+000,3,9.792727e-001,1.825000e+000,,,,,,,,,,,,,,,,,,0,4.000000e+000,1.000000e+000,20,1,6.892090e-001,0,1,0,
1435336725.108,,1.000000e+004,2.715681e+002,-9.073153e-005,0.000000e+000,-1.788752e-001,0.000000e+000,3,9.786805e-001,1.825000e+000,,,,,,,,,,,,,,,,,,0,4.000000e+000,1.000000e+000,20,1,6.787109e-001,0,1,0,
1435336949.170,,1.000000e+004,2.656848e+002,-8.985833e-005,0.000000e+000,-1.805422e-001,0.000000e+000,3,9.794465e-001,1.825000e+000,,,,,,,,,,,,,,,,,,0,4.000000e+000,1.000000e+000,20,1,6.107178e-001,0,1,0,
1435337181.748,,1.000000e+004,2.596287e+002,-8.857239e-005,0.000000e+000,-1.838551e-001,0.000000e+000,3,9.769890e-001,1.825000e+000,,,,,,,,,,,,,,,,,,0,4.000000e+000,1.000000e+000,20,1,6.184082e-001,0,1,0,
1435337407.139,,1.000000e+004,2.536563e+002,-8.893018e-005,0.000000e+000,-1.835095e-001,0.000000e+000,3,9.803372e-001,1.825000e+000,,,,,,,,,,,,,,,,,,0,4.000000e+000,1.000000e+000,20,1,6.589050e-001,0,1,0,
1435337639.014,,1.000000e+004,2.476285e+002,-8.772446e-005,0.000000e+000,-1.858439e-001,0.000000e+000,3,9.787839e-001,1.825000e+000,,,,,,,,,,,,,,,,,,0,4.000000e+000,1.000000e+000,20,1,6.688080e-001,0,1,0,
1435337867.186,,1.000000e+004,2.415607e+002,-8.624871e-005,0.000000e+000,-1.843523e-001,0.000000e+000,3,9.773501e-001,1.825000e+000,,,,,,,,,,,,,,,,,,0,4.000000e+000,1.000000e+000,20,1,6.287994e-001,0,1,0,
1435338096.686,,1.000000e+004,2.355425e+002,-8.518092e-005,0.000000e+000,-1.844410e-001,0.000000e+000,3,9.775689e-001,1.825000e+000,,,,,,,,,,,,,,,,,,0,4.000000e+000,1.000000e+000,20,1,6.274872e-001,0,1,0,
1435338328.701,,1.000000e+004,2.295428e+002,-8.346245e-005,0.000000e+000,-1.871324e-001,0.000000e+000,3,9.750677e-001,1.825000e+000,,,,,,,,,,,,,,,,,,0,4.000000e+000,1.000000e+000,20,1,6.242981e-001,0,1,0,
1435338557.045,,1.000000e+004,2.234849e+002,-8.235528e-005,0.000000e+000,-1.859180e-001,0.000000e+000,3,9.710748e-001,1.825000e+000,,,,,,,,,,,,,,,,,,0,4.000000e+000,1.000000e+000,20,1,6.923981e-001,0,1,0,
1435338782.358,,1.000000e+004,2.175829e+002,-8.148798e-005,0.000000e+000,-1.879808e-001,0.000000e+000,3,9.739836e-001,1.825000e+000,,,,,,,,,,,,,,,,,,0,4.000000e+000,1.000000e+000,20,1,6.950989e-001,0,1,0,
1435339009.920,,1.000000e+004,2.116182e+002,-7.966908e-005,0.000000e+000,-1.875748e-001,0.000000e+000,3,9.751984e-001,1.825000e+000,,,,,,,,,,,,,,,,,,0,4.000000e+000,1.000000e+000,20,1,6.223907e-001,0,1,0,
1435339236.529,,1.000000e+004,2.056595e+002,-7.847599e-005,0.000000e+000,-1.884478e-001,0.000000e+000,3,9.742757e-001,1.825000e+000,,,,,,,,,,,,,,,,,,0,4.000000e+000,1.000000e+000,20,1,6.224976e-001,0,1,0,
1435339470.998,,1.000000e+004,1.996307e+002,-7.688795e-005,0.000000e+000,-1.891217e-001,0.000000e+000,3,9.690319e-001,1.825000e+000,,,,,,,,,,,,,,,,,,0,4.000000e+000,1.000000e+000,20,1,6.735992e-001,0,1,0,
1435339706.483,,1.000000e+004,1.936097e+002,-7.549038e-005,0.000000e+000,-1.895940e-001,0.000000e+000,3,9.716198e-001,1.825000e+000,,,,,,,,,,,,,,,,,,0,4.000000e+000,1.000000e+000,20,1,7.111053e-001,0,1,0,
1435339938.264,,1.000000e+004,1.875381e+002,-7.402897e-005,0.000000e+000,-1.891108e-001,0.000000e+000,3,9.686517e-001,1.825000e+000,,,,,,,,,,,,,,,,,,0,4.000000e+000,1.000000e+000,20,1,6.026917e-001,0,1,0,
1435340169.295,,1.000000e+004,1.816382e+002,-7.264149e-005,0.000000e+000,-1.898855e-001,0.000000e+000,3,9.697309e-001,1.825000e+000,,,,,,,,,,,,,,,,,,0,4.000000e+000,1.000000e+000,20,1,6.430054e-001,0,1,0,
1435340398.514,,1.000000e+004,1.756046e+002,-7.093445e-005,0.000000e+000,-1.899628e-001,0.000000e+000,3,9.686795e-001,1.825000e+000,,,,,,,,,,,,,,,,,,0,4.000000e+000,1.000000e+000,20,1,6.871033e-001,0,1,0,
1435340625.498,,1.000000e+004,1.696323e+002,-6.983815e-005,0.000000e+000,-1.894833e-001,0.000000e+000,3,9.654424e-001,1.825000e+000,,,,,,,,,,,,,,,,,,0,4.000000e+000,1.000000e+000,20,1,6.513977e-001,0,1,0,
1435340862.186,,1.000000e+004,1.635876e+002,-6.829721e-005,0.000000e+000,-1.904782e-001,0.000000e+000,3,9.670839e-001,1.825000e+000,,,,,,,,,,,,,,,,,,0,4.000000e+000,1.000000e+000,20,1,5.422974e-001,0,1,0,
1435341090.811,,1.000000e+004,1.576008e+002,-6.720707e-005,0.000000e+000,-1.914670e-001,0.000000e+000,3,9.630654e-001,1.825000e+000,,,,,,,,,,,,,,,,,,0,4.000000e+000,1.000000e+000,20,1,6.972961e-001,0,1,0,
1435341320.342,,1.000000e+004,1.516417e+002,-6.580290e-005,0.000000e+000,-1.934102e-001,0.000000e+000,3,9.587494e-001,1.825000e+000,,,,,,,,,,,,,,,,,,0,4.000000e+000,1.000000e+000,20,1,6.236115e-001,0,1,0,
1435341551.873,,1.000000e+004,1.455606e+002,-6.496740e-005,0.000000e+000,-1.923124e-001,0.000000e+000,3,9.596500e-001,1.825000e+000,,,,,,,,,,,,,,,,,,0,4.000000e+000,1.000000e+000,20,1,7.433014e-001,0,1,0,
1435341782.561,,1.000000e+004,1.394789e+002,-6.416739e-005,0.000000e+000,-1.926758e-001,0.000000e+000,3,9.663313e-001,1.825000e+000,,,,,,,,,,,,,,,,,,0,4.000000e+000,1.000000e+000,20,1,7.013092e-001,0,1,0,
1435342007.092,,1.000000e+004,1.336505e+002,-6.322676e-005,0.000000e+000,-1.930256e-001,0.000000e+000,3,9.604944e-001,1.825000e+000,,,,,,,,,,,,,,,,,,0,4.000000e+000,1.000000e+000,20,1,6.316986e-001,0,1,0,
1435342236.170,,1.000000e+004,1.276047e+002,-6.234879e-005,0.000000e+000,-1.954303e-001,0.000000e+000,3,9.535869e-001,1.825000e+000,,,,,,,,,,,,,,,,,,0,4.000000e+000,1.000000e+000,20,1,6.557999e-001,0,1,0,
1435342460.139,,1.000000e+004,1.216349e+002,-6.241546e-005,0.000000e+000,-1.931914e-001,0.000000e+000,3,9.553281e-001,1.825000e+000,,,,,,,,,,,,,,,,,,0,4.000000e+000,1.000000e+000,20,1,6.140976e-001,0,1,0,
1435342692.592,,1.000000e+004,1.155692e+002,-6.259664e-005,0.000000e+000,-1.900960e-001,0.000000e+000,3,9.636755e-001,1.825000e+000,,,,,,,,,,,,,,,,,,0,4.000000e+000,1.000000e+000,20,1,6.763000e-001,0,1,0,
1435342918.842,,1.000000e+004,1.095906e+002,-6.370396e-005,0.000000e+000,-1.882022e-001,0.000000e+000,3,9.597536e-001,1.825000e+000,,,,,,,,,,,,,,,,,,0,4.000000e+000,1.000000e+000,20,1,7.236023e-001,0,1,0,
1435343142.108,,1.000000e+004,1.036297e+002,-6.522668e-005,0.000000e+000,-1.871921e-001,0.000000e+000,3,9.595369e-001,1.825000e+000,,,,,,,,,,,,,,,,,,0,4.000000e+000,1.000000e+000,20,1,6.790009e-001,0,1,0,
1435343364.623,,1.000000e+004,9.758675e+001,-6.791252e-005,0.000000e+000,-1.834355e-001,0.000000e+000,3,9.654337e-001,1.825000e+000,,,,,,,,,,,,,,,,,,0,4.000000e+000,1.000000e+000,20,1,6.573334e-001,0,1,0,
1435343586.858,,1.000000e+004,9.153630e+001,-7.287975e-005,0.000000e+000,-1.793534e-001,0.000000e+000,3,9.654154e-001,1.825000e+000,,,,,,,,,,,,,,,,,,0,4.000000e+000,1.000000e+000,20,1,6.840057e-001,0,1,0,
1435343804.592,,1.000000e+004,8.561317e+001,-7.930255e-005,0.000000e+000,-1.743937e-001,0.000000e+000,3,9.720466e-001,1.825000e+000,,,,,,,,,,,,,,,,,,0,4.000000e+000,1.000000e+000,20,1,6.895447e-001,0,1,0,
1435344026.576,,1.000000e+004,7.945214e+001,-9.037690e-005,0.000000e+000,-1.625049e-001,0.000000e+000,3,9.588154e-001,1.825000e+000,,,,,,,,,,,,,,,,,,0,4.000000e+000,1.000000e+000,20,1,6.470947e-001,0,1,0,
1435344234.326,,1.000000e+004,7.362277e+001,-1.251883e-004,0.000000e+000,-1.553322e-001,0.000000e+000,3,9.800031e-001,1.825000e+000,,,,,,,,,,,,,,,,,,0,4.000000e+000,1.000000e+000,20,1,7.375717e-001,0,1,0,
1435344449.983,,1.000000e+004,6.746439e+001,-1.407459e-004,0.000000e+000,-1.513491e-001,0.000000e+000,3,9.844995e-001,1.825000e+000,,,,,,,,,,,,,,,,,,0,4.000000e+000,1.000000e+000,20,1,6.868057e-001,0,0,0,
1435344644.279,,1.000000e+004,6.149683e+001,-1.439678e-004,0.000000e+000,-1.634611e-001,0.000000e+000,3,9.796764e-001,1.825000e+000,,,,,,,,,,,,,,,,,,0,4.000000e+000,1.000000e+000,20,1,8.239594e-001,0,0,0,
1435344840.248,,1.000000e+004,5.534222e+001,-1.429446e-004,0.000000e+000,-1.636598e-001,0.000000e+000,3,9.799362e-001,1.825000e+000,,,,,,,,,,,,,,,,,,0,4.000000e+000,1.000000e+000,20,1,9.266090e-001,0,0,0,
1435345024.998,,1.000000e+004,4.963755e+001,-1.307750e-004,0.000000e+000,-1.655093e-001,0.000000e+000,3,9.707005e-001,1.825000e+000,,,,,,,,,,,,,,,,,,0,4.000000e+000,1.000000e+000,20,1,7.244186e-001,0,1,0,
1435345239.545,,1.000000e+004,4.365401e+001,-1.295211e-004,0.000000e+000,-1.650131e-001,0.000000e+000,3,9.690656e-001,1.825000e+000,,,,,,,,,,,,,,,,,,0,4.000000e+000,1.000000e+000,20,1,6.650887e-001,0,1,0,
1435345481.842,,1.000000e+004,3.757585e+001,-1.254952e-004,0.000000e+000,-1.663975e-001,0.000000e+000,3,9.663581e-001,1.825000e+000,,,,,,,,,,,,,,,,,,0,4.000000e+000,1.000000e+000,20,1,7.318611e-001,0,0,0,
1435345674.623,,1.000000e+004,3.159513e+001,-1.211208e-004,0.000000e+000,-1.690472e-001,0.000000e+000,3,9.631590e-001,1.825000e+000,,,,,,,,,,,,,,,,,,0,4.000000e+000,1.000000e+000,20,1,7.536087e-001,0,0,0,
1435345850.811,,1.000000e+004,2.543266e+001,-1.124910e-004,0.000000e+000,-1.729618e-001,0.000000e+000,3,9.573313e-001,1.825000e+000,,,,,,,,,,,,,,,,,,0,4.000000e+000,1.000000e+000,20,1,7.926006e-001,0,0,0,
1435346064.186,,1.000000e+004,1.955564e+001,-9.704271e-005,0.000000e+000,-1.814690e-001,0.000000e+000,3,9.424774e-001,1.825000e+000,,,,,,,,,,,,,,,,,,0,4.000000e+000,1.000000e+000,20,1,6.886806e-001,0,0,0,
1435346280.420,,1.000000e+004,1.362912e+001,-6.688241e-005,0.000000e+000,-2.093898e-001,0.000000e+000,3,8.953054e-001,1.825000e+000,,,,,,,,,,,,,,,,,,0,4.000000e+000,1.000000e+000,20,1,6.931705e-001,0,1,0,
1435346539.576,,1.000000e+004,7.034013e+000,2.373468e-005,0.000000e+000,2.572781e-001,0.000000e+000,3,5.908070e-001,1.825000e+000,,,,,,,,,,,,,,,,,,0,4.000000e+000,1.000000e+000,20,1,4.347820e-001,0,1,0,
1435349517.764,,3.500000e+004,3.500461e+002,-4.178444e-004,0.000000e+000,-1.291426e-001,0.000000e+000,3,9.720203e-001,1.825000e+000,,,,,,,,,,,,,,,,,,0,4.000000e+000,1.000000e+000,20,1,1.681519e-002,0,1,0,
1435349757.342,,3.500000e+004,3.433710e+002,-4.165950e-004,0.000000e+000,-1.236209e-001,0.000000e+000,3,9.676033e-001,1.825000e+000,,,,,,,,,,,,,,,,,,0,4.000000e+000,1.000000e+000,20,1,1.181488e+000,0,1,0,
1435349914.967,,3.500000e+004,3.375859e+002,-4.143983e-004,0.000000e+000,-1.204095e-001,0.000000e+000,3,9.696420e-001,1.825000e+000,,,,,,,,,,,,,,,,,,0,4.000000e+000,1.000000e+000,20,1,6.395874e-001,0,1,0,
1435350239.983,,3.500000e+004,3.315297e+002,-4.115204e-004,0.000000e+000,-1.219345e-001,0.000000e+000,3,9.690594e-001,1.825000e+000,,,,,,,,,,,,,,,,,,0,4.000000e+000,1.000000e+000,20,1,6.901855e-001,0,1,0,
1435350459.217,,3.500000e+004,3.256260e+002,-4.079847e-004,0.000000e+000,-1.204214e-001,0.000000e+000,3,9.673422e-001,1.825000e+000,,,,,,,,,,,,,,,,,,0,4.000000e+000,1.000000e+000,20,1,6.354980e-001,0,1,0,
1435350695.529,,3.500000e+004,3.196016e+002,-4.045074e-004,0.000000e+000,-1.241446e-001,0.000000e+000,3,9.671945e-001,1.825000e+000,,,,,,,,,,,,,,,,,,0,4.000000e+000,1.000000e+000,20,1,6.523132e-001,0,1,0,
1435350921.811,,3.500000e+004,3.136108e+002,-4.013353e-004,0.000000e+000,-1.295343e-001,0.000000e+000,3,9.719601e-001,1.825000e+000,,,,,,,,,,,,,,,,,,0,4.000000e+000,1.000000e+000,20,1,6.664124e-001,0,1,0,
1435351147.186,,3.500000e+004,3.076328e+002,-3.986877e-004,0.000000e+000,-1.316185e-001,0.000000e+000,3,9.696692e-001,1.825000e+000,,,,,,,,,,,,,,,,,,0,4.000000e+000,1.000000e+000,20,1,5.879822e-001,0,1,0,
1435351371.201,,3.500000e+004,3.016941e+002,-3.959986e-004,0.000000e+000,-1.338305e-001,0.000000e+000,3,9.699010e-001,1.825000e+000,,,,,,,,,,,,,,,,,,0,4.000000e+000,1.000000e+000,20,1,6.004028e-001,0,1,0,
1435351600.873,,3.500000e+004,2.955950e+002,-3.914216e-004,0.000000e+000,-1.375017e-001,0.000000e+000,3,9.685000e-001,1.825000e+000,,,,,,,,,,,,,,,,,,0,4.000000e+000,1.000000e+000,20,1,6.797180e-001,0,1,0,
1435351824.748,,3.500000e+004,2.896212e+002,-3.888858e-004,0.000000e+000,-1.403467e-001,0.000000e+000,3,9.696295e-001,1.825000e+000,,,,,,,,,,,,,,,,,,0,4.000000e+000,1.000000e+000,20,1,6.405945e-001,0,1,0,
1435352054.170,,3.500000e+004,2.835626e+002,-3.853654e-004,0.000000e+000,-1.435930e-001,0.000000e+000,3,9.706795e-001,1.825000e+000,,,,,,,,,,,,,,,,,,0,4.000000e+000,1.000000e+000,20,1,6.778870e-001,0,1,0,
1435352276.170,,3.500000e+004,2.776108e+002,-3.815015e-004,0.000000e+000,-1.452667e-001,0.000000e+000,3,9.691632e-001,1.825000e+000,,,,,,,,,,,,,,,,,,0,4.000000e+000,1.000000e+000,20,1,6.795044e-001,0,1,0,
1435352500.701,,3.500000e+004,2.716171e+002,-3.789553e-004,0.000000e+000,-1.463338e-001,0.000000e+000,3,9.687766e-001,1.825000e+000,,,,,,,,,,,,,,,,,,0,4.000000e+000,1.000000e+000,20,1,6.199036e-001,0,1,0,
1435352733.295,,3.500000e+004,2.656238e+002,-3.766842e-004,0.000000e+000,-1.488224e-001,0.000000e+000,3,9.701771e-001,1.825000e+000,,,,,,,,,,,,,,,,,,0,4.000000e+000,1.000000e+000,20,1,6.950073e-001,0,1,0,
1435352962.029,,3.500000e+004,2.595795e+002,-3.726312e-004,0.000000e+000,-1.477270e-001,0.000000e+000,3,9.686720e-001,1.825000e+000,,,,,,,,,,,,,,,,,,0,4.000000e+000,1.000000e+000,20,1,6.271057e-001,0,1,0,
1435353186.795,,3.500000e+004,2.536606e+002,-3.723587e-004,0.000000e+000,-1.467754e-001,0.000000e+000,3,9.672014e-001,1.825000e+000,,,,,,,,,,,,,,,,,,0,4.000000e+000,1.000000e+000,20,1,6.674957e-001,0,1,0,
1435353415.311,,3.500000e+004,2.475876e+002,-3.700075e-004,0.000000e+000,-1.468922e-001,0.000000e+000,3,9.691184e-001,1.825000e+000,,,,,,,,,,,,,,,,,,0,4.000000e+000,1.000000e+000,20,1,6.198120e-001,0,1,0,
1435353640.545,,3.500000e+004,2.416228e+002,-3.639777e-004,0.000000e+000,-1.473577e-001,0.000000e+000,3,9.706507e-001,1.825000e+000,,,,,,,,,,,,,,,,,,0,4.000000e+000,1.000000e+000,20,1,6.290894e-001,0,1,0,
1435353868.779,,3.500000e+004,2.356053e+002,-3.611381e-004,0.000000e+000,-1.459895e-001,0.000000e+000,3,9.693124e-001,1.825000e+000,,,,,,,,,,,,,,,,,,0,4.000000e+000,1.000000e+000,20,1,6.351929e-001,0,1,0,
1435354103.311,,3.500000e+004,2.294516e+002,-3.561964e-004,0.000000e+000,-1.461664e-001,0.000000e+000,3,9.683079e-001,1.825000e+000,,,,,,,,,,,,,,,,,,0,4.000000e+000,1.000000e+000,20,1,6.238098e-001,0,1,0,
1435354324.858,,3.500000e+004,2.236215e+002,-3.511242e-004,0.000000e+000,-1.440302e-001,0.000000e+000,3,9.700089e-001,1.825000e+000,,,,,,,,,,,,,,,,,,0,4.000000e+000,1.000000e+000,20,1,6.732941e-001,0,1,0,
1435354557.061,,3.500000e+004,2.176113e+002,-3.468786e-004,0.000000e+000,-1.451450e-001,0.000000e+000,3,9.701581e-001,1.825000e+000,,,,,,,,,,,,,,,,,,0,4.000000e+000,1.000000e+000,20,1,6.636047e-001,0,1,0,
1435354789.139,,3.500000e+004,2.115016e+002,-3.414529e-004,0.000000e+000,-1.446943e-001,0.000000e+000,3,9.690639e-001,1.825000e+000,,,,,,,,,,,,,,,,,,0,4.000000e+000,1.000000e+000,20,1,6.396942e-001,0,1,0,
1435355016.029,,3.500000e+004,2.055633e+002,-3.376319e-004,0.000000e+000,-1.437164e-001,0.000000e+000,3,9.697587e-001,1.825000e+000,,,,,,,,,,,,,,,,,,0,4.000000e+000,1.000000e+000,20,1,6.331940e-001,0,1,0,
1435355243.779,,3.500000e+004,1.996334e+002,-3.332371e-004,0.000000e+000,-1.430716e-001,0.000000e+000,3,9.693748e-001,1.825000e+000,,,,,,,,,,,,,,,,,,0,4.000000e+000,1.000000e+000,20,1,6.363068e-001,0,1,0,
1435355470.936,,3.500000e+004,1.935970e+002,-3.284557e-004,0.000000e+000,-1.429974e-001,0.000000e+000,3,9.706337e-001,1.825000e+000,,,,,,,,,,,,,,,,,,0,4.000000e+000,1.000000e+000,20,1,6.555023e-001,0,1,0,
1435355702.561,,3.500000e+004,1.875882e+002,-3.235538e-004,0.000000e+000,-1.416048e-001,0.000000e+000,3,9.697966e-001,1.825000e+000,,,,,,,,,,,,,,,,,,0,4.000000e+000,1.000000e+000,20,1,7.122040e-001,0,1,0,
1435355932.826,,3.500000e+004,1.815780e+002,-3.187419e-004,0.000000e+000,-1.404037e-001,0.000000e+000,3,9.698113e-001,1.825000e+000,,,,,,,,,,,,,,,,,,0,4.000000e+000,1.000000e+000,20,1,6.650085e-001,0,1,0,
1435356162.967,,3.500000e+004,1.755879e+002,-3.138252e-004,0.000000e+000,-1.404044e-001,0.000000e+000,3,9.699347e-001,1.825000e+000,,,,,,,,,,,,,,,,,,0,4.000000e+000,1.000000e+000,20,1,6.700897e-001,0,1,0,
1435356394.561,,3.500000e+004,1.695951e+002,-3.095050e-004,0.000000e+000,-1.393638e-001,0.000000e+000,3,9.692798e-001,1.825000e+000,,,,,,,,,,,,,,,,,,0,4.000000e+000,1.000000e+000,20,1,6.707916e-001,0,1,0,
1435356625.514,,3.500000e+004,1.636171e+002,-3.049632e-004,0.000000e+000,-1.386577e-001,0.000000e+000,3,9.695627e-001,1.825000e+000,,,,,,,,,,,,,,,,,,0,4.000000e+000,1.000000e+000,20,1,6.157990e-001,0,1,0,
1435356852.014,,3.500000e+004,1.576229e+002,-3.010939e-004,0.000000e+000,-1.376614e-001,0.000000e+000,3,9.694504e-001,1.825000e+000,,,,,,,,,,,,,,,,,,0,4.000000e+000,1.000000e+000,20,1,6.255951e-001,0,1,0,
1435357081.561,,3.500000e+004,1.516386e+002,-2.974750e-004,0.000000e+000,-1.324829e-001,0.000000e+000,3,9.467601e-001,1.825000e+000,,,,,,,,,,,,,,,,,,0,4.000000e+000,1.000000e+000,20,1,6.873016e-001,0,1,0,
1435357316.389,,3.500000e+004,1.456032e+002,-2.958932e-004,0.000000e+000,-1.321926e-001,0.000000e+000,3,9.554994e-001,1.825000e+000,,,,,,,,,,,,,,,,,,0,4.000000e+000,1.000000e+000,20,1,6.168060e-001,0,1,0,
1435357546.545,,3.500000e+004,1.395797e+002,-2.905557e-004,0.000000e+000,-1.357869e-001,0.000000e+000,3,9.686024e-001,1.825000e+000,,,,,,,,,,,,,,,,,,0,4.000000e+000,1.000000e+000,20,1,5.709991e-001,0,1,0,
1435357777.811,,3.500000e+004,1.335988e+002,-2.870930e-004,0.000000e+000,-1.335823e-001,0.000000e+000,3,9.654339e-001,1.825000e+000,,,,,,,,,,,,,,,,,,0,4.000000e+000,1.000000e+000,20,1,6.287994e-001,0,1,0,
1435358010.092,,3.500000e+004,1.275907e+002,-2.870992e-004,0.000000e+000,-1.345933e-001,0.000000e+000,3,9.678808e-001,1.825000e+000,,,,,,,,,,,,,,,,,,0,4.000000e+000,1.000000e+000,20,1,6.184998e-001,0,1,0,
1435358233.326,,3.500000e+004,1.216756e+002,-2.855245e-004,0.000000e+000,-1.321622e-001,0.000000e+000,3,9.694445e-001,1.825000e+000,,,,,,,,,,,,,,,,,,0,4.000000e+000,1.000000e+000,20,1,6.443024e-001,0,1,0,
1435358460.811,,3.500000e+004,1.156779e+002,-2.867364e-004,0.000000e+000,-1.309016e-001,0.000000e+000,3,9.647146e-001,1.825000e+000,,,,,,,,,,,,,,,,,,0,4.000000e+000,1.000000e+000,20,1,5.916977e-001,0,1,0,
1435358685.326,,3.500000e+004,1.095639e+002,-2.920980e-004,0.000000e+000,-1.340058e-001,0.000000e+000,3,9.609816e-001,1.825000e+000,,,,,,,,,,,,,,,,,,0,4.000000e+000,1.000000e+000,20,1,6.421051e-001,0,1,0,
1435358906.795,,3.500000e+004,1.036171e+002,-2.972125e-004,0.000000e+000,-1.279292e-001,0.000000e+000,3,9.647290e-001,1.825000e+000,,,,,,,,,,,,,,,,,,0,4.000000e+000,1.000000e+000,20,1,7.042999e-001,0,1,0,
1435359132.654,,3.500000e+004,9.756813e+001,-3.057879e-004,0.000000e+000,-1.237959e-001,0.000000e+000,3,9.602007e-001,1.825000e+000,,,,,,,,,,,,,,,,,,0,4.000000e+000,1.000000e+000,20,1,6.427841e-001,0,1,0,
1435359352.467,,3.500000e+004,9.161009e+001,-3.240314e-004,0.000000e+000,-1.276895e-001,0.000000e+000,3,9.677512e-001,1.825000e+000,,,,,,,,,,,,,,,,,,0,4.000000e+000,1.000000e+000,20,1,6.850281e-001,0,1,0,
1435359569.045,,3.500000e+004,8.568398e+001,-3.481096e-004,0.000000e+000,-1.250314e-001,0.000000e+000,3,9.643114e-001,1.825000e+000,,,,,,,,,,,,,,,,,,0,4.000000e+000,1.000000e+000,20,1,6.206207e-001,0,1,0,
1435359829.670,,3.500000e+004,7.847014e+001,-4.142965e-004,0.000000e+000,-1.230150e-001,0.000000e+000,3,9.546742e-001,1.825000e+000,,,,,,,,,,,,,,,,,,0,4.000000e+000,1.000000e+000,20,1,7.156296e-001,0,1,0,
1435360007.545,,3.500000e+004,7.348949e+001,-5.076525e-004,0.000000e+000,-1.200003e-001,0.000000e+000,3,9.675694e-001,1.825000e+000,,,,,,,,,,,,,,,,,,0,4.000000e+000,1.000000e+000,20,1,6.751709e-001,0,1,0,
1435360258.561,,3.500000e+004,6.634182e+001,-5.738547e-004,0.000000e+000,-1.217436e-001,0.000000e+000,3,9.623379e-001,1.825000e+000,,,,,,,,,,,,,,,,,,0,4.000000e+000,1.000000e+000,20,1,7.515259e-001,0,1,0,
1435360425.514,,3.500000e+004,6.151940e+001,-5.836154e-004,0.000000e+000,-1.229976e-001,0.000000e+000,3,9.702019e-001,1.825000e+000,,,,,,,,,,,,,,,,,,0,4.000000e+000,1.000000e+000,20,1,6.383629e-001,0,1,0,
1435360629.545,,3.500000e+004,5.548143e+001,-5.806474e-004,0.000000e+000,-1.227892e-001,0.000000e+000,3,9.721976e-001,1.825000e+000,,,,,,,,,,,,,,,,,,0,4.000000e+000,1.000000e+000,20,1,7.520981e-001,0,0,0,
1435360828.498,,3.500000e+004,4.949857e+001,-5.427002e-004,0.000000e+000,-1.205711e-001,0.000000e+000,3,9.752380e-001,1.825000e+000,,,,,,,,,,,,,,,,,,0,4.000000e+000,1.000000e+000,20,1,8.629227e-001,0,0,0,
1435361024.092,,3.500000e+004,4.337469e+001,-5.376354e-004,0.000000e+000,-1.213431e-001,0.000000e+000,3,9.780805e-001,1.825000e+000,,,,,,,,,,,,,,,,,,0,4.000000e+000,1.000000e+000,20,1,7.878609e-001,0,0,0,
1435361213.779,,3.500000e+004,3.749730e+001,-5.280122e-004,0.000000e+000,-1.200421e-001,0.000000e+000,3,9.757761e-001,1.825000e+000,,,,,,,,,,,,,,,,,,0,4.000000e+000,1.000000e+000,20,1,7.382126e-001,0,1,0,
1435361417.795,,3.500000e+004,3.155701e+001,-5.114333e-004,0.000000e+000,-1.219201e-001,0.000000e+000,3,9.792492e-001,1.825000e+000,,,,,,,,,,,,,,,,,,0,4.000000e+000,1.000000e+000,20,1,6.204891e-001,0,1,0,
1435361635.639,,3.500000e+004,2.558815e+001,-4.837600e-004,0.000000e+000,-1.224287e-001,0.000000e+000,3,9.808249e-001,1.825000e+000,,,,,,,,,,,,,,,,,,0,4.000000e+000,1.000000e+000,20,1,7.591305e-001,0,1,0,
1435361859.686,,3.500000e+004,1.956237e+001,-4.328101e-004,0.000000e+000,-1.229427e-001,0.000000e+000,3,9.826660e-001,1.825000e+000,,,,,,,,,,,,,,,,,,0,4.000000e+000,1.000000e+000,20,1,6.170292e-001,0,0,0,
1435362080.639,,3.500000e+004,1.358274e+001,-3.345025e-004,0.000000e+000,-1.255495e-001,0.000000e+000,3,9.826336e-001,1.825000e+000,,,,,,,,,,,,,,,,,,0,4.000000e+000,1.000000e+000,20,1,6.795197e-001,0,0,0,
1435362365.514,,3.500000e+004,6.647731e+000,-6.240421e-005,0.000000e+000,-1.735710e-001,0.000000e+000,3,7.702757e-001,1.825000e+000,,,,,,,,,,,,,,,,,,0,4.000000e+000,1.000000e+000,20,1,3.512340e-001,0,1,0,
1435365368.358,,7.000000e+004,3.500461e+002,-8.670796e-004,0.000000e+000,-1.198043e-001,0.000000e+000,3,9.638759e-001,1.825000e+000,,,,,,,,,,,,,,,,,,0,4.000000e+000,1.000000e+000,20,1,1.681519e-002,0,1,0,
1435365588.608,,7.000000e+004,3.429914e+002,-8.616344e-004,0.000000e+000,-1.160090e-001,0.000000e+000,3,9.628686e-001,1.825000e+000,,,,,,,,,,,,,,,,,,0,4.000000e+000,1.000000e+000,20,1,1.324097e+000,0,1,0,
1435365698.404,,7.000000e+004,3.374850e+002,-8.582548e-004,0.000000e+000,-1.131212e-001,0.000000e+000,3,9.635585e-001,1.825000e+000,,,,,,,,,,,,,,,,,,0,4.000000e+000,1.000000e+000,20,1,9.977722e-001,0,1,0,
1435366093.904,,7.000000e+004,3.315897e+002,-8.498598e-004,0.000000e+000,-1.132582e-001,0.000000e+000,3,9.631415e-001,1.825000e+000,,,,,,,,,,,,,,,,,,0,4.000000e+000,1.000000e+000,20,1,6.604919e-001,0,1,0,
1435366308.483,,7.000000e+004,3.255971e+002,-8.470126e-004,0.000000e+000,-1.138954e-001,0.000000e+000,3,9.674091e-001,1.825000e+000,,,,,,,,,,,,,,,,,,0,4.000000e+000,1.000000e+000,20,1,6.065979e-001,0,1,0,
1435366549.154,,7.000000e+004,3.196223e+002,-8.386664e-004,0.000000e+000,-1.193334e-001,0.000000e+000,3,9.664888e-001,1.825000e+000,,,,,,,,,,,,,,,,,,0,4.000000e+000,1.000000e+000,20,1,6.384888e-001,0,1,0,
1435366776.576,,7.000000e+004,3.136308e+002,-8.343504e-004,0.000000e+000,-1.209836e-001,0.000000e+000,3,9.638973e-001,1.825000e+000,,,,,,,,,,,,,,,,,,0,4.000000e+000,1.000000e+000,20,1,7.064209e-001,0,1,0,
1435367009.764,,7.000000e+004,3.076776e+002,-8.292618e-004,0.000000e+000,-1.247470e-001,0.000000e+000,3,9.628765e-001,1.825000e+000,,,,,,,,,,,,,,,,,,0,4.000000e+000,1.000000e+000,20,1,6.266174e-001,0,1,0,
1435367240.951,,7.000000e+004,3.016389e+002,-8.190896e-004,0.000000e+000,-1.278023e-001,0.000000e+000,3,9.622244e-001,1.825000e+000,,,,,,,,,,,,,,,,,,0,4.000000e+000,1.000000e+000,20,1,5.390015e-001,0,1,0,
1435367470.014,,7.000000e+004,2.956009e+002,-8.147791e-004,0.000000e+000,-1.290251e-001,0.000000e+000,3,9.619072e-001,1.825000e+000,,,,,,,,,,,,,,,,,,0,4.000000e+000,1.000000e+000,20,1,7.149048e-001,0,1,0,
1435367699.451,,7.000000e+004,2.895201e+002,-8.068561e-004,0.000000e+000,-1.319400e-001,0.000000e+000,3,9.626011e-001,1.825000e+000,,,,,,,,,,,,,,,,,,0,4.000000e+000,1.000000e+000,20,1,6.400757e-001,0,1,0,
1435367922.123,,7.000000e+004,2.835518e+002,-8.014200e-004,0.000000e+000,-1.332577e-001,0.000000e+000,3,9.628305e-001,1.825000e+000,,,,,,,,,,,,,,,,,,0,4.000000e+000,1.000000e+000,20,1,6.130981e-001,0,1,0,
1435368146.764,,7.000000e+004,2.776418e+002,-7.959621e-004,0.000000e+000,-1.360150e-001,0.000000e+000,3,9.632461e-001,1.825000e+000,,,,,,,,,,,,,,,,,,0,4.000000e+000,1.000000e+000,20,1,6.591187e-001,0,1,0,
1435368377.998,,7.000000e+004,2.715876e+002,-7.885072e-004,0.000000e+000,-1.388058e-001,0.000000e+000,3,9.656175e-001,1.825000e+000,,,,,,,,,,,,,,,,,,0,4.000000e+000,1.000000e+000,20,1,6.197815e-001,0,1,0,
1435368604.748,,7.000000e+004,2.655627e+002,-7.807549e-004,0.000000e+000,-1.383297e-001,0.000000e+000,3,9.608712e-001,1.825000e+000,,,,,,,,,,,,,,,,,,0,4.000000e+000,1.000000e+000,20,1,6.852112e-001,0,1,0,
1435368835.154,,7.000000e+004,2.595302e+002,-7.736966e-004,0.000000e+000,-1.397010e-001,0.000000e+000,3,9.645484e-001,1.825000e+000,,,,,,,,,,,,,,,,,,0,4.000000e+000,1.000000e+000,20,1,6.716919e-001,0,1,0,
1435369063.983,,7.000000e+004,2.535280e+002,-7.776805e-004,0.000000e+000,-1.375493e-001,0.000000e+000,3,9.622572e-001,1.825000e+000,,,,,,,,,,,,,,,,,,0,4.000000e+000,1.000000e+000,20,1,6.069031e-001,0,1,0,
1435369292.154,,7.000000e+004,2.475713e+002,-7.694530e-004,0.000000e+000,-1.371938e-001,0.000000e+000,3,9.613186e-001,1.825000e+000,,,,,,,,,,,,,,,,,,0,4.000000e+000,1.000000e+000,20,1,5.543060e-001,0,1,0,
1435369523.701,,7.000000e+004,2.415880e+002,-7.649522e-004,0.000000e+000,-1.389918e-001,0.000000e+000,3,9.575553e-001,1.825000e+000,,,,,,,,,,,,,,,,,,0,4.000000e+000,1.000000e+000,20,1,6.676941e-001,0,1,0,
1435369753.108,,7.000000e+004,2.355278e+002,-7.512601e-004,0.000000e+000,-1.341675e-001,0.000000e+000,3,9.624293e-001,1.825000e+000,,,,,,,,,,,,,,,,,,0,4.000000e+000,1.000000e+000,20,1,6.864929e-001,0,1,0,
1435369980.108,,7.000000e+004,2.295462e+002,-7.425962e-004,0.000000e+000,-1.358399e-001,0.000000e+000,3,9.656733e-001,1.825000e+000,,,,,,,,,,,,,,,,,,0,4.000000e+000,1.000000e+000,20,1,6.312866e-001,0,1,0,
1435370205.389,,7.000000e+004,2.235881e+002,-7.329540e-004,0.000000e+000,-1.350615e-001,0.000000e+000,3,9.566469e-001,1.825000e+000,,,,,,,,,,,,,,,,,,0,4.000000e+000,1.000000e+000,20,1,6.595917e-001,0,1,0,
1435370461.061,,7.000000e+004,2.169810e+002,-7.241237e-004,0.000000e+000,-1.337418e-001,0.000000e+000,3,9.623718e-001,1.825000e+000,,,,,,,,,,,,,,,,,,0,4.000000e+000,1.000000e+000,20,1,6.221008e-001,0,1,0,
1435370665.795,,7.000000e+004,2.116362e+002,-7.156787e-004,0.000000e+000,-1.333565e-001,0.000000e+000,3,9.616151e-001,1.825000e+000,,,,,,,,,,,,,,,,,,0,4.000000e+000,1.000000e+000,20,1,6.704102e-001,0,1,0,
1435370900.029,,7.000000e+004,2.056792e+002,-7.070763e-004,0.000000e+000,-1.330320e-001,0.000000e+000,3,9.602994e-001,1.825000e+000,,,,,,,,,,,,,,,,,,0,4.000000e+000,1.000000e+000,20,1,6.282959e-001,0,1,0,
1435371137.498,,7.000000e+004,1.995719e+002,-6.969752e-004,0.000000e+000,-1.302781e-001,0.000000e+000,3,9.595398e-001,1.825000e+000,,,,,,,,,,,,,,,,,,0,4.000000e+000,1.000000e+000,20,1,6.304932e-001,0,1,0,
1435371363.670,,7.000000e+004,1.936147e+002,-6.872528e-004,0.000000e+000,-1.304987e-001,0.000000e+000,3,9.611433e-001,1.825000e+000,,,,,,,,,,,,,,,,,,0,4.000000e+000,1.000000e+000,20,1,6.607056e-001,0,1,0,
1435371594.967,,7.000000e+004,1.876333e+002,-6.805385e-004,0.000000e+000,-1.288019e-001,0.000000e+000,3,9.580024e-001,1.825000e+000,,,,,,,,,,,,,,,,,,0,4.000000e+000,1.000000e+000,20,1,7.077942e-001,0,1,0,
1435371827.670,,7.000000e+004,1.816472e+002,-6.710405e-004,0.000000e+000,-1.283986e-001,0.000000e+000,3,9.568642e-001,1.825000e+000,,,,,,,,,,,,,,,,,,0,4.000000e+000,1.000000e+000,20,1,6.788025e-001,0,1,0,
1435372056.561,,7.000000e+004,1.756548e+002,-6.600861e-004,0.000000e+000,-1.266440e-001,0.000000e+000,3,9.594829e-001,1.825000e+000,,,,,,,,,,,,,,,,,,0,4.000000e+000,1.000000e+000,20,1,6.622925e-001,0,1,0,
1435372294.811,,7.000000e+004,1.695714e+002,-6.510685e-004,0.000000e+000,-1.257394e-001,0.000000e+000,3,9.613819e-001,1.825000e+000,,,,,,,,,,,,,,,,,,0,4.000000e+000,1.000000e+000,20,1,5.998993e-001,0,1,0,
1435372523.576,,7.000000e+004,1.635825e+002,-6.401963e-004,0.000000e+000,-1.269136e-001,0.000000e+000,3,9.634157e-001,1.825000e+000,,,,,,,,,,,,,,,,,,0,4.000000e+000,1.000000e+000,20,1,6.924896e-001,0,1,0,
1435372752.998,,7.000000e+004,1.575973e+002,-6.330024e-004,0.000000e+000,-1.243307e-001,0.000000e+000,3,9.604861e-001,1.825000e+000,,,,,,,,,,,,,,,,,,0,4.000000e+000,1.000000e+000,20,1,6.082916e-001,0,1,0,
1435372986.436,,7.000000e+004,1.515367e+002,-6.247266e-004,0.000000e+000,-1.215270e-001,0.000000e+000,3,9.588138e-001,1.825000e+000,,,,,,,,,,,,,,,,,,0,4.000000e+000,1.000000e+000,20,1,6.229095e-001,0,1,0,
1435373213.889,,7.000000e+004,1.456180e+002,-6.191786e-004,0.000000e+000,-1.224454e-001,0.000000e+000,3,9.597526e-001,1.825000e+000,,,,,,,,,,,,,,,,,,0,4.000000e+000,1.000000e+000,20,1,6.937103e-001,0,1,0,
1435373446.904,,7.000000e+004,1.395551e+002,-6.297116e-004,0.000000e+000,-1.247214e-001,0.000000e+000,3,9.524639e-001,1.825000e+000,,,,,,,,,,,,,,,,,,0,4.000000e+000,1.000000e+000,20,1,5.599976e-001,0,1,0,
1435373676.920,,7.000000e+004,1.335597e+002,-6.126324e-004,0.000000e+000,-1.211640e-001,0.000000e+000,3,9.456156e-001,1.825000e+000,,,,,,,,,,,,,,,,,,0,4.000000e+000,1.000000e+000,20,1,6.410065e-001,0,1,0,
1435373899.701,,7.000000e+004,1.276675e+002,-6.044744e-004,0.000000e+000,-1.184979e-001,0.000000e+000,3,9.558282e-001,1.825000e+000,,,,,,,,,,,,,,,,,,0,4.000000e+000,1.000000e+000,20,1,6.610031e-001,0,1,0,
1435374154.498,,7.000000e+004,1.209836e+002,-6.049784e-004,0.000000e+000,-1.190699e-001,0.000000e+000,3,9.573857e-001,1.825000e+000,,,,,,,,,,,,,,,,,,0,4.000000e+000,1.000000e+000,20,1,6.123047e-001,0,1,0,
1435374357.858,,7.000000e+004,1.156391e+002,-5.998813e-004,0.000000e+000,-1.262549e-001,0.000000e+000,3,9.541146e-001,1.825000e+000,,,,,,,,,,,,,,,,,,0,4.000000e+000,1.000000e+000,20,1,6.380997e-001,0,1,0,
1435374583.420,,7.000000e+004,1.095639e+002,-6.204322e-004,0.000000e+000,-1.117445e-001,0.000000e+000,3,9.596575e-001,1.825000e+000,,,,,,,,,,,,,,,,,,0,4.000000e+000,1.000000e+000,20,1,6.279984e-001,0,1,0,
1435374810.904,,7.000000e+004,1.035722e+002,-6.228641e-004,0.000000e+000,-1.153011e-001,0.000000e+000,3,9.591886e-001,1.825000e+000,,,,,,,,,,,,,,,,,,0,4.000000e+000,1.000000e+000,20,1,6.209946e-001,0,1,0,
1435375072.373,,7.000000e+004,9.650475e+001,-6.532624e-004,0.000000e+000,-1.170137e-001,0.000000e+000,3,9.598777e-001,1.825000e+000,,,,,,,,,,,,,,,,,,0,4.000000e+000,1.000000e+000,20,1,6.692505e-001,0,1,0,
1435375255.264,,7.000000e+004,9.157083e+001,-6.954760e-004,0.000000e+000,-1.025474e-001,0.000000e+000,3,9.555230e-001,1.825000e+000,,,,,,,,,,,,,,,,,,0,4.000000e+000,1.000000e+000,20,1,7.379074e-001,0,1,0,
1435375475.967,,7.000000e+004,8.552539e+001,-7.289412e-004,0.000000e+000,-1.170573e-001,0.000000e+000,3,9.578234e-001,1.825000e+000,,,,,,,,,,,,,,,,,,0,4.000000e+000,1.000000e+000,20,1,6.927795e-001,0,1,0,
1435375694.561,,7.000000e+004,7.960287e+001,-8.404966e-004,0.000000e+000,-1.222174e-001,0.000000e+000,3,9.540679e-001,1.825000e+000,,,,,,,,,,,,,,,,,,0,4.000000e+000,1.000000e+000,20,1,7.838974e-001,0,0,0,
1435375896.311,,7.000000e+004,7.355135e+001,-1.033543e-003,0.000000e+000,-1.203880e-001,0.000000e+000,3,9.696638e-001,1.825000e+000,,,,,,,,,,,,,,,,,,0,4.000000e+000,1.000000e+000,20,1,7.036667e-001,0,0,0,
1435376088.233,,7.000000e+004,6.755722e+001,-1.162413e-003,0.000000e+000,-1.203067e-001,0.000000e+000,3,9.694247e-001,1.825000e+000,,,,,,,,,,,,,,,,,,0,4.000000e+000,1.000000e+000,20,1,7.444153e-001,0,1,0,
1435376324.373,,7.000000e+004,6.066245e+001,-1.200304e-003,0.000000e+000,-1.158112e-001,0.000000e+000,3,9.648145e-001,1.825000e+000,,,,,,,,,,,,,,,,,,0,4.000000e+000,1.000000e+000,20,1,6.955299e-001,0,1,0,
1435376509.811,,7.000000e+004,5.542263e+001,-1.220540e-003,0.000000e+000,-1.243884e-001,0.000000e+000,3,9.607574e-001,1.825000e+000,,,,,,,,,,,,,,,,,,0,4.000000e+000,1.000000e+000,20,1,7.034912e-001,0,1,0,
1435376720.483,,7.000000e+004,4.958131e+001,-1.143685e-003,0.000000e+000,-1.161721e-001,0.000000e+000,3,9.677310e-001,1.825000e+000,,,,,,,,,,,,,,,,,,0,4.000000e+000,1.000000e+000,20,1,5.820618e-001,0,1,0,
1435376925.920,,7.000000e+004,4.356860e+001,-1.114353e-003,0.000000e+000,-1.007935e-001,0.000000e+000,3,9.456579e-001,1.825000e+000,,,,,,,,,,,,,,,,,,0,4.000000e+000,1.000000e+000,20,1,8.061600e-001,0,0,0,
1435377112.342,,7.000000e+004,3.755222e+001,-1.117574e-003,0.000000e+000,-1.175350e-001,0.000000e+000,3,9.729311e-001,1.825000e+000,,,,,,,,,,,,,,,,,,0,4.000000e+000,1.000000e+000,20,1,8.122292e-001,0,0,0,
1435377307.311,,7.000000e+004,3.153388e+001,-1.096222e-003,0.000000e+000,-1.241596e-001,0.000000e+000,3,9.603881e-001,1.825000e+000,,,,,,,,,,,,,,,,,,0,4.000000e+000,1.000000e+000,20,1,6.879387e-001,0,0,0,
1435377518.264,,7.000000e+004,2.566991e+001,-1.036103e-003,0.000000e+000,-1.204809e-001,0.000000e+000,3,9.736543e-001,1.825000e+000,,,,,,,,,,,,,,,,,,0,4.000000e+000,1.000000e+000,20,1,6.512203e-001,0,1,0,
1435377740.951,,7.000000e+004,1.960992e+001,-9.446937e-004,0.000000e+000,-1.188398e-001,0.000000e+000,3,9.702336e-001,1.825000e+000,,,,,,,,,,,,,,,,,,0,4.000000e+000,1.000000e+000,20,1,6.709805e-001,0,1,0,
1435377969.186,,7.000000e+004,1.356091e+001,-7.868980e-004,0.000000e+000,-1.218913e-001,0.000000e+000,3,9.760731e-001,1.825000e+000,,,,,,,,,,,,,,,,,,0,4.000000e+000,1.000000e+000,20,1,7.064495e-001,0,0,0,
1435378192.170,,7.000000e+004,7.615789e+000,-4.959737e-004,0.000000e+000,-1.280124e-001,0.000000e+000,3,9.856389e-001,1.825000e+000,,,,,,,,,,,,,,,,,,0,4.000000e+000,1.000000e+000,20,1,6.283417e-001,0,0,0,
1435378428.404,,7.000000e+004,3.995787e+000,-1.878644e-004,0.000000e+000,-1.553596e-001,0.000000e+000,3,9.278708e-001,1.825000e+000,,,,,,,,,,,,,,,,,,0,4.000000e+000,1.000000e+000,20,1,3.966093e-003,0,0,0,