File: !!!Рисунки/Магнитная восприимчивость/Cu3SbS3_206_4_m_61_21mg_H_1000_Oe_m_T_3_rso.dat
[Header]
TITLE,MPMS RSO Measurement
BYAPP,MPMS Measurement,1.1,Summary
FILEOPENTIME, 1438356864.000000 7/31/2015, 8:34:24 PM

INFO, APPNAME, MPMS MultiVu Application, Revision 1.58,  Build 076

INFO, NAME, Unnamed
INFO, WEIGHT, 1.000
INFO, AREA, 1.000
INFO, LENGTH, 1.000
INFO, SHAPE, 0
INFO, COMMENT,
INFO, SEQUENCE FILE: m(T).seq


INFO, BACKGROUND DATA FILE:, None


STARTUPAXIS,X,4,LINEAR,AUTO,0.000000,0.000000
STARTUPAXIS,Y1,5,LINEAR,AUTO,0.000000,0.000000


STARTUPGROUP,Longitudinal
FIELDGROUP,Longitudinal,1,2,3,4,5,6,7,8,9,10,11,19,20,21,22,23,35
FIELDGROUP,Transverse,1,2,3,4,12,13,14,15,16,17,18,24,25,26,27,28,35

PLOT_APPEARANCE,ALL,HORZ_GRID_ON,VERT_GRID_ON,MARKERS_AND_LINES

[Data]
Time,Comment,Field (Oe),Temperature (K),Long Moment (emu),Long Scan Std Dev,Long Offset (cm),Long Offset Std Dev,Long Algorithm,Long Reg Fit,Long Reg Factor,Trans Moment (emu),Trans Scan Std Dev,Trans Offset (cm),Trans Offset Std Dev,Trans Algorithm,Trans Reg Fit,Trans Reg Factor,Long Moment [w/o ABS] (emu),Long Scan Std Dev [w/o ABS],Long Offset [w/o ABS] (cm),Long Offset Std Dev [w/o ABS],Long Reg Fit [w/o ABS],Trans Moment [w/o ABS] (emu),Trans Scan Std Dev [w/o ABS],Trans Offset [w/o ABS] (cm),Trans Offset Std Dev [w/o ABS],Trans Reg Fit [w/o ABS],RSO Position (deg),Amplitude (cm),Frequency,Cycles to Average,Scans per Measurement,Delta Temp (K),Error,EC Comp. Running,Using ABS,
1438356864.000,,9.999999e+002,2.005244e+000,3.295314e-005,0.000000e+000,-2.873408e-003,0.000000e+000,3,9.739481e-001,1.825000e+000,,,,,,,,,,,,,,,,,,0,4.000000e+000,1.000000e+000,20,1,4.017830e-003,0,1,0,
1438357087.812,,9.999999e+002,5.443023e+000,1.033377e-005,0.000000e+000,-9.978554e-002,0.000000e+000,3,9.288746e-001,1.825000e+000,,,,,,,,,,,,,,,,,,0,4.000000e+000,1.000000e+000,20,1,8.204341e-001,0,0,0,
1438357251.718,,9.999999e+002,8.371258e+000,6.157166e-006,0.000000e+000,-2.072753e-001,0.000000e+000,3,8.918908e-001,1.825000e+000,,,,,,,,,,,,,,,,,,0,4.000000e+000,1.000000e+000,20,1,4.505014e-001,0,0,0,
1438357437.093,,9.999999e+002,1.133221e+001,4.018230e-006,0.000000e+000,-3.913564e-001,0.000000e+000,3,8.586573e-001,1.825000e+000,,,,,,,,,,,,,,,,,,0,4.000000e+000,1.000000e+000,20,1,4.087801e-001,0,1,0,
1438357614.312,,9.999999e+002,1.420266e+001,3.174635e-006,0.000000e+000,-6.092345e-001,0.000000e+000,3,8.703730e-001,1.825000e+000,,,,,,,,,,,,,,,,,,0,4.000000e+000,1.000000e+000,20,1,4.008207e-001,0,1,0,
1438357800.406,,9.999999e+002,1.728595e+001,5.368480e-007,0.000000e+000,0.000000e+000,0.000000e+000,3,0.000000e+000,1.825000e+000,,,,,,,,,,,,,,,,,,0,4.000000e+000,1.000000e+000,20,1,4.654293e-001,0,0,0,
1438357976.843,,9.999999e+002,2.025168e+001,-1.772429e-007,0.000000e+000,0.000000e+000,0.000000e+000,3,0.000000e+000,1.825000e+000,,,,,,,,,,,,,,,,,,0,4.000000e+000,1.000000e+000,20,1,4.558601e-001,0,0,0,
1438358159.797,,9.999999e+002,2.323072e+001,-2.709741e-006,0.000000e+000,8.542448e-001,0.000000e+000,3,5.946223e-001,1.825000e+000,,,,,,,,,,,,,,,,,,0,4.000000e+000,1.000000e+000,20,1,4.614296e-001,0,0,0,
1438358347.297,,9.999999e+002,2.625113e+001,-2.837457e-006,0.000000e+000,7.621385e-001,0.000000e+000,3,6.231006e-001,1.825000e+000,,,,,,,,,,,,,,,,,,0,4.000000e+000,1.000000e+000,20,1,4.370899e-001,0,1,0,
1438358533.078,,9.999999e+002,2.932823e+001,-2.944024e-006,0.000000e+000,6.858300e-001,0.000000e+000,3,6.394840e-001,1.825000e+000,,,,,,,,,,,,,,,,,,0,4.000000e+000,1.000000e+000,20,1,4.303398e-001,0,1,0,
1438358712.890,,9.999999e+002,3.224068e+001,-3.052674e-006,0.000000e+000,6.412672e-001,0.000000e+000,3,6.587480e-001,1.825000e+000,,,,,,,,,,,,,,,,,,0,4.000000e+000,1.000000e+000,20,1,4.116096e-001,0,0,0,
1438358902.000,,9.999999e+002,3.535209e+001,-3.148480e-006,0.000000e+000,6.039068e-001,0.000000e+000,3,6.727937e-001,1.825000e+000,,,,,,,,,,,,,,,,,,0,4.000000e+000,1.000000e+000,20,1,4.372330e-001,0,0,0,
1438359080.484,,9.999999e+002,3.828735e+001,-3.223606e-006,0.000000e+000,5.797979e-001,0.000000e+000,3,6.847072e-001,1.825000e+000,,,,,,,,,,,,,,,,,,0,4.000000e+000,1.000000e+000,20,1,4.037895e-001,0,0,0,
1438359259.937,,9.999999e+002,4.126695e+001,-3.296819e-006,0.000000e+000,5.640857e-001,0.000000e+000,3,6.893818e-001,1.825000e+000,,,,,,,,,,,,,,,,,,0,4.000000e+000,1.000000e+000,20,1,4.406700e-001,0,1,0,
1438359444.390,,9.999999e+002,4.425105e+001,-3.320865e-006,0.000000e+000,5.529747e-001,0.000000e+000,3,6.935782e-001,1.825000e+000,,,,,,,,,,,,,,,,,,0,4.000000e+000,1.000000e+000,20,1,4.603615e-001,0,1,0,
1438359632.140,,9.999999e+002,4.724219e+001,-3.366666e-006,0.000000e+000,5.447659e-001,0.000000e+000,3,6.995491e-001,1.825000e+000,,,,,,,,,,,,,,,,,,0,4.000000e+000,1.000000e+000,20,1,4.259377e-001,0,1,0,
1438359819.609,,9.999999e+002,5.033751e+001,-3.418445e-006,0.000000e+000,5.336514e-001,0.000000e+000,3,7.035196e-001,1.825000e+000,,,,,,,,,,,,,,,,,,0,4.000000e+000,1.000000e+000,20,1,4.275017e-001,0,0,0,
1438359993.609,,9.999999e+002,5.321619e+001,-3.464786e-006,0.000000e+000,5.215263e-001,0.000000e+000,3,7.079695e-001,1.825000e+000,,,,,,,,,,,,,,,,,,0,4.000000e+000,1.000000e+000,20,1,3.982201e-001,0,0,0,
1438360189.422,,9.999999e+002,5.637399e+001,-3.469207e-006,0.000000e+000,5.151973e-001,0.000000e+000,3,7.071108e-001,1.825000e+000,,,,,,,,,,,,,,,,,,0,4.000000e+000,1.000000e+000,20,1,4.020195e-001,0,1,0,
1438360367.578,,9.999999e+002,5.927597e+001,-3.449828e-006,0.000000e+000,5.215068e-001,0.000000e+000,3,7.032135e-001,1.825000e+000,,,,,,,,,,,,,,,,,,0,4.000000e+000,1.000000e+000,20,1,4.035606e-001,0,1,0,
1438360550.375,,9.999999e+002,6.229600e+001,-3.382715e-006,0.000000e+000,5.443563e-001,0.000000e+000,3,6.995717e-001,1.825000e+000,,,,,,,,,,,,,,,,,,0,4.000000e+000,1.000000e+000,20,1,3.911209e-001,0,1,0,
1438360735.890,,9.999999e+002,6.529077e+001,-3.273614e-006,0.000000e+000,5.788462e-001,0.000000e+000,3,6.835306e-001,1.825000e+000,,,,,,,,,,,,,,,,,,0,4.000000e+000,1.000000e+000,20,1,3.761368e-001,0,0,0,
1438360926.156,,9.999999e+002,6.831706e+001,-3.131118e-006,0.000000e+000,6.332122e-001,0.000000e+000,3,6.668449e-001,1.825000e+000,,,,,,,,,,,,,,,,,,0,4.000000e+000,1.000000e+000,20,1,3.604355e-001,0,0,0,
1438361103.640,,9.999999e+002,7.127931e+001,-2.967712e-006,0.000000e+000,7.188843e-001,0.000000e+000,3,6.367660e-001,1.825000e+000,,,,,,,,,,,,,,,,,,0,4.000000e+000,1.000000e+000,20,1,3.957291e-001,0,1,0,
1438361284.390,,9.999999e+002,7.424632e+001,-2.812302e-006,0.000000e+000,8.515292e-001,0.000000e+000,3,5.959059e-001,1.825000e+000,,,,,,,,,,,,,,,,,,0,4.000000e+000,1.000000e+000,20,1,4.574890e-001,0,1,0,
1438361469.297,,9.999999e+002,7.724927e+001,1.648344e-007,0.000000e+000,0.000000e+000,0.000000e+000,3,0.000000e+000,1.825000e+000,,,,,,,,,,,,,,,,,,0,4.000000e+000,1.000000e+000,20,1,3.978424e-001,0,1,0,
1438361657.281,,9.999999e+002,8.025302e+001,3.269517e-006,0.000000e+000,-6.392239e-001,0.000000e+000,3,8.790402e-001,1.825000e+000,,,,,,,,,,,,,,,,,,0,4.000000e+000,1.000000e+000,20,1,4.057693e-001,0,0,0,
1438361835.953,,9.999999e+002,8.323051e+001,3.637569e-006,0.000000e+000,-5.013436e-001,0.000000e+000,3,8.654690e-001,1.825000e+000,,,,,,,,,,,,,,,,,,0,4.000000e+000,1.000000e+000,20,1,4.286423e-001,0,0,0,
1438362029.218,,9.999999e+002,8.633751e+001,3.846787e-006,0.000000e+000,-4.515382e-001,0.000000e+000,3,8.620381e-001,1.825000e+000,,,,,,,,,,,,,,,,,,0,4.000000e+000,1.000000e+000,20,1,4.622116e-001,0,1,0,
1438362205.984,,9.999999e+002,8.925689e+001,4.015486e-006,0.000000e+000,-4.205977e-001,0.000000e+000,3,8.601664e-001,1.825000e+000,,,,,,,,,,,,,,,,,,0,4.000000e+000,1.000000e+000,20,1,4.032745e-001,0,1,0,
1438362387.484,,9.999999e+002,9.224831e+001,4.175935e-006,0.000000e+000,-3.942285e-001,0.000000e+000,3,8.528379e-001,1.825000e+000,,,,,,,,,,,,,,,,,,0,4.000000e+000,1.000000e+000,20,1,3.817673e-001,0,1,0,
1438362604.297,,9.999999e+002,9.581967e+001,4.331197e-006,0.000000e+000,-3.711449e-001,0.000000e+000,3,8.600698e-001,1.825000e+000,,,,,,,,,,,,,,,,,,0,4.000000e+000,1.000000e+000,20,1,4.450226e-001,0,0,0,
1438362758.187,,9.999999e+002,9.833726e+001,4.403315e-006,0.000000e+000,-3.613083e-001,0.000000e+000,3,8.588830e-001,1.825000e+000,,,,,,,,,,,,,,,,,,0,4.000000e+000,1.000000e+000,20,1,3.883820e-001,0,0,0,
1438362941.172,,9.999999e+002,1.012950e+002,4.490047e-006,0.000000e+000,-3.509988e-001,0.000000e+000,3,8.528517e-001,1.825000e+000,,,,,,,,,,,,,,,,,,0,4.000000e+000,1.000000e+000,20,1,3.425980e-001,0,0,0,
1438363125.640,,9.999999e+002,1.043255e+002,4.557621e-006,0.000000e+000,-3.398483e-001,0.000000e+000,3,8.492578e-001,1.825000e+000,,,,,,,,,,,,,,,,,,0,4.000000e+000,1.000000e+000,20,1,4.743958e-001,0,1,0,
1438363305.125,,9.999999e+002,1.073288e+002,4.606723e-006,0.000000e+000,-3.358932e-001,0.000000e+000,3,8.507196e-001,1.825000e+000,,,,,,,,,,,,,,,,,,0,4.000000e+000,1.000000e+000,20,1,3.499985e-001,0,1,0,
1438363488.656,,9.999999e+002,1.102506e+002,4.652457e-006,0.000000e+000,-3.385538e-001,0.000000e+000,3,8.412285e-001,1.825000e+000,,,,,,,,,,,,,,,,,,0,4.000000e+000,1.000000e+000,20,1,3.889999e-001,0,1,0,
1438363675.640,,9.999999e+002,1.132229e+002,4.647062e-006,0.000000e+000,-3.327917e-001,0.000000e+000,3,8.502191e-001,1.825000e+000,,,,,,,,,,,,,,,,,,0,4.000000e+000,1.000000e+000,20,1,4.195023e-001,0,0,0,
1438363859.047,,9.999999e+002,1.163066e+002,4.654536e-006,0.000000e+000,-3.327144e-001,0.000000e+000,3,8.485441e-001,1.825000e+000,,,,,,,,,,,,,,,,,,0,4.000000e+000,1.000000e+000,20,1,4.522018e-001,0,0,0,
1438364043.515,,9.999999e+002,1.192917e+002,4.652122e-006,0.000000e+000,-3.341538e-001,0.000000e+000,3,8.508676e-001,1.825000e+000,,,,,,,,,,,,,,,,,,0,4.000000e+000,1.000000e+000,20,1,3.992996e-001,0,0,0,
1438364225.734,,9.999999e+002,1.222852e+002,4.640121e-006,0.000000e+000,-3.376790e-001,0.000000e+000,3,8.419444e-001,1.825000e+000,,,,,,,,,,,,,,,,,,0,4.000000e+000,1.000000e+000,20,1,3.918991e-001,0,1,0,
1438364405.734,,9.999999e+002,1.252536e+002,4.642735e-006,0.000000e+000,-3.384393e-001,0.000000e+000,3,8.463607e-001,1.825000e+000,,,,,,,,,,,,,,,,,,0,4.000000e+000,1.000000e+000,20,1,3.957977e-001,0,1,0,
1438364590.547,,9.999999e+002,1.282650e+002,4.636671e-006,0.000000e+000,-3.430932e-001,0.000000e+000,3,8.436169e-001,1.825000e+000,,,,,,,,,,,,,,,,,,0,4.000000e+000,1.000000e+000,20,1,3.895874e-001,0,0,0,
1438364779.250,,9.999999e+002,1.313242e+002,4.613763e-006,0.000000e+000,-3.477580e-001,0.000000e+000,3,8.435593e-001,1.825000e+000,,,,,,,,,,,,,,,,,,0,4.000000e+000,1.000000e+000,20,1,4.653015e-001,0,0,0,
1438364961.812,,9.999999e+002,1.343584e+002,4.583243e-006,0.000000e+000,-3.516297e-001,0.000000e+000,3,8.439588e-001,1.825000e+000,,,,,,,,,,,,,,,,,,0,4.000000e+000,1.000000e+000,20,1,4.029999e-001,0,0,0,
1438365135.734,,9.999999e+002,1.372740e+002,4.571155e-006,0.000000e+000,-3.556965e-001,0.000000e+000,3,8.405325e-001,1.825000e+000,,,,,,,,,,,,,,,,,,0,4.000000e+000,1.000000e+000,20,1,3.923950e-001,0,1,0,
1438365315.203,,9.999999e+002,1.402314e+002,4.537872e-006,0.000000e+000,-3.592182e-001,0.000000e+000,3,8.386737e-001,1.825000e+000,,,,,,,,,,,,,,,,,,0,4.000000e+000,1.000000e+000,20,1,4.519043e-001,0,1,0,
1438365494.922,,9.999999e+002,1.432404e+002,4.511077e-006,0.000000e+000,-3.657573e-001,0.000000e+000,3,8.374623e-001,1.825000e+000,,,,,,,,,,,,,,,,,,0,4.000000e+000,1.000000e+000,20,1,4.539032e-001,0,0,0,
1438365679.843,,9.999999e+002,1.462480e+002,4.474723e-006,0.000000e+000,-3.718030e-001,0.000000e+000,3,8.342401e-001,1.825000e+000,,,,,,,,,,,,,,,,,,0,4.000000e+000,1.000000e+000,20,1,4.821014e-001,0,0,0,
1438365859.609,,9.999999e+002,1.493145e+002,4.442877e-006,0.000000e+000,-3.778945e-001,0.000000e+000,3,8.359091e-001,1.825000e+000,,,,,,,,,,,,,,,,,,0,4.000000e+000,1.000000e+000,20,1,3.711090e-001,0,0,0,
1438366043.047,,9.999999e+002,1.522202e+002,4.421806e-006,0.000000e+000,-3.843655e-001,0.000000e+000,3,8.336702e-001,1.825000e+000,,,,,,,,,,,,,,,,,,0,4.000000e+000,1.000000e+000,20,1,4.167023e-001,0,1,0,
1438366231.078,,9.999999e+002,1.552489e+002,4.396171e-006,0.000000e+000,-3.907790e-001,0.000000e+000,3,8.345820e-001,1.825000e+000,,,,,,,,,,,,,,,,,,0,4.000000e+000,1.000000e+000,20,1,4.454041e-001,0,1,0,
1438366407.078,,9.999999e+002,1.582224e+002,4.356929e-006,0.000000e+000,-3.933145e-001,0.000000e+000,3,8.338244e-001,1.825000e+000,,,,,,,,,,,,,,,,,,0,4.000000e+000,1.000000e+000,20,1,3.993988e-001,0,1,0,
1438366595.312,,9.999999e+002,1.612679e+002,4.309491e-006,0.000000e+000,-4.004489e-001,0.000000e+000,3,8.402059e-001,1.825000e+000,,,,,,,,,,,,,,,,,,0,4.000000e+000,1.000000e+000,20,1,4.066925e-001,0,0,0,
1438366780.859,,9.999999e+002,1.642881e+002,4.284439e-006,0.000000e+000,-4.087495e-001,0.000000e+000,3,8.349346e-001,1.825000e+000,,,,,,,,,,,,,,,,,,0,4.000000e+000,1.000000e+000,20,1,4.064026e-001,0,0,0,
1438366969.031,,9.999999e+002,1.673901e+002,4.228801e-006,0.000000e+000,-4.144103e-001,0.000000e+000,3,8.323069e-001,1.825000e+000,,,,,,,,,,,,,,,,,,0,4.000000e+000,1.000000e+000,20,1,3.979950e-001,0,0,0,
1438367139.484,,9.999999e+002,1.702245e+002,4.205292e-006,0.000000e+000,-4.223420e-001,0.000000e+000,3,8.345192e-001,1.825000e+000,,,,,,,,,,,,,,,,,,0,4.000000e+000,1.000000e+000,20,1,3.713989e-001,0,1,0,
1438367320.593,,9.999999e+002,1.732408e+002,4.175402e-006,0.000000e+000,-4.278228e-001,0.000000e+000,3,8.329554e-001,1.825000e+000,,,,,,,,,,,,,,,,,,0,4.000000e+000,1.000000e+000,20,1,4.082947e-001,0,1,0,
1438367509.453,,9.999999e+002,1.763047e+002,4.127318e-006,0.000000e+000,-4.358418e-001,0.000000e+000,3,8.326936e-001,1.825000e+000,,,,,,,,,,,,,,,,,,0,4.000000e+000,1.000000e+000,20,1,4.051971e-001,0,0,0,
1438367691.968,,9.999999e+002,1.792329e+002,4.130373e-006,0.000000e+000,-4.436639e-001,0.000000e+000,3,8.351313e-001,1.825000e+000,,,,,,,,,,,,,,,,,,0,4.000000e+000,1.000000e+000,20,1,4.441071e-001,0,0,0,
1438367870.859,,9.999999e+002,1.822545e+002,4.056779e-006,0.000000e+000,-4.526807e-001,0.000000e+000,3,8.284546e-001,1.825000e+000,,,,,,,,,,,,,,,,,,0,4.000000e+000,1.000000e+000,20,1,4.315033e-001,0,0,0,
1438368055.828,,9.999999e+002,1.852080e+002,4.025618e-006,0.000000e+000,-4.604494e-001,0.000000e+000,3,8.294253e-001,1.825000e+000,,,,,,,,,,,,,,,,,,0,4.000000e+000,1.000000e+000,20,1,4.077911e-001,0,1,0,
1438368253.562,,9.999999e+002,1.883300e+002,3.990580e-006,0.000000e+000,-4.659955e-001,0.000000e+000,3,8.312636e-001,1.825000e+000,,,,,,,,,,,,,,,,,,0,4.000000e+000,1.000000e+000,20,1,4.306030e-001,0,1,0,
1438368425.000,,9.999999e+002,1.912183e+002,3.957634e-006,0.000000e+000,-4.760422e-001,0.000000e+000,3,8.309235e-001,1.825000e+000,,,,,,,,,,,,,,,,,,0,4.000000e+000,1.000000e+000,20,1,4.138031e-001,0,1,0,
1438368615.750,,9.999999e+002,1.942634e+002,3.931959e-006,0.000000e+000,-4.852960e-001,0.000000e+000,3,8.282187e-001,1.825000e+000,,,,,,,,,,,,,,,,,,0,4.000000e+000,1.000000e+000,20,1,3.959961e-001,0,0,0,
1438368800.484,,9.999999e+002,1.971985e+002,3.893706e-006,0.000000e+000,-4.921806e-001,0.000000e+000,3,8.293461e-001,1.825000e+000,,,,,,,,,,,,,,,,,,0,4.000000e+000,1.000000e+000,20,1,3.864899e-001,0,0,0,
1438368990.422,,9.999999e+002,2.003268e+002,3.884432e-006,0.000000e+000,-5.006616e-001,0.000000e+000,3,8.301248e-001,1.825000e+000,,,,,,,,,,,,,,,,,,0,4.000000e+000,1.000000e+000,20,1,4.199066e-001,0,0,0,
1438369166.172,,9.999999e+002,2.032466e+002,3.850062e-006,0.000000e+000,-5.074192e-001,0.000000e+000,3,8.323439e-001,1.825000e+000,,,,,,,,,,,,,,,,,,0,4.000000e+000,1.000000e+000,20,1,4.427032e-001,0,1,0,
1438369348.859,,9.999999e+002,2.062229e+002,3.808822e-006,0.000000e+000,-5.174351e-001,0.000000e+000,3,8.309622e-001,1.825000e+000,,,,,,,,,,,,,,,,,,0,4.000000e+000,1.000000e+000,20,1,4.147949e-001,0,1,0,
1438369529.047,,9.999999e+002,2.092235e+002,3.774962e-006,0.000000e+000,-5.263084e-001,0.000000e+000,3,8.320521e-001,1.825000e+000,,,,,,,,,,,,,,,,,,0,4.000000e+000,1.000000e+000,20,1,4.155121e-001,0,0,0,
1438369719.500,,9.999999e+002,2.123802e+002,3.755423e-006,0.000000e+000,-5.347382e-001,0.000000e+000,3,8.361180e-001,1.825000e+000,,,,,,,,,,,,,,,,,,0,4.000000e+000,1.000000e+000,20,1,3.977051e-001,0,0,0,
1438369894.984,,9.999999e+002,2.152534e+002,3.714860e-006,0.000000e+000,-5.433658e-001,0.000000e+000,3,8.315606e-001,1.825000e+000,,,,,,,,,,,,,,,,,,0,4.000000e+000,1.000000e+000,20,1,4.021912e-001,0,0,0,
1438370081.687,,9.999999e+002,2.182733e+002,3.707953e-006,0.000000e+000,-5.538160e-001,0.000000e+000,3,8.342221e-001,1.825000e+000,,,,,,,,,,,,,,,,,,0,4.000000e+000,1.000000e+000,20,1,4.322968e-001,0,1,0,
1438370266.484,,9.999999e+002,2.212955e+002,3.662251e-006,0.000000e+000,-5.614034e-001,0.000000e+000,3,8.379108e-001,1.825000e+000,,,,,,,,,,,,,,,,,,0,4.000000e+000,1.000000e+000,20,1,4.440918e-001,0,1,0,
1438370442.015,,9.999999e+002,2.242328e+002,3.600039e-006,0.000000e+000,-5.773920e-001,0.000000e+000,3,8.223172e-001,1.825000e+000,,,,,,,,,,,,,,,,,,0,4.000000e+000,1.000000e+000,20,1,3.753052e-001,0,1,0,
1438370632.265,,9.999999e+002,2.272920e+002,3.597652e-006,0.000000e+000,-5.786819e-001,0.000000e+000,3,8.352357e-001,1.825000e+000,,,,,,,,,,,,,,,,,,0,4.000000e+000,1.000000e+000,20,1,3.646088e-001,0,0,0,
1438370814.437,,9.999999e+002,2.302289e+002,3.593599e-006,0.000000e+000,-5.845768e-001,0.000000e+000,3,8.367095e-001,1.825000e+000,,,,,,,,,,,,,,,,,,0,4.000000e+000,1.000000e+000,20,1,3.950958e-001,0,0,0,
1438371004.390,,9.999999e+002,2.333456e+002,3.577096e-006,0.000000e+000,-5.982890e-001,0.000000e+000,3,8.375564e-001,1.825000e+000,,,,,,,,,,,,,,,,,,0,4.000000e+000,1.000000e+000,20,1,4.346008e-001,0,1,0,
1438371181.843,,9.999999e+002,2.362688e+002,3.549434e-006,0.000000e+000,-6.033809e-001,0.000000e+000,3,8.368845e-001,1.825000e+000,,,,,,,,,,,,,,,,,,0,4.000000e+000,1.000000e+000,20,1,3.787994e-001,0,1,0,
1438371366.468,,9.999999e+002,2.392777e+002,3.524899e-006,0.000000e+000,-6.185185e-001,0.000000e+000,3,8.259128e-001,1.825000e+000,,,,,,,,,,,,,,,,,,0,4.000000e+000,1.000000e+000,20,1,4.342041e-001,0,1,0,
1438371552.500,,9.999999e+002,2.423093e+002,3.511668e-006,0.000000e+000,-6.215230e-001,0.000000e+000,3,8.416905e-001,1.825000e+000,,,,,,,,,,,,,,,,,,0,4.000000e+000,1.000000e+000,20,1,4.295959e-001,0,0,0,
1438371728.968,,9.999999e+002,2.452944e+002,3.485110e-006,0.000000e+000,-6.329088e-001,0.000000e+000,3,8.418340e-001,1.825000e+000,,,,,,,,,,,,,,,,,,0,4.000000e+000,1.000000e+000,20,1,4.002075e-001,0,0,0,
1438371913.968,,9.999999e+002,2.482185e+002,3.488962e-006,0.000000e+000,-6.380253e-001,0.000000e+000,3,8.455023e-001,1.825000e+000,,,,,,,,,,,,,,,,,,0,4.000000e+000,1.000000e+000,20,1,4.098053e-001,0,1,0,
1438372100.453,,9.999999e+002,2.512464e+002,3.469974e-006,0.000000e+000,-6.522387e-001,0.000000e+000,3,8.445742e-001,1.825000e+000,,,,,,,,,,,,,,,,,,0,4.000000e+000,1.000000e+000,20,1,4.365997e-001,0,1,0,
1438372281.859,,9.999999e+002,2.542800e+002,3.481547e-006,0.000000e+000,-6.463551e-001,0.000000e+000,3,8.530477e-001,1.825000e+000,,,,,,,,,,,,,,,,,,0,4.000000e+000,1.000000e+000,20,1,4.472046e-001,0,1,0,
1438372458.812,,9.999999e+002,2.572507e+002,3.450559e-006,0.000000e+000,-6.628290e-001,0.000000e+000,3,8.435670e-001,1.825000e+000,,,,,,,,,,,,,,,,,,0,4.000000e+000,1.000000e+000,20,1,3.784180e-001,0,0,0,
1438372649.812,,9.999999e+002,2.603048e+002,3.403915e-006,0.000000e+000,-6.702125e-001,0.000000e+000,3,8.435274e-001,1.825000e+000,,,,,,,,,,,,,,,,,,0,4.000000e+000,1.000000e+000,20,1,4.053955e-001,0,0,0,
1438372833.906,,9.999999e+002,2.632667e+002,3.414350e-006,0.000000e+000,-6.787424e-001,0.000000e+000,3,8.464967e-001,1.825000e+000,,,,,,,,,,,,,,,,,,0,4.000000e+000,1.000000e+000,20,1,3.609924e-001,0,0,0,
1438373020.750,,9.999999e+002,2.664460e+002,3.422035e-006,0.000000e+000,-6.742021e-001,0.000000e+000,3,8.483145e-001,1.825000e+000,,,,,,,,,,,,,,,,,,0,4.000000e+000,1.000000e+000,20,1,3.781128e-001,0,1,0,
1438373196.703,,9.999999e+002,2.693427e+002,3.435885e-006,0.000000e+000,-6.704935e-001,0.000000e+000,3,8.557709e-001,1.825000e+000,,,,,,,,,,,,,,,,,,0,4.000000e+000,1.000000e+000,20,1,4.060974e-001,0,1,0,
1438373376.734,,9.999999e+002,2.722416e+002,3.366747e-006,0.000000e+000,-6.960765e-001,0.000000e+000,3,8.447077e-001,1.825000e+000,,,,,,,,,,,,,,,,,,0,4.000000e+000,1.000000e+000,20,1,4.053040e-001,0,0,0,
1438373566.390,,9.999999e+002,2.753377e+002,3.374778e-006,0.000000e+000,-6.889865e-001,0.000000e+000,3,8.478449e-001,1.825000e+000,,,,,,,,,,,,,,,,,,0,4.000000e+000,1.000000e+000,20,1,4.454041e-001,0,0,0,
1438373742.578,,9.999999e+002,2.782595e+002,3.382684e-006,0.000000e+000,-6.957814e-001,0.000000e+000,3,8.560632e-001,1.825000e+000,,,,,,,,,,,,,,,,,,0,4.000000e+000,1.000000e+000,20,1,4.862976e-001,0,0,0,
1438373923.515,,9.999999e+002,2.812250e+002,3.365546e-006,0.000000e+000,-7.037815e-001,0.000000e+000,3,8.541484e-001,1.825000e+000,,,,,,,,,,,,,,,,,,0,4.000000e+000,1.000000e+000,20,1,4.230042e-001,0,1,0,
1438374115.406,,9.999999e+002,2.843162e+002,3.359301e-006,0.000000e+000,-7.089305e-001,0.000000e+000,3,8.585209e-001,1.825000e+000,,,,,,,,,,,,,,,,,,0,4.000000e+000,1.000000e+000,20,1,3.677979e-001,0,1,0,
1438374291.672,,9.999999e+002,2.872519e+002,3.356261e-006,0.000000e+000,-7.191296e-001,0.000000e+000,3,8.668799e-001,1.825000e+000,,,,,,,,,,,,,,,,,,0,4.000000e+000,1.000000e+000,20,1,4.309998e-001,0,1,0,
1438374470.328,,9.999999e+002,2.902338e+002,3.329574e-006,0.000000e+000,-7.177426e-001,0.000000e+000,3,8.581799e-001,1.825000e+000,,,,,,,,,,,,,,,,,,0,4.000000e+000,1.000000e+000,20,1,3.951111e-001,0,1,0,
1438374661.328,,9.999999e+002,2.932687e+002,3.337143e-006,0.000000e+000,-7.286847e-001,0.000000e+000,3,8.535736e-001,1.825000e+000,,,,,,,,,,,,,,,,,,0,4.000000e+000,1.000000e+000,20,1,4.266968e-001,0,0,0,
1438374849.562,,9.999999e+002,2.962930e+002,3.286194e-006,0.000000e+000,-7.309930e-001,0.000000e+000,3,8.546095e-001,1.825000e+000,,,,,,,,,,,,,,,,,,0,4.000000e+000,1.000000e+000,20,1,3.533020e-001,0,0,0,
1438375031.453,,9.999999e+002,2.993727e+002,3.268852e-006,0.000000e+000,-7.360649e-001,0.000000e+000,3,8.563743e-001,1.825000e+000,,,,,,,,,,,,,,,,,,0,4.000000e+000,1.000000e+000,20,1,4.338074e-001,0,1,0,
1438375214.453,,9.999999e+002,3.023137e+002,3.271339e-006,0.000000e+000,-7.390200e-001,0.000000e+000,3,8.633245e-001,1.825000e+000,,,,,,,,,,,,,,,,,,0,4.000000e+000,1.000000e+000,20,1,3.323975e-001,0,1,0,
1438375395.453,,9.999999e+002,3.052808e+002,3.240869e-006,0.000000e+000,-7.378367e-001,0.000000e+000,3,8.565245e-001,1.825000e+000,,,,,,,,,,,,,,,,,,0,4.000000e+000,1.000000e+000,20,1,4.275208e-001,0,1,0,
1438375582.640,,9.999999e+002,3.083310e+002,3.258020e-006,0.000000e+000,-7.505910e-001,0.000000e+000,3,8.603917e-001,1.825000e+000,,,,,,,,,,,,,,,,,,0,4.000000e+000,1.000000e+000,20,1,4.110107e-001,0,0,0,
1438375768.703,,9.999999e+002,3.112971e+002,3.228519e-006,0.000000e+000,-7.544931e-001,0.000000e+000,3,8.571916e-001,1.825000e+000,,,,,,,,,,,,,,,,,,0,4.000000e+000,1.000000e+000,20,1,3.803101e-001,0,0,0,
1438375946.359,,9.999999e+002,3.141916e+002,3.222827e-006,0.000000e+000,-7.533297e-001,0.000000e+000,3,8.661787e-001,1.825000e+000,,,,,,,,,,,,,,,,,,0,4.000000e+000,1.000000e+000,20,1,3.746033e-001,0,1,0,
1438376133.609,,9.999999e+002,3.172608e+002,3.254515e-006,0.000000e+000,-7.601262e-001,0.000000e+000,3,8.579671e-001,1.825000e+000,,,,,,,,,,,,,,,,,,0,4.000000e+000,1.000000e+000,20,1,4.371948e-001,0,1,0,
1438376313.093,,9.999999e+002,3.203183e+002,3.209689e-006,0.000000e+000,-7.693088e-001,0.000000e+000,3,8.439457e-001,1.825000e+000,,,,,,,,,,,,,,,,,,0,4.000000e+000,1.000000e+000,20,1,3.765869e-001,0,1,0,
1438376497.984,,9.999999e+002,3.232120e+002,-2.854590e-006,0.000000e+000,1.147251e+000,0.000000e+000,3,5.160715e-001,1.825000e+000,,,,,,,,,,,,,,,,,,0,4.000000e+000,1.000000e+000,20,1,3.981018e-001,0,1,0,
1438376685.218,,9.999999e+002,3.262562e+002,-3.318357e-007,0.000000e+000,-1.579882e+000,0.000000e+000,3,0.000000e+000,1.825000e+000,,,,,,,,,,,,,,,,,,0,4.000000e+000,1.000000e+000,20,1,4.350891e-001,0,0,0,
1438376866.812,,9.999999e+002,3.292957e+002,3.233395e-006,0.000000e+000,-7.749328e-001,0.000000e+000,3,8.642033e-001,1.825000e+000,,,,,,,,,,,,,,,,,,0,4.000000e+000,1.000000e+000,20,1,4.289856e-001,0,0,0,
1438377050.734,,9.999999e+002,3.323657e+002,8.931682e-007,0.000000e+000,0.000000e+000,0.000000e+000,3,0.000000e+000,1.825000e+000,,,,,,,,,,,,,,,,,,0,4.000000e+000,1.000000e+000,20,1,4.225159e-001,0,1,0,
1438377229.937,,9.999999e+002,3.352969e+002,-2.837560e-006,0.000000e+000,1.145378e+000,0.000000e+000,3,5.025247e-001,1.825000e+000,,,,,,,,,,,,,,,,,,0,4.000000e+000,1.000000e+000,20,1,3.842163e-001,0,1,0,
1438377410.390,,9.999999e+002,3.382831e+002,3.236889e-006,0.000000e+000,-7.830970e-001,0.000000e+000,3,8.588461e-001,1.825000e+000,,,,,,,,,,,,,,,,,,0,4.000000e+000,1.000000e+000,20,1,3.918152e-001,0,1,0,
1438377592.062,,9.999999e+002,3.412894e+002,8.313133e-007,0.000000e+000,0.000000e+000,0.000000e+000,3,0.000000e+000,1.825000e+000,,,,,,,,,,,,,,,,,,0,4.000000e+000,1.000000e+000,20,1,4.313049e-001,0,1,0,
1438377774.515,,9.999999e+002,3.442484e+002,8.110225e-007,0.000000e+000,0.000000e+000,0.000000e+000,3,0.000000e+000,1.825000e+000,,,,,,,,,,,,,,,,,,0,4.000000e+000,1.000000e+000,20,1,4.230957e-001,0,0,0,
1438377958.078,,9.999999e+002,3.472301e+002,7.732505e-007,0.000000e+000,0.000000e+000,0.000000e+000,3,0.000000e+000,1.825000e+000,,,,,,,,,,,,,,,,,,0,4.000000e+000,1.000000e+000,20,1,4.146118e-001,0,0,0,
1438378451.453,,9.999999e+002,3.500062e+002,7.624720e-007,0.000000e+000,0.000000e+000,0.000000e+000,3,0.000000e+000,1.825000e+000,,,,,,,,,,,,,,,,,,0,4.000000e+000,1.000000e+000,20,1,1.687622e-002,0,1,0,
1438378918.328,,9.999999e+002,3.475540e+002,7.752150e-007,0.000000e+000,0.000000e+000,0.000000e+000,3,0.000000e+000,1.825000e+000,,,,,,,,,,,,,,,,,,0,4.000000e+000,1.000000e+000,20,1,7.310791e-001,0,0,0,
1438379014.093,,9.999999e+002,3.433407e+002,8.211086e-007,0.000000e+000,0.000000e+000,0.000000e+000,3,0.000000e+000,1.825000e+000,,,,,,,,,,,,,,,,,,0,4.000000e+000,1.000000e+000,20,1,1.294617e+000,0,1,0,
1438379100.797,,9.999999e+002,3.392980e+002,9.308581e-007,0.000000e+000,0.000000e+000,0.000000e+000,3,0.000000e+000,1.825000e+000,,,,,,,,,,,,,,,,,,0,4.000000e+000,1.000000e+000,20,1,1.041107e+000,0,1,0,
1438379185.422,,9.999999e+002,3.367393e+002,9.574537e-007,0.000000e+000,0.000000e+000,0.000000e+000,3,0.000000e+000,1.825000e+000,,,,,,,,,,,,,,,,,,0,4.000000e+000,1.000000e+000,20,1,4.809875e-001,0,1,0,
1438379280.578,,9.999999e+002,3.360501e+002,9.713951e-007,0.000000e+000,0.000000e+000,0.000000e+000,3,0.000000e+000,1.825000e+000,,,,,,,,,,,,,,,,,,0,4.000000e+000,1.000000e+000,20,1,1.235962e-001,0,1,0,
1438379765.703,,9.999999e+002,3.326149e+002,9.721605e-007,0.000000e+000,0.000000e+000,0.000000e+000,3,0.000000e+000,1.825000e+000,,,,,,,,,,,,,,,,,,0,4.000000e+000,1.000000e+000,20,1,5.891724e-001,0,1,0,
1438379938.500,,9.999999e+002,3.297253e+002,3.367153e-006,0.000000e+000,-7.528551e-001,0.000000e+000,3,8.552019e-001,1.825000e+000,,,,,,,,,,,,,,,,,,0,4.000000e+000,1.000000e+000,20,1,4.005127e-001,0,1,0,
1438380136.406,,9.999999e+002,3.267065e+002,3.402234e-006,0.000000e+000,-7.500428e-001,0.000000e+000,3,8.489808e-001,1.825000e+000,,,,,,,,,,,,,,,,,,0,4.000000e+000,1.000000e+000,20,1,4.072876e-001,0,1,0,
1438380309.609,,9.999999e+002,3.236891e+002,3.444687e-006,0.000000e+000,-7.453942e-001,0.000000e+000,3,8.531222e-001,1.825000e+000,,,,,,,,,,,,,,,,,,0,4.000000e+000,1.000000e+000,20,1,5.276184e-001,0,0,0,
1438380449.015,,9.999999e+002,3.206186e+002,3.444241e-006,0.000000e+000,-7.385700e-001,0.000000e+000,3,8.472545e-001,1.825000e+000,,,,,,,,,,,,,,,,,,0,4.000000e+000,1.000000e+000,20,1,5.589905e-001,0,1,0,
1438380594.250,,9.999999e+002,3.177055e+002,3.434984e-006,0.000000e+000,-7.354121e-001,0.000000e+000,3,8.426768e-001,1.825000e+000,,,,,,,,,,,,,,,,,,0,4.000000e+000,1.000000e+000,20,1,4.522095e-001,0,1,0,
1438380819.484,,9.999999e+002,3.148151e+002,3.451179e-006,0.000000e+000,-7.344656e-001,0.000000e+000,3,8.392817e-001,1.825000e+000,,,,,,,,,,,,,,,,,,0,4.000000e+000,1.000000e+000,20,1,3.359070e-001,0,1,0,
1438381028.140,,9.999999e+002,3.117371e+002,3.468802e-006,0.000000e+000,-7.249413e-001,0.000000e+000,3,8.464183e-001,1.825000e+000,,,,,,,,,,,,,,,,,,0,4.000000e+000,1.000000e+000,20,1,4.472961e-001,0,1,0,
1438381221.593,,9.999999e+002,3.087427e+002,3.463570e-006,0.000000e+000,-7.264110e-001,0.000000e+000,3,8.358884e-001,1.825000e+000,,,,,,,,,,,,,,,,,,0,4.000000e+000,1.000000e+000,20,1,3.865051e-001,0,1,0,
1438381413.562,,9.999999e+002,3.057593e+002,3.483945e-006,0.000000e+000,-7.260340e-001,0.000000e+000,3,8.328528e-001,1.825000e+000,,,,,,,,,,,,,,,,,,0,4.000000e+000,1.000000e+000,20,1,4.288940e-001,0,1,0,
1438381603.468,,9.999999e+002,3.027514e+002,3.526331e-006,0.000000e+000,-7.173376e-001,0.000000e+000,3,8.216693e-001,1.825000e+000,,,,,,,,,,,,,,,,,,0,4.000000e+000,1.000000e+000,20,1,4.691772e-001,0,1,0,
1438381787.265,,9.999999e+002,2.996924e+002,3.544225e-006,0.000000e+000,-7.082531e-001,0.000000e+000,3,8.423541e-001,1.825000e+000,,,,,,,,,,,,,,,,,,0,4.000000e+000,1.000000e+000,20,1,4.468994e-001,0,0,0,
1438381948.453,,9.999999e+002,2.965939e+002,3.550684e-006,0.000000e+000,-7.123232e-001,0.000000e+000,3,8.328239e-001,1.825000e+000,,,,,,,,,,,,,,,,,,0,4.000000e+000,1.000000e+000,20,1,6.490784e-001,0,1,0,
1438382078.140,,9.999999e+002,2.936846e+002,3.569676e-006,0.000000e+000,-7.076104e-001,0.000000e+000,3,8.495299e-001,1.825000e+000,,,,,,,,,,,,,,,,,,0,4.000000e+000,1.000000e+000,20,1,5.666809e-001,0,1,0,
1438382256.000,,9.999999e+002,2.908163e+002,3.585390e-006,0.000000e+000,-7.028590e-001,0.000000e+000,3,8.368123e-001,1.825000e+000,,,,,,,,,,,,,,,,,,0,4.000000e+000,1.000000e+000,20,1,3.400879e-001,0,1,0,
1438382481.765,,9.999999e+002,2.877833e+002,3.590170e-006,0.000000e+000,-7.037681e-001,0.000000e+000,3,8.351948e-001,1.825000e+000,,,,,,,,,,,,,,,,,,0,4.000000e+000,1.000000e+000,20,1,3.659973e-001,0,1,0,
1438382685.000,,9.999999e+002,2.847714e+002,3.646058e-006,0.000000e+000,-6.948727e-001,0.000000e+000,3,8.308173e-001,1.825000e+000,,,,,,,,,,,,,,,,,,0,4.000000e+000,1.000000e+000,20,1,4.124146e-001,0,1,0,
1438382878.843,,9.999999e+002,2.817814e+002,3.653501e-006,0.000000e+000,-6.825294e-001,0.000000e+000,3,8.388459e-001,1.825000e+000,,,,,,,,,,,,,,,,,,0,4.000000e+000,1.000000e+000,20,1,4.354248e-001,0,1,0,
1438383066.093,,9.999999e+002,2.787570e+002,3.683250e-006,0.000000e+000,-6.865357e-001,0.000000e+000,3,8.310922e-001,1.825000e+000,,,,,,,,,,,,,,,,,,0,4.000000e+000,1.000000e+000,20,1,4.256897e-001,0,0,0,
1438383242.297,,9.999999e+002,2.755657e+002,3.674196e-006,0.000000e+000,-6.805321e-001,0.000000e+000,3,8.297324e-001,1.825000e+000,,,,,,,,,,,,,,,,,,0,4.000000e+000,1.000000e+000,20,1,5.373230e-001,0,0,0,
1438383374.937,,9.999999e+002,2.726478e+002,3.729523e-006,0.000000e+000,-6.773602e-001,0.000000e+000,3,8.271957e-001,1.825000e+000,,,,,,,,,,,,,,,,,,0,4.000000e+000,1.000000e+000,20,1,5.652771e-001,0,1,0,
1438383531.656,,9.999999e+002,2.697396e+002,3.718593e-006,0.000000e+000,-6.680124e-001,0.000000e+000,3,8.300625e-001,1.825000e+000,,,,,,,,,,,,,,,,,,0,4.000000e+000,1.000000e+000,20,1,3.879089e-001,0,1,0,
1438383758.093,,9.999999e+002,2.667393e+002,3.720032e-006,0.000000e+000,-6.732579e-001,0.000000e+000,3,8.393263e-001,1.825000e+000,,,,,,,,,,,,,,,,,,0,4.000000e+000,1.000000e+000,20,1,3.978882e-001,0,1,0,
1438383964.843,,9.999999e+002,2.637617e+002,3.771284e-006,0.000000e+000,-6.694243e-001,0.000000e+000,3,8.105066e-001,1.825000e+000,,,,,,,,,,,,,,,,,,0,4.000000e+000,1.000000e+000,20,1,4.441833e-001,0,1,0,
1438384166.765,,9.999999e+002,2.607109e+002,3.764466e-006,0.000000e+000,-6.572842e-001,0.000000e+000,3,8.282932e-001,1.825000e+000,,,,,,,,,,,,,,,,,,0,4.000000e+000,1.000000e+000,20,1,4.248047e-001,0,1,0,
1438384344.906,,9.999999e+002,2.576519e+002,3.782538e-006,0.000000e+000,-6.506483e-001,0.000000e+000,3,8.271140e-001,1.825000e+000,,,,,,,,,,,,,,,,,,0,4.000000e+000,1.000000e+000,20,1,4.942932e-001,0,0,0,
1438384488.922,,9.999999e+002,2.545470e+002,3.790056e-006,0.000000e+000,-6.471416e-001,0.000000e+000,3,8.267341e-001,1.825000e+000,,,,,,,,,,,,,,,,,,0,4.000000e+000,1.000000e+000,20,1,6.031952e-001,0,1,0,
1438384634.109,,9.999999e+002,2.516628e+002,3.837365e-006,0.000000e+000,-6.464546e-001,0.000000e+000,3,8.320801e-001,1.825000e+000,,,,,,,,,,,,,,,,,,0,4.000000e+000,1.000000e+000,20,1,4.801941e-001,0,1,0,
1438384845.609,,9.999999e+002,2.487646e+002,3.834794e-006,0.000000e+000,-6.325493e-001,0.000000e+000,3,8.232342e-001,1.825000e+000,,,,,,,,,,,,,,,,,,0,4.000000e+000,1.000000e+000,20,1,3.045044e-001,0,1,0,
1438385062.328,,9.999999e+002,2.457395e+002,3.838040e-006,0.000000e+000,-6.310472e-001,0.000000e+000,3,8.113080e-001,1.825000e+000,,,,,,,,,,,,,,,,,,0,4.000000e+000,1.000000e+000,20,1,3.453979e-001,0,1,0,
1438385263.922,,9.999999e+002,2.427162e+002,3.874361e-006,0.000000e+000,-6.223782e-001,0.000000e+000,3,8.255119e-001,1.825000e+000,,,,,,,,,,,,,,,,,,0,4.000000e+000,1.000000e+000,20,1,4.468079e-001,0,0,0,
1438385426.437,,9.999999e+002,2.396441e+002,3.907618e-006,0.000000e+000,-6.111374e-001,0.000000e+000,3,8.266086e-001,1.825000e+000,,,,,,,,,,,,,,,,,,0,4.000000e+000,1.000000e+000,20,1,6.190033e-001,0,0,0,
1438385563.640,,9.999999e+002,2.366521e+002,3.940378e-006,0.000000e+000,-6.058246e-001,0.000000e+000,3,8.286172e-001,1.825000e+000,,,,,,,,,,,,,,,,,,0,4.000000e+000,1.000000e+000,20,1,5.365906e-001,0,1,0,
1438385733.906,,9.999999e+002,2.338102e+002,3.943209e-006,0.000000e+000,-5.969583e-001,0.000000e+000,3,8.271264e-001,1.825000e+000,,,,,,,,,,,,,,,,,,0,4.000000e+000,1.000000e+000,20,1,3.637085e-001,0,1,0,
1438385973.687,,9.999999e+002,2.306530e+002,3.973743e-006,0.000000e+000,-5.862188e-001,0.000000e+000,3,8.349324e-001,1.825000e+000,,,,,,,,,,,,,,,,,,0,4.000000e+000,1.000000e+000,20,1,3.823853e-001,0,1,0,
1438386178.359,,9.999999e+002,2.276193e+002,3.957530e-006,0.000000e+000,-5.848852e-001,0.000000e+000,3,8.183238e-001,1.825000e+000,,,,,,,,,,,,,,,,,,0,4.000000e+000,1.000000e+000,20,1,3.726044e-001,0,1,0,
1438386353.297,,9.999999e+002,2.246829e+002,4.014071e-006,0.000000e+000,-5.718651e-001,0.000000e+000,3,8.228272e-001,1.825000e+000,,,,,,,,,,,,,,,,,,0,4.000000e+000,1.000000e+000,20,1,4.709015e-001,0,0,0,
1438386504.234,,9.999999e+002,2.216783e+002,4.068605e-006,0.000000e+000,-5.710628e-001,0.000000e+000,3,8.263012e-001,1.825000e+000,,,,,,,,,,,,,,,,,,0,4.000000e+000,1.000000e+000,20,1,5.177002e-001,0,1,0,
1438386656.156,,9.999999e+002,2.186652e+002,4.089688e-006,0.000000e+000,-5.596781e-001,0.000000e+000,3,8.259749e-001,1.825000e+000,,,,,,,,,,,,,,,,,,0,4.000000e+000,1.000000e+000,20,1,5.041046e-001,0,1,0,
1438386858.406,,9.999999e+002,2.157370e+002,4.149043e-006,0.000000e+000,-5.561618e-001,0.000000e+000,3,8.210621e-001,1.825000e+000,,,,,,,,,,,,,,,,,,0,4.000000e+000,1.000000e+000,20,1,4.039001e-001,0,1,0,
1438387073.156,,9.999999e+002,2.127122e+002,4.180109e-006,0.000000e+000,-5.443094e-001,0.000000e+000,3,8.153934e-001,1.825000e+000,,,,,,,,,,,,,,,,,,0,4.000000e+000,1.000000e+000,20,1,3.990021e-001,0,1,0,
1438387265.906,,9.999999e+002,2.096957e+002,4.181647e-006,0.000000e+000,-5.339078e-001,0.000000e+000,3,8.234529e-001,1.825000e+000,,,,,,,,,,,,,,,,,,0,4.000000e+000,1.000000e+000,20,1,4.702911e-001,0,0,0,
1438387415.640,,9.999999e+002,2.066077e+002,4.195616e-006,0.000000e+000,-5.314840e-001,0.000000e+000,3,8.237966e-001,1.825000e+000,,,,,,,,,,,,,,,,,,0,4.000000e+000,1.000000e+000,20,1,5.939026e-001,0,1,0,
1438387563.281,,9.999999e+002,2.037264e+002,4.225761e-006,0.000000e+000,-5.182051e-001,0.000000e+000,3,8.194530e-001,1.825000e+000,,,,,,,,,,,,,,,,,,0,4.000000e+000,1.000000e+000,20,1,4.502106e-001,0,1,0,
1438387774.062,,9.999999e+002,2.007232e+002,4.267765e-006,0.000000e+000,-5.139678e-001,0.000000e+000,3,8.212453e-001,1.825000e+000,,,,,,,,,,,,,,,,,,0,4.000000e+000,1.000000e+000,20,1,3.296051e-001,0,1,0,
1438387989.734,,9.999999e+002,1.977352e+002,4.313045e-006,0.000000e+000,-5.144341e-001,0.000000e+000,3,8.182886e-001,1.825000e+000,,,,,,,,,,,,,,,,,,0,4.000000e+000,1.000000e+000,20,1,4.147949e-001,0,1,0,
1438388176.687,,9.999999e+002,1.947367e+002,4.332718e-006,0.000000e+000,-4.975165e-001,0.000000e+000,3,8.248325e-001,1.825000e+000,,,,,,,,,,,,,,,,,,0,4.000000e+000,1.000000e+000,20,1,4.691010e-001,0,0,0,
1438388330.000,,9.999999e+002,1.917097e+002,4.392614e-006,0.000000e+000,-4.889905e-001,0.000000e+000,3,8.227807e-001,1.825000e+000,,,,,,,,,,,,,,,,,,0,4.000000e+000,1.000000e+000,20,1,5.592957e-001,0,1,0,
1438388481.453,,9.999999e+002,1.886678e+002,4.411163e-006,0.000000e+000,-4.840777e-001,0.000000e+000,3,8.225559e-001,1.825000e+000,,,,,,,,,,,,,,,,,,0,4.000000e+000,1.000000e+000,20,1,4.561005e-001,0,1,0,
1438388681.453,,9.999999e+002,1.857633e+002,4.442242e-006,0.000000e+000,-4.749941e-001,0.000000e+000,3,8.243291e-001,1.825000e+000,,,,,,,,,,,,,,,,,,0,4.000000e+000,1.000000e+000,20,1,3.401947e-001,0,1,0,
1438388896.140,,9.999999e+002,1.827346e+002,4.486129e-006,0.000000e+000,-4.674807e-001,0.000000e+000,3,8.244229e-001,1.825000e+000,,,,,,,,,,,,,,,,,,0,4.000000e+000,1.000000e+000,20,1,3.302002e-001,0,1,0,
1438389092.531,,9.999999e+002,1.796913e+002,4.498968e-006,0.000000e+000,-4.617721e-001,0.000000e+000,3,8.243901e-001,1.825000e+000,,,,,,,,,,,,,,,,,,0,4.000000e+000,1.000000e+000,20,1,4.464111e-001,0,0,0,
1438389249.703,,9.999999e+002,1.765627e+002,4.547679e-006,0.000000e+000,-4.565481e-001,0.000000e+000,3,8.266378e-001,1.825000e+000,,,,,,,,,,,,,,,,,,0,4.000000e+000,1.000000e+000,20,1,5.502014e-001,0,1,0,
1438389400.047,,9.999999e+002,1.736890e+002,4.591551e-006,0.000000e+000,-4.481660e-001,0.000000e+000,3,8.269042e-001,1.825000e+000,,,,,,,,,,,,,,,,,,0,4.000000e+000,1.000000e+000,20,1,4.062042e-001,0,1,0,
1438389598.000,,9.999999e+002,1.707852e+002,4.629084e-006,0.000000e+000,-4.457114e-001,0.000000e+000,3,8.243982e-001,1.825000e+000,,,,,,,,,,,,,,,,,,0,4.000000e+000,1.000000e+000,20,1,3.379059e-001,0,1,0,
1438389822.062,,9.999999e+002,1.677101e+002,4.646455e-006,0.000000e+000,-4.342438e-001,0.000000e+000,3,8.220417e-001,1.825000e+000,,,,,,,,,,,,,,,,,,0,4.000000e+000,1.000000e+000,20,1,3.264923e-001,0,1,0,
1438390008.265,,9.999999e+002,1.646880e+002,4.701981e-006,0.000000e+000,-4.283616e-001,0.000000e+000,3,8.314649e-001,1.825000e+000,,,,,,,,,,,,,,,,,,0,4.000000e+000,1.000000e+000,20,1,4.305115e-001,0,0,0,
1438390155.218,,9.999999e+002,1.616633e+002,4.747807e-006,0.000000e+000,-4.203739e-001,0.000000e+000,3,8.280025e-001,1.825000e+000,,,,,,,,,,,,,,,,,,0,4.000000e+000,1.000000e+000,20,1,5.982971e-001,0,1,0,
1438390314.109,,9.999999e+002,1.587699e+002,4.765474e-006,0.000000e+000,-4.182109e-001,0.000000e+000,3,8.277496e-001,1.825000e+000,,,,,,,,,,,,,,,,,,0,4.000000e+000,1.000000e+000,20,1,4.123993e-001,0,1,0,
1438390531.156,,9.999999e+002,1.557757e+002,4.806454e-006,0.000000e+000,-4.113845e-001,0.000000e+000,3,8.298565e-001,1.825000e+000,,,,,,,,,,,,,,,,,,0,4.000000e+000,1.000000e+000,20,1,3.812866e-001,0,1,0,
1438390742.078,,9.999999e+002,1.527700e+002,4.841042e-006,0.000000e+000,-4.071516e-001,0.000000e+000,3,8.302308e-001,1.825000e+000,,,,,,,,,,,,,,,,,,0,4.000000e+000,1.000000e+000,20,1,4.515991e-001,0,0,0,
1438390916.547,,9.999999e+002,1.496806e+002,4.872305e-006,0.000000e+000,-4.006857e-001,0.000000e+000,3,8.320769e-001,1.825000e+000,,,,,,,,,,,,,,,,,,0,4.000000e+000,1.000000e+000,20,1,5.778046e-001,0,0,0,
1438391066.797,,9.999999e+002,1.466686e+002,4.918631e-006,0.000000e+000,-3.958676e-001,0.000000e+000,3,8.294191e-001,1.825000e+000,,,,,,,,,,,,,,,,,,0,4.000000e+000,1.000000e+000,20,1,4.666901e-001,0,1,0,
1438391246.015,,9.999999e+002,1.437352e+002,4.939056e-006,0.000000e+000,-3.914543e-001,0.000000e+000,3,8.317891e-001,1.825000e+000,,,,,,,,,,,,,,,,,,0,4.000000e+000,1.000000e+000,20,1,3.919983e-001,0,1,0,
1438391450.515,,9.999999e+002,1.408065e+002,4.964659e-006,0.000000e+000,-3.863018e-001,0.000000e+000,3,8.328406e-001,1.825000e+000,,,,,,,,,,,,,,,,,,0,4.000000e+000,1.000000e+000,20,1,3.274994e-001,0,1,0,
1438391660.797,,9.999999e+002,1.377315e+002,5.008331e-006,0.000000e+000,-3.834489e-001,0.000000e+000,3,8.329107e-001,1.825000e+000,,,,,,,,,,,,,,,,,,0,4.000000e+000,1.000000e+000,20,1,4.054108e-001,0,1,0,
1438391840.422,,9.999999e+002,1.347498e+002,5.020079e-006,0.000000e+000,-3.774225e-001,0.000000e+000,3,8.359579e-001,1.825000e+000,,,,,,,,,,,,,,,,,,0,4.000000e+000,1.000000e+000,20,1,4.821014e-001,0,0,0,
1438391999.703,,9.999999e+002,1.316385e+002,5.034442e-006,0.000000e+000,-3.724845e-001,0.000000e+000,3,8.349355e-001,1.825000e+000,,,,,,,,,,,,,,,,,,0,4.000000e+000,1.000000e+000,20,1,5.410004e-001,0,1,0,
1438392150.187,,9.999999e+002,1.287715e+002,5.059530e-006,0.000000e+000,-3.702264e-001,0.000000e+000,3,8.341972e-001,1.825000e+000,,,,,,,,,,,,,,,,,,0,4.000000e+000,1.000000e+000,20,1,4.443970e-001,0,1,0,
1438392360.406,,9.999999e+002,1.257116e+002,5.048400e-006,0.000000e+000,-3.674074e-001,0.000000e+000,3,8.315975e-001,1.825000e+000,,,,,,,,,,,,,,,,,,0,4.000000e+000,1.000000e+000,20,1,3.667984e-001,0,1,0,
1438392569.437,,9.999999e+002,1.227345e+002,5.078594e-006,0.000000e+000,-3.606188e-001,0.000000e+000,3,8.410232e-001,1.825000e+000,,,,,,,,,,,,,,,,,,0,4.000000e+000,1.000000e+000,20,1,4.291000e-001,0,0,0,
1438392745.015,,9.999999e+002,1.195993e+002,5.100057e-006,0.000000e+000,-3.623926e-001,0.000000e+000,3,8.436875e-001,1.825000e+000,,,,,,,,,,,,,,,,,,0,4.000000e+000,1.000000e+000,20,1,4.880981e-001,0,0,0,
1438392891.031,,9.999999e+002,1.166655e+002,5.111608e-006,0.000000e+000,-3.592236e-001,0.000000e+000,3,8.418723e-001,1.825000e+000,,,,,,,,,,,,,,,,,,0,4.000000e+000,1.000000e+000,20,1,5.020981e-001,0,1,0,
1438393064.687,,9.999999e+002,1.137627e+002,5.091484e-006,0.000000e+000,-3.597727e-001,0.000000e+000,3,8.401906e-001,1.825000e+000,,,,,,,,,,,,,,,,,,0,4.000000e+000,1.000000e+000,20,1,3.815994e-001,0,1,0,
1438393274.140,,9.999999e+002,1.107757e+002,5.088858e-006,0.000000e+000,-3.581033e-001,0.000000e+000,3,8.437625e-001,1.825000e+000,,,,,,,,,,,,,,,,,,0,4.000000e+000,1.000000e+000,20,1,3.815994e-001,0,1,0,
1438393467.968,,9.999999e+002,1.077724e+002,5.076357e-006,0.000000e+000,-3.601480e-001,0.000000e+000,3,8.435678e-001,1.825000e+000,,,,,,,,,,,,,,,,,,0,4.000000e+000,1.000000e+000,20,1,4.484940e-001,0,0,0,
1438393630.875,,9.999999e+002,1.046543e+002,5.022927e-006,0.000000e+000,-3.653511e-001,0.000000e+000,3,8.422275e-001,1.825000e+000,,,,,,,,,,,,,,,,,,0,4.000000e+000,1.000000e+000,20,1,5.776978e-001,0,0,0,
1438393782.422,,9.999999e+002,1.017759e+002,4.966555e-006,0.000000e+000,-3.712262e-001,0.000000e+000,3,8.426837e-001,1.825000e+000,,,,,,,,,,,,,,,,,,0,4.000000e+000,1.000000e+000,20,1,4.412003e-001,0,1,0,
1438393981.406,,9.999999e+002,9.874310e+001,4.902308e-006,0.000000e+000,-3.792325e-001,0.000000e+000,3,8.422176e-001,1.825000e+000,,,,,,,,,,,,,,,,,,0,4.000000e+000,1.000000e+000,20,1,3.825607e-001,0,1,0,
1438394190.797,,9.999999e+002,9.568846e+001,4.804082e-006,0.000000e+000,-3.896459e-001,0.000000e+000,3,8.436336e-001,1.825000e+000,,,,,,,,,,,,,,,,,,0,4.000000e+000,1.000000e+000,20,1,4.135971e-001,0,0,0,
1438394361.047,,9.999999e+002,9.267204e+001,4.665493e-006,0.000000e+000,-4.047447e-001,0.000000e+000,3,8.398283e-001,1.825000e+000,,,,,,,,,,,,,,,,,,0,4.000000e+000,1.000000e+000,20,1,4.707031e-001,0,0,0,
1438394515.687,,9.999999e+002,8.965529e+001,4.506429e-006,0.000000e+000,-4.269574e-001,0.000000e+000,3,8.376877e-001,1.825000e+000,,,,,,,,,,,,,,,,,,0,4.000000e+000,1.000000e+000,20,1,5.289230e-001,0,1,0,
1438394686.390,,9.999999e+002,8.678194e+001,4.327449e-006,0.000000e+000,-4.538925e-001,0.000000e+000,3,8.367036e-001,1.825000e+000,,,,,,,,,,,,,,,,,,0,4.000000e+000,1.000000e+000,20,1,3.924866e-001,0,1,0,
1438394891.812,,9.999999e+002,8.370679e+001,4.081915e-006,0.000000e+000,-4.922720e-001,0.000000e+000,3,8.415292e-001,1.825000e+000,,,,,,,,,,,,,,,,,,0,4.000000e+000,1.000000e+000,20,1,3.788300e-001,0,1,0,
1438395078.562,,9.999999e+002,8.070729e+001,3.777448e-006,0.000000e+000,-5.696766e-001,0.000000e+000,3,8.380405e-001,1.825000e+000,,,,,,,,,,,,,,,,,,0,4.000000e+000,1.000000e+000,20,1,5.112076e-001,0,0,0,
1438395234.250,,9.999999e+002,7.770271e+001,7.552719e-007,0.000000e+000,0.000000e+000,0.000000e+000,3,0.000000e+000,1.825000e+000,,,,,,,,,,,,,,,,,,0,4.000000e+000,1.000000e+000,20,1,5.423584e-001,0,0,0,
1438395390.172,,9.999999e+002,7.466309e+001,-3.563104e-007,0.000000e+000,0.000000e+000,0.000000e+000,3,0.000000e+000,1.825000e+000,,,,,,,,,,,,,,,,,,0,4.000000e+000,1.000000e+000,20,1,4.938354e-001,0,1,0,
1438395574.484,,9.999999e+002,7.175360e+001,-2.871124e-006,0.000000e+000,8.211964e-001,0.000000e+000,3,5.486944e-001,1.825000e+000,,,,,,,,,,,,,,,,,,0,4.000000e+000,1.000000e+000,20,1,3.938675e-001,0,1,0,
1438395768.593,,9.999999e+002,6.873046e+001,-2.986057e-006,0.000000e+000,7.157800e-001,0.000000e+000,3,5.665292e-001,1.825000e+000,,,,,,,,,,,,,,,,,,0,4.000000e+000,1.000000e+000,20,1,4.842987e-001,0,0,0,
1438395929.859,,9.999999e+002,6.571106e+001,-3.109494e-006,0.000000e+000,6.406168e-001,0.000000e+000,3,5.919813e-001,1.825000e+000,,,,,,,,,,,,,,,,,,0,4.000000e+000,1.000000e+000,20,1,5.077744e-001,0,0,0,
1438396085.328,,9.999999e+002,6.259757e+001,-3.199596e-006,0.000000e+000,5.901570e-001,0.000000e+000,3,6.071623e-001,1.825000e+000,,,,,,,,,,,,,,,,,,0,4.000000e+000,1.000000e+000,20,1,4.700508e-001,0,0,0,
1438396238.578,,9.999999e+002,5.973923e+001,-3.260551e-006,0.000000e+000,5.625461e-001,0.000000e+000,3,6.173656e-001,1.825000e+000,,,,,,,,,,,,,,,,,,0,4.000000e+000,1.000000e+000,20,1,4.057693e-001,0,1,0,
1438396426.062,,9.999999e+002,5.677966e+001,-3.280840e-006,0.000000e+000,5.528952e-001,0.000000e+000,3,6.179138e-001,1.825000e+000,,,,,,,,,,,,,,,,,,0,4.000000e+000,1.000000e+000,20,1,3.880310e-001,0,1,0,
1438396638.484,,9.999999e+002,5.362791e+001,-3.264944e-006,0.000000e+000,5.565421e-001,0.000000e+000,3,6.181036e-001,1.825000e+000,,,,,,,,,,,,,,,,,,0,4.000000e+000,1.000000e+000,20,1,4.443703e-001,0,0,0,
1438396786.968,,9.999999e+002,5.063954e+001,-3.218614e-006,0.000000e+000,5.795925e-001,0.000000e+000,3,6.116995e-001,1.825000e+000,,,,,,,,,,,,,,,,,,0,4.000000e+000,1.000000e+000,20,1,5.401421e-001,0,0,0,
1438396925.609,,9.999999e+002,4.764565e+001,-3.136988e-006,0.000000e+000,6.196721e-001,0.000000e+000,3,5.980843e-001,1.825000e+000,,,,,,,,,,,,,,,,,,0,4.000000e+000,1.000000e+000,20,1,5.512314e-001,0,0,0,
1438397076.984,,9.999999e+002,4.465698e+001,-3.046181e-006,0.000000e+000,6.739174e-001,0.000000e+000,3,5.870821e-001,1.825000e+000,,,,,,,,,,,,,,,,,,0,4.000000e+000,1.000000e+000,20,1,5.249405e-001,0,1,0,
1438397259.156,,9.999999e+002,4.177490e+001,-2.959809e-006,0.000000e+000,7.394974e-001,0.000000e+000,3,5.630499e-001,1.825000e+000,,,,,,,,,,,,,,,,,,0,4.000000e+000,1.000000e+000,20,1,3.705406e-001,0,1,0,
1438397454.250,,9.999999e+002,3.877094e+001,-2.898368e-006,0.000000e+000,7.938414e-001,0.000000e+000,3,5.560404e-001,1.825000e+000,,,,,,,,,,,,,,,,,,0,4.000000e+000,1.000000e+000,20,1,4.549789e-001,0,0,0,
1438397623.484,,9.999999e+002,3.559621e+001,-2.856988e-006,0.000000e+000,8.290628e-001,0.000000e+000,3,5.437772e-001,1.825000e+000,,,,,,,,,,,,,,,,,,0,4.000000e+000,1.000000e+000,20,1,4.961510e-001,0,0,0,
1438397760.890,,9.999999e+002,3.261234e+001,-2.830958e-006,0.000000e+000,8.579778e-001,0.000000e+000,3,5.411349e-001,1.825000e+000,,,,,,,,,,,,,,,,,,0,4.000000e+000,1.000000e+000,20,1,5.730515e-001,0,0,0,
1438397904.093,,9.999999e+002,2.969516e+001,-2.799000e-006,0.000000e+000,9.040738e-001,0.000000e+000,3,5.327209e-001,1.825000e+000,,,,,,,,,,,,,,,,,,0,4.000000e+000,1.000000e+000,20,1,4.846992e-001,0,0,0,
1438398076.765,,9.999999e+002,2.675823e+001,-3.887880e-007,0.000000e+000,0.000000e+000,0.000000e+000,3,0.000000e+000,1.825000e+000,,,,,,,,,,,,,,,,,,0,4.000000e+000,1.000000e+000,20,1,4.269199e-001,0,1,0,
1438398228.968,,9.999999e+002,2.373162e+001,-2.782673e-006,0.000000e+000,1.011675e+000,0.000000e+000,3,5.312840e-001,1.825000e+000,,,,,,,,,,,,,,,,,,0,4.000000e+000,1.000000e+000,20,1,2.422714e-001,0,1,0,
1438398439.187,,9.999999e+002,2.064985e+001,5.023257e-007,0.000000e+000,0.000000e+000,0.000000e+000,3,0.000000e+000,1.825000e+000,,,,,,,,,,,,,,,,,,0,4.000000e+000,1.000000e+000,20,1,4.172192e-001,0,0,0,
1438398613.968,,9.999999e+002,1.773055e+001,3.377852e-006,0.000000e+000,-7.183574e-001,0.000000e+000,3,8.481772e-001,1.825000e+000,,,,,,,,,,,,,,,,,,0,4.000000e+000,1.000000e+000,20,1,4.186611e-001,0,0,0,
1438398799.172,,9.999999e+002,1.468622e+001,3.752816e-006,0.000000e+000,-5.540183e-001,0.000000e+000,3,8.321456e-001,1.825000e+000,,,,,,,,,,,,,,,,,,0,4.000000e+000,1.000000e+000,20,1,3.862095e-001,0,0,0,
1438398978.406,,9.999999e+002,1.173421e+001,4.705801e-006,0.000000e+000,-3.868934e-001,0.000000e+000,3,8.393510e-001,1.825000e+000,,,,,,,,,,,,,,,,,,0,4.000000e+000,1.000000e+000,20,1,4.178505e-001,0,1,0,
1438399158.875,,9.999999e+002,8.778115e+000,6.719527e-006,0.000000e+000,-2.413058e-001,0.000000e+000,3,8.725811e-001,1.825000e+000,,,,,,,,,,,,,,,,,,0,4.000000e+000,1.000000e+000,20,1,4.305973e-001,0,1,0,
1438399375.140,,9.999999e+002,5.737473e+000,1.135604e-005,0.000000e+000,-1.321615e-001,0.000000e+000,3,9.196885e-001,1.825000e+000,,,,,,,,,,,,,,,,,,0,4.000000e+000,1.000000e+000,20,1,4.463263e-001,0,0,0,
1438399562.359,,9.999999e+002,2.773856e+000,2.537581e-005,0.000000e+000,-5.559385e-002,0.000000e+000,3,9.620375e-001,1.825000e+000,,,,,,,,,,,,,,,,,,0,4.000000e+000,1.000000e+000,20,1,3.834231e-001,0,0,0,
1438399811.968,,9.999999e+002,1.997198e+000,3.411095e-005,0.000000e+000,-4.134097e-002,0.000000e+000,3,9.721941e-001,1.825000e+000,,,,,,,,,,,,,,,,,,0,4.000000e+000,1.000000e+000,20,1,6.340146e-003,0,1,0,