File: !!!Рисунки/Магнитная восприимчивость/Cu3SbS3_206_4_m_68_45mg_H_1000_Oe_m_T_rso.dat
[Header]
TITLE,MPMS RSO Measurement
BYAPP,MPMS Measurement,1.1,Summary
FILEOPENTIME, 1438281821.937000 7/30/2015, 11:43:41 PM

INFO, APPNAME, MPMS MultiVu Application, Revision 1.58,  Build 076

INFO, NAME, Unnamed
INFO, WEIGHT, 1.000
INFO, AREA, 1.000
INFO, LENGTH, 1.000
INFO, SHAPE, 0
INFO, COMMENT,
INFO, SEQUENCE FILE: m(T).seq


INFO, BACKGROUND DATA FILE:, None


STARTUPAXIS,X,4,LINEAR,AUTO,0.000000,0.000000
STARTUPAXIS,Y1,5,LINEAR,AUTO,0.000000,0.000000


STARTUPGROUP,Longitudinal
FIELDGROUP,Longitudinal,1,2,3,4,5,6,7,8,9,10,11,19,20,21,22,23,35
FIELDGROUP,Transverse,1,2,3,4,12,13,14,15,16,17,18,24,25,26,27,28,35

PLOT_APPEARANCE,ALL,HORZ_GRID_ON,VERT_GRID_ON,MARKERS_AND_LINES

[Data]
Time,Comment,Field (Oe),Temperature (K),Long Moment (emu),Long Scan Std Dev,Long Offset (cm),Long Offset Std Dev,Long Algorithm,Long Reg Fit,Long Reg Factor,Trans Moment (emu),Trans Scan Std Dev,Trans Offset (cm),Trans Offset Std Dev,Trans Algorithm,Trans Reg Fit,Trans Reg Factor,Long Moment [w/o ABS] (emu),Long Scan Std Dev [w/o ABS],Long Offset [w/o ABS] (cm),Long Offset Std Dev [w/o ABS],Long Reg Fit [w/o ABS],Trans Moment [w/o ABS] (emu),Trans Scan Std Dev [w/o ABS],Trans Offset [w/o ABS] (cm),Trans Offset Std Dev [w/o ABS],Trans Reg Fit [w/o ABS],RSO Position (deg),Amplitude (cm),Frequency,Cycles to Average,Scans per Measurement,Delta Temp (K),Error,EC Comp. Running,Using ABS,
1438281821.937,,9.999999e+002,2.009090e+000,2.998461e-005,0.000000e+000,1.456453e-002,0.000000e+000,3,9.806539e-001,1.825000e+000,,,,,,,,,,,,,,,,,,0,4.000000e+000,1.000000e+000,20,1,2.046001e-002,0,0,0,
1438282045.484,,9.999999e+002,5.208384e+000,6.761083e-006,0.000000e+000,1.424453e-001,0.000000e+000,3,8.777426e-001,1.825000e+000,,,,,,,,,,,,,,,,,,0,4.000000e+000,1.000000e+000,20,1,3.498011e-001,0,1,0,
1438282234.625,,9.999999e+002,8.256394e+000,1.984972e-006,0.000000e+000,8.818673e-001,0.000000e+000,3,4.036055e-001,1.825000e+000,,,,,,,,,,,,,,,,,,0,4.000000e+000,1.000000e+000,20,1,4.415913e-001,0,0,0,
1438282419.797,,9.999999e+002,1.121633e+001,-3.525271e-006,0.000000e+000,-4.874575e-001,0.000000e+000,3,8.528194e-001,1.825000e+000,,,,,,,,,,,,,,,,,,0,4.000000e+000,1.000000e+000,20,1,4.304800e-001,0,0,0,
1438282606.343,,9.999999e+002,1.431416e+001,-4.952370e-006,0.000000e+000,-3.110645e-001,0.000000e+000,3,8.625707e-001,1.825000e+000,,,,,,,,,,,,,,,,,,0,4.000000e+000,1.000000e+000,20,1,3.990507e-001,0,1,0,
1438282793.609,,9.999999e+002,1.733202e+001,-5.987924e-006,0.000000e+000,-2.510266e-001,0.000000e+000,3,8.769794e-001,1.825000e+000,,,,,,,,,,,,,,,,,,0,4.000000e+000,1.000000e+000,20,1,3.988705e-001,0,0,0,
1438282982.875,,9.999999e+002,2.031422e+001,-6.710221e-006,0.000000e+000,-2.212855e-001,0.000000e+000,3,8.865121e-001,1.825000e+000,,,,,,,,,,,,,,,,,,0,4.000000e+000,1.000000e+000,20,1,4.197998e-001,0,0,0,
1438283164.906,,9.999999e+002,2.332994e+001,-7.245091e-006,0.000000e+000,-2.051080e-001,0.000000e+000,3,8.922099e-001,1.825000e+000,,,,,,,,,,,,,,,,,,0,4.000000e+000,1.000000e+000,20,1,3.721905e-001,0,0,0,
1438283348.781,,9.999999e+002,2.633173e+001,-7.647985e-006,0.000000e+000,-1.942263e-001,0.000000e+000,3,8.960001e-001,1.825000e+000,,,,,,,,,,,,,,,,,,0,4.000000e+000,1.000000e+000,20,1,3.683109e-001,0,1,0,
1438283530.297,,9.999999e+002,2.924073e+001,-7.933498e-006,0.000000e+000,-1.858190e-001,0.000000e+000,3,8.991392e-001,1.825000e+000,,,,,,,,,,,,,,,,,,0,4.000000e+000,1.000000e+000,20,1,4.701900e-001,0,1,0,
1438283716.406,,9.999999e+002,3.224384e+001,-8.156662e-006,0.000000e+000,-1.800447e-001,0.000000e+000,3,9.011559e-001,1.825000e+000,,,,,,,,,,,,,,,,,,0,4.000000e+000,1.000000e+000,20,1,4.240417e-001,0,0,0,
1438283900.390,,9.999999e+002,3.534978e+001,-8.320179e-006,0.000000e+000,-1.759607e-001,0.000000e+000,3,9.027186e-001,1.825000e+000,,,,,,,,,,,,,,,,,,0,4.000000e+000,1.000000e+000,20,1,4.344482e-001,0,0,0,
1438284077.843,,9.999999e+002,3.827255e+001,-8.403693e-006,0.000000e+000,-1.731844e-001,0.000000e+000,3,9.030532e-001,1.825000e+000,,,,,,,,,,,,,,,,,,0,4.000000e+000,1.000000e+000,20,1,3.866997e-001,0,0,0,
1438284263.922,,9.999999e+002,4.126785e+001,-8.491467e-006,0.000000e+000,-1.718724e-001,0.000000e+000,3,9.037474e-001,1.825000e+000,,,,,,,,,,,,,,,,,,0,4.000000e+000,1.000000e+000,20,1,3.708496e-001,0,1,0,
1438284444.687,,9.999999e+002,4.426814e+001,-8.589852e-006,0.000000e+000,-1.699722e-001,0.000000e+000,3,9.055923e-001,1.825000e+000,,,,,,,,,,,,,,,,,,0,4.000000e+000,1.000000e+000,20,1,4.620399e-001,0,1,0,
1438284621.437,,9.999999e+002,4.723289e+001,-8.700415e-006,0.000000e+000,-1.666436e-001,0.000000e+000,3,9.064791e-001,1.825000e+000,,,,,,,,,,,,,,,,,,0,4.000000e+000,1.000000e+000,20,1,4.073410e-001,0,1,0,
1438284813.703,,9.999999e+002,5.028498e+001,-8.828622e-006,0.000000e+000,-1.635910e-001,0.000000e+000,3,9.057276e-001,1.825000e+000,,,,,,,,,,,,,,,,,,0,4.000000e+000,1.000000e+000,20,1,4.249802e-001,0,0,0,
1438284998.703,,9.999999e+002,5.327809e+001,-9.071321e-006,0.000000e+000,-1.599181e-001,0.000000e+000,3,9.078932e-001,1.825000e+000,,,,,,,,,,,,,,,,,,0,4.000000e+000,1.000000e+000,20,1,3.704185e-001,0,0,0,
1438285177.828,,9.999999e+002,5.626437e+001,-9.227487e-006,0.000000e+000,-1.570802e-001,0.000000e+000,3,9.083048e-001,1.825000e+000,,,,,,,,,,,,,,,,,,0,4.000000e+000,1.000000e+000,20,1,4.596100e-001,0,1,0,
1438285355.109,,9.999999e+002,5.921577e+001,-9.265479e-006,0.000000e+000,-1.554939e-001,0.000000e+000,3,9.090073e-001,1.825000e+000,,,,,,,,,,,,,,,,,,0,4.000000e+000,1.000000e+000,20,1,4.167137e-001,0,1,0,
1438285545.593,,9.999999e+002,6.231644e+001,-9.215959e-006,0.000000e+000,-1.578971e-001,0.000000e+000,3,9.089629e-001,1.825000e+000,,,,,,,,,,,,,,,,,,0,4.000000e+000,1.000000e+000,20,1,4.320107e-001,0,1,0,
1438285731.343,,9.999999e+002,6.529499e+001,-9.041350e-006,0.000000e+000,-1.602705e-001,0.000000e+000,3,9.072056e-001,1.825000e+000,,,,,,,,,,,,,,,,,,0,4.000000e+000,1.000000e+000,20,1,4.010773e-001,0,0,0,
1438285913.797,,9.999999e+002,6.827057e+001,-8.779840e-006,0.000000e+000,-1.652017e-001,0.000000e+000,3,9.049749e-001,1.825000e+000,,,,,,,,,,,,,,,,,,0,4.000000e+000,1.000000e+000,20,1,3.749924e-001,0,0,0,
1438286099.640,,9.999999e+002,7.128915e+001,-8.396334e-006,0.000000e+000,-1.725584e-001,0.000000e+000,3,9.024291e-001,1.825000e+000,,,,,,,,,,,,,,,,,,0,4.000000e+000,1.000000e+000,20,1,4.412613e-001,0,0,0,
1438286274.187,,9.999999e+002,7.419902e+001,-7.835263e-006,0.000000e+000,-1.850564e-001,0.000000e+000,3,8.977665e-001,1.825000e+000,,,,,,,,,,,,,,,,,,0,4.000000e+000,1.000000e+000,20,1,3.906860e-001,0,1,0,
1438286463.093,,9.999999e+002,7.726060e+001,-6.886655e-006,0.000000e+000,-2.094308e-001,0.000000e+000,3,8.864514e-001,1.825000e+000,,,,,,,,,,,,,,,,,,0,4.000000e+000,1.000000e+000,20,1,4.279785e-001,0,1,0,
1438286639.859,,9.999999e+002,8.021689e+001,-5.434734e-006,0.000000e+000,-2.695431e-001,0.000000e+000,3,8.673710e-001,1.825000e+000,,,,,,,,,,,,,,,,,,0,4.000000e+000,1.000000e+000,20,1,4.134903e-001,0,0,0,
1438286827.093,,9.999999e+002,8.326692e+001,-4.436821e-006,0.000000e+000,-3.426030e-001,0.000000e+000,3,8.488720e-001,1.825000e+000,,,,,,,,,,,,,,,,,,0,4.000000e+000,1.000000e+000,20,1,4.075241e-001,0,0,0,
1438287017.359,,9.999999e+002,8.628496e+001,-4.124780e-006,0.000000e+000,-3.778992e-001,0.000000e+000,3,8.446041e-001,1.825000e+000,,,,,,,,,,,,,,,,,,0,4.000000e+000,1.000000e+000,20,1,4.845505e-001,0,0,0,
1438287192.656,,9.999999e+002,8.924480e+001,-3.902421e-006,0.000000e+000,-4.108015e-001,0.000000e+000,3,8.418033e-001,1.825000e+000,,,,,,,,,,,,,,,,,,0,4.000000e+000,1.000000e+000,20,1,4.274673e-001,0,1,0,
1438287378.203,,9.999999e+002,9.229230e+001,-3.729896e-006,0.000000e+000,-4.363514e-001,0.000000e+000,3,8.448289e-001,1.825000e+000,,,,,,,,,,,,,,,,,,0,4.000000e+000,1.000000e+000,20,1,4.389114e-001,0,1,0,
1438287565.218,,9.999999e+002,9.524498e+001,-3.590248e-006,0.000000e+000,-4.619573e-001,0.000000e+000,3,8.393906e-001,1.825000e+000,,,,,,,,,,,,,,,,,,0,4.000000e+000,1.000000e+000,20,1,3.635941e-001,0,0,0,
1438287747.297,,9.999999e+002,9.823026e+001,-3.499972e-006,0.000000e+000,-4.865173e-001,0.000000e+000,3,8.413897e-001,1.825000e+000,,,,,,,,,,,,,,,,,,0,4.000000e+000,1.000000e+000,20,1,4.570236e-001,0,0,0,
1438287928.750,,9.999999e+002,1.012386e+002,-3.417803e-006,0.000000e+000,-5.069738e-001,0.000000e+000,3,8.449572e-001,1.825000e+000,,,,,,,,,,,,,,,,,,0,4.000000e+000,1.000000e+000,20,1,4.369965e-001,0,0,0,
1438288114.515,,9.999999e+002,1.042673e+002,-3.351470e-006,0.000000e+000,-5.222675e-001,0.000000e+000,3,8.466244e-001,1.825000e+000,,,,,,,,,,,,,,,,,,0,4.000000e+000,1.000000e+000,20,1,3.707962e-001,0,1,0,
1438288298.953,,9.999999e+002,1.072797e+002,-3.335114e-006,0.000000e+000,-5.355831e-001,0.000000e+000,3,8.542155e-001,1.825000e+000,,,,,,,,,,,,,,,,,,0,4.000000e+000,1.000000e+000,20,1,4.413986e-001,0,1,0,
1438288476.218,,9.999999e+002,1.102722e+002,-3.290931e-006,0.000000e+000,-5.486169e-001,0.000000e+000,3,8.477237e-001,1.825000e+000,,,,,,,,,,,,,,,,,,0,4.000000e+000,1.000000e+000,20,1,4.675980e-001,0,1,0,
1438288666.218,,9.999999e+002,1.133635e+002,-3.322814e-006,0.000000e+000,-5.562918e-001,0.000000e+000,3,8.521803e-001,1.825000e+000,,,,,,,,,,,,,,,,,,0,4.000000e+000,1.000000e+000,20,1,3.941040e-001,0,0,0,
1438288850.187,,9.999999e+002,1.163223e+002,-3.291130e-006,0.000000e+000,-5.611121e-001,0.000000e+000,3,8.577917e-001,1.825000e+000,,,,,,,,,,,,,,,,,,0,4.000000e+000,1.000000e+000,20,1,4.207993e-001,0,0,0,
1438289031.984,,9.999999e+002,1.192773e+002,-3.285251e-006,0.000000e+000,-5.635129e-001,0.000000e+000,3,8.604671e-001,1.825000e+000,,,,,,,,,,,,,,,,,,0,4.000000e+000,1.000000e+000,20,1,4.197998e-001,0,0,0,
1438289210.734,,9.999999e+002,1.222378e+002,-3.294823e-006,0.000000e+000,-5.646265e-001,0.000000e+000,3,8.559287e-001,1.825000e+000,,,,,,,,,,,,,,,,,,0,4.000000e+000,1.000000e+000,20,1,4.087982e-001,0,1,0,
1438289401.031,,9.999999e+002,1.252626e+002,-3.302934e-006,0.000000e+000,-5.594442e-001,0.000000e+000,3,8.573889e-001,1.825000e+000,,,,,,,,,,,,,,,,,,0,4.000000e+000,1.000000e+000,20,1,4.318008e-001,0,1,0,
1438289626.937,,9.999999e+002,1.289159e+002,-3.279927e-006,0.000000e+000,-5.626991e-001,0.000000e+000,3,8.524052e-001,1.825000e+000,,,,,,,,,,,,,,,,,,0,4.000000e+000,1.000000e+000,20,1,4.405975e-001,0,0,0,
1438289768.656,,9.999999e+002,1.312679e+002,-3.310573e-006,0.000000e+000,-5.629175e-001,0.000000e+000,3,8.550707e-001,1.825000e+000,,,,,,,,,,,,,,,,,,0,4.000000e+000,1.000000e+000,20,1,3.914948e-001,0,0,0,
1438289952.218,,9.999999e+002,1.342820e+002,-3.340443e-006,0.000000e+000,-5.599747e-001,0.000000e+000,3,8.541281e-001,1.825000e+000,,,,,,,,,,,,,,,,,,0,4.000000e+000,1.000000e+000,20,1,4.434967e-001,0,1,0,
1438290137.734,,9.999999e+002,1.372661e+002,-3.349011e-006,0.000000e+000,-5.557483e-001,0.000000e+000,3,8.553554e-001,1.825000e+000,,,,,,,,,,,,,,,,,,0,4.000000e+000,1.000000e+000,20,1,3.659058e-001,0,1,0,
1438290319.203,,9.999999e+002,1.402534e+002,-3.389272e-006,0.000000e+000,-5.529974e-001,0.000000e+000,3,8.564217e-001,1.825000e+000,,,,,,,,,,,,,,,,,,0,4.000000e+000,1.000000e+000,20,1,4.629974e-001,0,1,0,
1438290500.718,,9.999999e+002,1.433006e+002,-3.383365e-006,0.000000e+000,-5.407240e-001,0.000000e+000,3,8.516552e-001,1.825000e+000,,,,,,,,,,,,,,,,,,0,4.000000e+000,1.000000e+000,20,1,4.140930e-001,0,0,0,
1438290684.484,,9.999999e+002,1.462628e+002,-3.421629e-006,0.000000e+000,-5.363660e-001,0.000000e+000,3,8.513934e-001,1.825000e+000,,,,,,,,,,,,,,,,,,0,4.000000e+000,1.000000e+000,20,1,4.642944e-001,0,0,0,
1438290872.328,,9.999999e+002,1.492744e+002,-3.433923e-006,0.000000e+000,-5.325826e-001,0.000000e+000,3,8.485678e-001,1.825000e+000,,,,,,,,,,,,,,,,,,0,4.000000e+000,1.000000e+000,20,1,4.264984e-001,0,1,0,
1438291050.468,,9.999999e+002,1.522458e+002,-3.465274e-006,0.000000e+000,-5.264398e-001,0.000000e+000,3,8.509290e-001,1.825000e+000,,,,,,,,,,,,,,,,,,0,4.000000e+000,1.000000e+000,20,1,4.295959e-001,0,1,0,
1438291236.218,,9.999999e+002,1.553785e+002,-3.473942e-006,0.000000e+000,-5.189890e-001,0.000000e+000,3,8.566003e-001,1.825000e+000,,,,,,,,,,,,,,,,,,0,4.000000e+000,1.000000e+000,20,1,3.994904e-001,0,1,0,
1438291415.687,,9.999999e+002,1.582396e+002,-3.504483e-006,0.000000e+000,-5.112057e-001,0.000000e+000,3,8.500407e-001,1.825000e+000,,,,,,,,,,,,,,,,,,0,4.000000e+000,1.000000e+000,20,1,3.787994e-001,0,0,0,
1438291604.437,,9.999999e+002,1.612787e+002,-3.539912e-006,0.000000e+000,-5.055447e-001,0.000000e+000,3,8.508519e-001,1.825000e+000,,,,,,,,,,,,,,,,,,0,4.000000e+000,1.000000e+000,20,1,4.281006e-001,0,0,0,
1438291785.203,,9.999999e+002,1.642992e+002,-3.556892e-006,0.000000e+000,-4.942933e-001,0.000000e+000,3,8.482165e-001,1.825000e+000,,,,,,,,,,,,,,,,,,0,4.000000e+000,1.000000e+000,20,1,4.138031e-001,0,1,0,
1438291967.172,,9.999999e+002,1.672563e+002,-3.605089e-006,0.000000e+000,-4.914261e-001,0.000000e+000,3,8.469669e-001,1.825000e+000,,,,,,,,,,,,,,,,,,0,4.000000e+000,1.000000e+000,20,1,4.204102e-001,0,1,0,
1438292153.500,,9.999999e+002,1.702878e+002,-3.650642e-006,0.000000e+000,-4.838961e-001,0.000000e+000,3,8.497881e-001,1.825000e+000,,,,,,,,,,,,,,,,,,0,4.000000e+000,1.000000e+000,20,1,4.664001e-001,0,1,0,
1438292334.812,,9.999999e+002,1.732653e+002,-3.678264e-006,0.000000e+000,-4.758561e-001,0.000000e+000,3,8.469811e-001,1.825000e+000,,,,,,,,,,,,,,,,,,0,4.000000e+000,1.000000e+000,20,1,4.412079e-001,0,0,0,
1438292520.578,,9.999999e+002,1.763088e+002,-3.714600e-006,0.000000e+000,-4.695488e-001,0.000000e+000,3,8.460407e-001,1.825000e+000,,,,,,,,,,,,,,,,,,0,4.000000e+000,1.000000e+000,20,1,3.798981e-001,0,0,0,
1438292702.359,,9.999999e+002,1.792590e+002,-3.732826e-006,0.000000e+000,-4.643142e-001,0.000000e+000,3,8.462721e-001,1.825000e+000,,,,,,,,,,,,,,,,,,0,4.000000e+000,1.000000e+000,20,1,4.443054e-001,0,0,0,
1438292889.875,,9.999999e+002,1.822906e+002,-3.782549e-006,0.000000e+000,-4.593243e-001,0.000000e+000,3,8.444469e-001,1.825000e+000,,,,,,,,,,,,,,,,,,0,4.000000e+000,1.000000e+000,20,1,4.676056e-001,0,1,0,
1438293065.390,,9.999999e+002,1.852404e+002,-3.799350e-006,0.000000e+000,-4.496096e-001,0.000000e+000,3,8.410987e-001,1.825000e+000,,,,,,,,,,,,,,,,,,0,4.000000e+000,1.000000e+000,20,1,4.356995e-001,0,1,0,
1438293253.906,,9.999999e+002,1.883491e+002,-3.841599e-006,0.000000e+000,-4.451004e-001,0.000000e+000,3,8.444178e-001,1.825000e+000,,,,,,,,,,,,,,,,,,0,4.000000e+000,1.000000e+000,20,1,3.733063e-001,0,0,0,
1438293435.187,,9.999999e+002,1.913071e+002,-3.891556e-006,0.000000e+000,-4.400580e-001,0.000000e+000,3,8.459030e-001,1.825000e+000,,,,,,,,,,,,,,,,,,0,4.000000e+000,1.000000e+000,20,1,4.140930e-001,0,0,0,
1438293622.890,,9.999999e+002,1.943345e+002,-3.931439e-006,0.000000e+000,-4.343427e-001,0.000000e+000,3,8.479362e-001,1.825000e+000,,,,,,,,,,,,,,,,,,0,4.000000e+000,1.000000e+000,20,1,4.367981e-001,0,0,0,
1438293799.203,,9.999999e+002,1.972977e+002,-3.982473e-006,0.000000e+000,-4.245414e-001,0.000000e+000,3,8.487359e-001,1.825000e+000,,,,,,,,,,,,,,,,,,0,4.000000e+000,1.000000e+000,20,1,3.764038e-001,0,1,0,
1438293982.656,,9.999999e+002,2.002138e+002,-4.011845e-006,0.000000e+000,-4.240001e-001,0.000000e+000,3,8.452463e-001,1.825000e+000,,,,,,,,,,,,,,,,,,0,4.000000e+000,1.000000e+000,20,1,3.871002e-001,0,1,0,
1438294167.906,,9.999999e+002,2.032577e+002,-4.022774e-006,0.000000e+000,-4.200063e-001,0.000000e+000,3,8.417102e-001,1.825000e+000,,,,,,,,,,,,,,,,,,0,4.000000e+000,1.000000e+000,20,1,4.206085e-001,0,1,0,
1438294347.437,,9.999999e+002,2.062229e+002,-4.094756e-006,0.000000e+000,-4.055000e-001,0.000000e+000,3,8.461594e-001,1.825000e+000,,,,,,,,,,,,,,,,,,0,4.000000e+000,1.000000e+000,20,1,4.147949e-001,0,0,0,
1438294529.437,,9.999999e+002,2.092410e+002,-4.132613e-006,0.000000e+000,-4.025525e-001,0.000000e+000,3,8.483104e-001,1.825000e+000,,,,,,,,,,,,,,,,,,0,4.000000e+000,1.000000e+000,20,1,4.039001e-001,0,0,0,
1438294719.703,,9.999999e+002,2.123230e+002,-4.171121e-006,0.000000e+000,-3.977392e-001,0.000000e+000,3,8.499063e-001,1.825000e+000,,,,,,,,,,,,,,,,,,0,4.000000e+000,1.000000e+000,20,1,3.916016e-001,0,1,0,
1438294897.687,,9.999999e+002,2.152751e+002,-4.209970e-006,0.000000e+000,-3.917055e-001,0.000000e+000,3,8.458564e-001,1.825000e+000,,,,,,,,,,,,,,,,,,0,4.000000e+000,1.000000e+000,20,1,4.951019e-001,0,1,0,
1438295074.875,,9.999999e+002,2.182733e+002,-4.263962e-006,0.000000e+000,-3.857709e-001,0.000000e+000,3,8.481104e-001,1.825000e+000,,,,,,,,,,,,,,,,,,0,4.000000e+000,1.000000e+000,20,1,4.196930e-001,0,1,0,
1438295259.047,,9.999999e+002,2.212368e+002,-4.306210e-006,0.000000e+000,-3.809004e-001,0.000000e+000,3,8.470002e-001,1.825000e+000,,,,,,,,,,,,,,,,,,0,4.000000e+000,1.000000e+000,20,1,4.178009e-001,0,0,0,
1438295444.562,,9.999999e+002,2.242363e+002,-4.361301e-006,0.000000e+000,-3.765451e-001,0.000000e+000,3,8.515966e-001,1.825000e+000,,,,,,,,,,,,,,,,,,0,4.000000e+000,1.000000e+000,20,1,3.952942e-001,0,0,0,
1438295628.797,,9.999999e+002,2.272302e+002,-4.391101e-006,0.000000e+000,-3.708208e-001,0.000000e+000,3,8.508661e-001,1.825000e+000,,,,,,,,,,,,,,,,,,0,4.000000e+000,1.000000e+000,20,1,4.470062e-001,0,1,0,
1438295813.484,,9.999999e+002,2.303242e+002,-4.416586e-006,0.000000e+000,-3.641294e-001,0.000000e+000,3,8.520536e-001,1.825000e+000,,,,,,,,,,,,,,,,,,0,4.000000e+000,1.000000e+000,20,1,3.742065e-001,0,1,0,
1438295999.000,,9.999999e+002,2.333238e+002,-4.456380e-006,0.000000e+000,-3.594529e-001,0.000000e+000,3,8.512302e-001,1.825000e+000,,,,,,,,,,,,,,,,,,0,4.000000e+000,1.000000e+000,20,1,3.766022e-001,0,1,0,
1438296180.531,,9.999999e+002,2.362762e+002,-4.485698e-006,0.000000e+000,-3.569746e-001,0.000000e+000,3,8.487757e-001,1.825000e+000,,,,,,,,,,,,,,,,,,0,4.000000e+000,1.000000e+000,20,1,3.787079e-001,0,0,0,
1438296364.843,,9.999999e+002,2.393538e+002,-2.871414e-006,0.000000e+000,3.072048e-001,0.000000e+000,3,8.628893e-001,1.825000e+000,,,,,,,,,,,,,,,,,,0,4.000000e+000,1.000000e+000,20,1,4.192047e-001,0,0,0,
1438296543.156,,9.999999e+002,2.422898e+002,-2.923381e-006,0.000000e+000,3.035863e-001,0.000000e+000,3,8.692179e-001,1.825000e+000,,,,,,,,,,,,,,,,,,0,4.000000e+000,1.000000e+000,20,1,4.530029e-001,0,1,0,
1438296726.625,,9.999999e+002,2.452504e+002,-2.964998e-006,0.000000e+000,2.957281e-001,0.000000e+000,3,8.687940e-001,1.825000e+000,,,,,,,,,,,,,,,,,,0,4.000000e+000,1.000000e+000,20,1,3.919983e-001,0,1,0,
1438296908.140,,9.999999e+002,2.482472e+002,-3.011783e-006,0.000000e+000,3.048170e-001,0.000000e+000,3,8.675712e-001,1.825000e+000,,,,,,,,,,,,,,,,,,0,4.000000e+000,1.000000e+000,20,1,4.344025e-001,0,1,0,
1438297090.328,,9.999999e+002,2.512548e+002,-3.029421e-006,0.000000e+000,2.863384e-001,0.000000e+000,3,8.686095e-001,1.825000e+000,,,,,,,,,,,,,,,,,,0,4.000000e+000,1.000000e+000,20,1,4.029999e-001,0,0,0,
1438297276.578,,9.999999e+002,2.542542e+002,-3.097746e-006,0.000000e+000,2.756745e-001,0.000000e+000,3,8.746967e-001,1.825000e+000,,,,,,,,,,,,,,,,,,0,4.000000e+000,1.000000e+000,20,1,4.299011e-001,0,0,0,
1438297462.609,,9.999999e+002,2.572507e+002,-3.136283e-006,0.000000e+000,2.676658e-001,0.000000e+000,3,8.789485e-001,1.825000e+000,,,,,,,,,,,,,,,,,,0,4.000000e+000,1.000000e+000,20,1,4.135742e-001,0,0,0,
1438297643.578,,9.999999e+002,2.602823e+002,-3.170009e-006,0.000000e+000,2.660450e-001,0.000000e+000,3,8.832421e-001,1.825000e+000,,,,,,,,,,,,,,,,,,0,4.000000e+000,1.000000e+000,20,1,3.963928e-001,0,1,0,
1438297825.093,,9.999999e+002,2.632483e+002,-3.152946e-006,0.000000e+000,2.646287e-001,0.000000e+000,3,8.789707e-001,1.825000e+000,,,,,,,,,,,,,,,,,,0,4.000000e+000,1.000000e+000,20,1,4.164124e-001,0,1,0,
1438298014.953,,9.999999e+002,2.663090e+002,-3.151684e-006,0.000000e+000,2.642503e-001,0.000000e+000,3,8.821428e-001,1.825000e+000,,,,,,,,,,,,,,,,,,0,4.000000e+000,1.000000e+000,20,1,3.872070e-001,0,0,0,
1438298197.922,,9.999999e+002,2.692847e+002,-3.217110e-006,0.000000e+000,2.578664e-001,0.000000e+000,3,8.824723e-001,1.825000e+000,,,,,,,,,,,,,,,,,,0,4.000000e+000,1.000000e+000,20,1,4.638977e-001,0,0,0,
1438298375.922,,9.999999e+002,2.722514e+002,-3.228654e-006,0.000000e+000,2.552489e-001,0.000000e+000,3,8.803215e-001,1.825000e+000,,,,,,,,,,,,,,,,,,0,4.000000e+000,1.000000e+000,20,1,4.053955e-001,0,0,0,
1438298561.656,,9.999999e+002,2.752618e+002,-3.283284e-006,0.000000e+000,2.579449e-001,0.000000e+000,3,8.797081e-001,1.825000e+000,,,,,,,,,,,,,,,,,,0,4.000000e+000,1.000000e+000,20,1,4.147949e-001,0,1,0,
1438298746.875,,9.999999e+002,2.782852e+002,-3.278221e-006,0.000000e+000,2.563010e-001,0.000000e+000,3,8.693476e-001,1.825000e+000,,,,,,,,,,,,,,,,,,0,4.000000e+000,1.000000e+000,20,1,4.346924e-001,0,1,0,
1438298990.312,,9.999999e+002,2.823614e+002,-3.370430e-006,0.000000e+000,2.681064e-001,0.000000e+000,3,8.762469e-001,1.825000e+000,,,,,,,,,,,,,,,,,,0,4.000000e+000,1.000000e+000,20,1,4.051819e-001,0,1,0,
1438299108.015,,9.999999e+002,2.842946e+002,-3.353965e-006,0.000000e+000,2.653645e-001,0.000000e+000,3,8.785906e-001,1.825000e+000,,,,,,,,,,,,,,,,,,0,4.000000e+000,1.000000e+000,20,1,4.326782e-001,0,0,0,
1438299293.000,,9.999999e+002,2.872574e+002,-3.394023e-006,0.000000e+000,2.629079e-001,0.000000e+000,3,8.774552e-001,1.825000e+000,,,,,,,,,,,,,,,,,,0,4.000000e+000,1.000000e+000,20,1,4.199219e-001,0,0,0,
1438299479.047,,9.999999e+002,2.902508e+002,-3.438700e-006,0.000000e+000,2.627024e-001,0.000000e+000,3,8.756170e-001,1.825000e+000,,,,,,,,,,,,,,,,,,0,4.000000e+000,1.000000e+000,20,1,4.515991e-001,0,1,0,
1438299661.984,,9.999999e+002,2.933091e+002,-3.485505e-006,0.000000e+000,2.639745e-001,0.000000e+000,3,8.723888e-001,1.825000e+000,,,,,,,,,,,,,,,,,,0,4.000000e+000,1.000000e+000,20,1,4.153137e-001,0,1,0,
1438299844.093,,9.999999e+002,2.963048e+002,-3.505951e-006,0.000000e+000,2.577873e-001,0.000000e+000,3,8.737556e-001,1.825000e+000,,,,,,,,,,,,,,,,,,0,4.000000e+000,1.000000e+000,20,1,3.533936e-001,0,1,0,
1438300032.375,,9.999999e+002,2.993425e+002,-3.537594e-006,0.000000e+000,2.567887e-001,0.000000e+000,3,8.773628e-001,1.825000e+000,,,,,,,,,,,,,,,,,,0,4.000000e+000,1.000000e+000,20,1,3.494263e-001,0,0,0,
1438300215.937,,9.999999e+002,3.023199e+002,-3.591919e-006,0.000000e+000,2.555678e-001,0.000000e+000,3,8.803545e-001,1.825000e+000,,,,,,,,,,,,,,,,,,0,4.000000e+000,1.000000e+000,20,1,4.186096e-001,0,0,0,
1438300392.000,,9.999999e+002,3.052618e+002,-3.608818e-006,0.000000e+000,2.624413e-001,0.000000e+000,3,8.817210e-001,1.825000e+000,,,,,,,,,,,,,,,,,,0,4.000000e+000,1.000000e+000,20,1,3.897095e-001,0,1,0,
1438300577.703,,9.999999e+002,3.082668e+002,-3.630483e-006,0.000000e+000,2.630328e-001,0.000000e+000,3,8.810069e-001,1.825000e+000,,,,,,,,,,,,,,,,,,0,4.000000e+000,1.000000e+000,20,1,4.366150e-001,0,1,0,
1438300757.781,,9.999999e+002,3.112119e+002,-3.677717e-006,0.000000e+000,2.585990e-001,0.000000e+000,3,8.762062e-001,1.825000e+000,,,,,,,,,,,,,,,,,,0,4.000000e+000,1.000000e+000,20,1,4.194946e-001,0,1,0,
1438300939.515,,9.999999e+002,3.142384e+002,-3.710549e-006,0.000000e+000,2.597355e-001,0.000000e+000,3,8.816280e-001,1.825000e+000,,,,,,,,,,,,,,,,,,0,4.000000e+000,1.000000e+000,20,1,3.881836e-001,0,0,0,
1438301116.765,,9.999999e+002,3.172062e+002,-3.747801e-006,0.000000e+000,2.539304e-001,0.000000e+000,3,8.834195e-001,1.825000e+000,,,,,,,,,,,,,,,,,,0,4.000000e+000,1.000000e+000,20,1,4.096985e-001,0,0,0,
1438301302.984,,9.999999e+002,3.202276e+002,-3.737262e-006,0.000000e+000,2.516720e-001,0.000000e+000,3,8.868302e-001,1.825000e+000,,,,,,,,,,,,,,,,,,0,4.000000e+000,1.000000e+000,20,1,3.624268e-001,0,0,0,
1438301491.468,,9.999999e+002,3.233258e+002,-3.793734e-006,0.000000e+000,2.470057e-001,0.000000e+000,3,8.904756e-001,1.825000e+000,,,,,,,,,,,,,,,,,,0,4.000000e+000,1.000000e+000,20,1,4.268188e-001,0,1,0,
1438301664.718,,9.999999e+002,3.262562e+002,-3.783265e-006,0.000000e+000,2.438539e-001,0.000000e+000,3,8.865317e-001,1.825000e+000,,,,,,,,,,,,,,,,,,0,4.000000e+000,1.000000e+000,20,1,3.771057e-001,0,1,0,
1438301848.984,,9.999999e+002,3.292365e+002,-3.830077e-006,0.000000e+000,2.409647e-001,0.000000e+000,3,8.937746e-001,1.825000e+000,,,,,,,,,,,,,,,,,,0,4.000000e+000,1.000000e+000,20,1,3.992920e-001,0,1,0,
1438302039.297,,9.999999e+002,3.323204e+002,-3.888754e-006,0.000000e+000,2.407012e-001,0.000000e+000,3,8.901350e-001,1.825000e+000,,,,,,,,,,,,,,,,,,0,4.000000e+000,1.000000e+000,20,1,3.619080e-001,0,0,0,
1438302217.875,,9.999999e+002,3.352432e+002,-3.861695e-006,0.000000e+000,2.304267e-001,0.000000e+000,3,8.981493e-001,1.825000e+000,,,,,,,,,,,,,,,,,,0,4.000000e+000,1.000000e+000,20,1,4.302979e-001,0,0,0,
1438302401.093,,9.999999e+002,3.381968e+002,-3.897938e-006,0.000000e+000,2.208511e-001,0.000000e+000,3,8.968868e-001,1.825000e+000,,,,,,,,,,,,,,,,,,0,4.000000e+000,1.000000e+000,20,1,3.446045e-001,0,0,0,
1438302597.218,,9.999999e+002,3.412814e+002,-3.908327e-006,0.000000e+000,2.149317e-001,0.000000e+000,3,8.983126e-001,1.825000e+000,,,,,,,,,,,,,,,,,,0,4.000000e+000,1.000000e+000,20,1,3.834229e-001,0,1,0,
1438302781.250,,9.999999e+002,3.442891e+002,-3.893887e-006,0.000000e+000,2.084892e-001,0.000000e+000,3,8.960874e-001,1.825000e+000,,,,,,,,,,,,,,,,,,0,4.000000e+000,1.000000e+000,20,1,4.396057e-001,0,1,0,
1438302956.984,,9.999999e+002,3.472550e+002,-4.001713e-006,0.000000e+000,2.034132e-001,0.000000e+000,3,9.031292e-001,1.825000e+000,,,,,,,,,,,,,,,,,,0,4.000000e+000,1.000000e+000,20,1,3.980103e-001,0,1,0,
1438303412.265,,9.999999e+002,3.499640e+002,-4.041657e-006,0.000000e+000,1.933289e-001,0.000000e+000,3,9.097087e-001,1.825000e+000,,,,,,,,,,,,,,,,,,0,4.000000e+000,1.000000e+000,20,1,3.369141e-002,0,0,0,
1438303871.906,,9.999999e+002,3.475707e+002,-3.935504e-006,0.000000e+000,1.931930e-001,0.000000e+000,3,8.975759e-001,1.825000e+000,,,,,,,,,,,,,,,,,,0,4.000000e+000,1.000000e+000,20,1,6.315002e-001,0,1,0,
1438303970.890,,9.999999e+002,3.442086e+002,-3.957966e-006,0.000000e+000,2.013311e-001,0.000000e+000,3,9.084533e-001,1.825000e+000,,,,,,,,,,,,,,,,,,0,4.000000e+000,1.000000e+000,20,1,1.155273e+000,0,1,0,
1438304058.375,,9.999999e+002,3.410663e+002,-3.896394e-006,0.000000e+000,1.991479e-001,0.000000e+000,3,9.007996e-001,1.825000e+000,,,,,,,,,,,,,,,,,,0,4.000000e+000,1.000000e+000,20,1,7.498779e-001,0,1,0,
1438304172.343,,9.999999e+002,3.388718e+002,-3.871305e-006,0.000000e+000,2.014153e-001,0.000000e+000,3,9.001831e-001,1.825000e+000,,,,,,,,,,,,,,,,,,0,4.000000e+000,1.000000e+000,20,1,2.202148e-001,0,1,0,
1438304515.484,,9.999999e+002,3.357310e+002,-3.847827e-006,0.000000e+000,2.013726e-001,0.000000e+000,3,8.995613e-001,1.825000e+000,,,,,,,,,,,,,,,,,,0,4.000000e+000,1.000000e+000,20,1,5.146179e-001,0,1,0,
1438304681.031,,9.999999e+002,3.327508e+002,-3.814691e-006,0.000000e+000,2.077966e-001,0.000000e+000,3,8.974923e-001,1.825000e+000,,,,,,,,,,,,,,,,,,0,4.000000e+000,1.000000e+000,20,1,4.083862e-001,0,1,0,
1438304877.734,,9.999999e+002,3.297623e+002,-3.784580e-006,0.000000e+000,2.134768e-001,0.000000e+000,3,8.987918e-001,1.825000e+000,,,,,,,,,,,,,,,,,,0,4.000000e+000,1.000000e+000,20,1,4.450989e-001,0,1,0,
1438305061.218,,9.999999e+002,3.267357e+002,-3.691307e-006,0.000000e+000,2.076747e-001,0.000000e+000,3,8.970873e-001,1.825000e+000,,,,,,,,,,,,,,,,,,0,4.000000e+000,1.000000e+000,20,1,4.364929e-001,0,1,0,
1438305253.968,,9.999999e+002,3.236962e+002,-3.710471e-006,0.000000e+000,2.117439e-001,0.000000e+000,3,8.947482e-001,1.825000e+000,,,,,,,,,,,,,,,,,,0,4.000000e+000,1.000000e+000,20,1,4.564209e-001,0,1,0,
1438305437.781,,9.999999e+002,3.207583e+002,-3.675306e-006,0.000000e+000,2.214693e-001,0.000000e+000,3,8.918544e-001,1.825000e+000,,,,,,,,,,,,,,,,,,0,4.000000e+000,1.000000e+000,20,1,4.476013e-001,0,1,0,
1438305626.047,,9.999999e+002,3.177330e+002,-3.641692e-006,0.000000e+000,2.204728e-001,0.000000e+000,3,8.976951e-001,1.825000e+000,,,,,,,,,,,,,,,,,,0,4.000000e+000,1.000000e+000,20,1,4.523010e-001,0,1,0,
1438305795.343,,9.999999e+002,3.147076e+002,-3.561378e-006,0.000000e+000,2.192281e-001,0.000000e+000,3,8.822198e-001,1.825000e+000,,,,,,,,,,,,,,,,,,0,4.000000e+000,1.000000e+000,20,1,4.699097e-001,0,0,0,
1438305937.093,,9.999999e+002,3.116584e+002,-3.571889e-006,0.000000e+000,2.255839e-001,0.000000e+000,3,8.904488e-001,1.825000e+000,,,,,,,,,,,,,,,,,,0,4.000000e+000,1.000000e+000,20,1,6.311951e-001,0,1,0,
1438306090.547,,9.999999e+002,3.086847e+002,-3.501485e-006,0.000000e+000,2.269270e-001,0.000000e+000,3,8.811403e-001,1.825000e+000,,,,,,,,,,,,,,,,,,0,4.000000e+000,1.000000e+000,20,1,3.734131e-001,0,1,0,
1438306316.172,,9.999999e+002,3.057466e+002,-3.500155e-006,0.000000e+000,2.310129e-001,0.000000e+000,3,8.777100e-001,1.825000e+000,,,,,,,,,,,,,,,,,,0,4.000000e+000,1.000000e+000,20,1,3.280029e-001,0,1,0,
1438306521.437,,9.999999e+002,3.027637e+002,-3.433039e-006,0.000000e+000,2.265282e-001,0.000000e+000,3,8.834293e-001,1.825000e+000,,,,,,,,,,,,,,,,,,0,4.000000e+000,1.000000e+000,20,1,3.705139e-001,0,1,0,
1438306723.672,,9.999999e+002,2.997468e+002,-3.423037e-006,0.000000e+000,2.315910e-001,0.000000e+000,3,8.781265e-001,1.825000e+000,,,,,,,,,,,,,,,,,,0,4.000000e+000,1.000000e+000,20,1,4.590759e-001,0,1,0,
1438306920.890,,9.999999e+002,2.967296e+002,-3.398773e-006,0.000000e+000,2.419461e-001,0.000000e+000,3,8.715585e-001,1.825000e+000,,,,,,,,,,,,,,,,,,0,4.000000e+000,1.000000e+000,20,1,4.489136e-001,0,1,0,
1438307103.687,,9.999999e+002,2.937482e+002,-3.391148e-006,0.000000e+000,2.274734e-001,0.000000e+000,3,8.792953e-001,1.825000e+000,,,,,,,,,,,,,,,,,,0,4.000000e+000,1.000000e+000,20,1,4.860229e-001,0,1,0,
1438307285.203,,9.999999e+002,2.907314e+002,-3.329859e-006,0.000000e+000,2.338462e-001,0.000000e+000,3,8.741378e-001,1.825000e+000,,,,,,,,,,,,,,,,,,0,4.000000e+000,1.000000e+000,20,1,4.870911e-001,0,0,0,
1438307432.250,,9.999999e+002,2.876449e+002,-3.245941e-006,0.000000e+000,2.404573e-001,0.000000e+000,3,8.710973e-001,1.825000e+000,,,,,,,,,,,,,,,,,,0,4.000000e+000,1.000000e+000,20,1,5.983887e-001,0,1,0,
1438307568.547,,9.999999e+002,2.847280e+002,-3.235978e-006,0.000000e+000,2.468910e-001,0.000000e+000,3,8.720010e-001,1.825000e+000,,,,,,,,,,,,,,,,,,0,4.000000e+000,1.000000e+000,20,1,4.557190e-001,0,1,0,
1438307776.547,,9.999999e+002,2.818026e+002,-3.203920e-006,0.000000e+000,2.544161e-001,0.000000e+000,3,8.679788e-001,1.825000e+000,,,,,,,,,,,,,,,,,,0,4.000000e+000,1.000000e+000,20,1,3.505249e-001,0,1,0,
1438307997.593,,9.999999e+002,2.787569e+002,-3.133739e-006,0.000000e+000,2.601056e-001,0.000000e+000,3,8.660389e-001,1.825000e+000,,,,,,,,,,,,,,,,,,0,4.000000e+000,1.000000e+000,20,1,3.842163e-001,0,1,0,
1438308195.547,,9.999999e+002,2.757584e+002,-3.126085e-006,0.000000e+000,2.623931e-001,0.000000e+000,3,8.589450e-001,1.825000e+000,,,,,,,,,,,,,,,,,,0,4.000000e+000,1.000000e+000,20,1,3.959961e-001,0,1,0,
1438308384.343,,9.999999e+002,2.727120e+002,-3.076055e-006,0.000000e+000,2.790696e-001,0.000000e+000,3,8.616357e-001,1.825000e+000,,,,,,,,,,,,,,,,,,0,4.000000e+000,1.000000e+000,20,1,4.562988e-001,0,0,0,
1438308544.406,,9.999999e+002,2.695605e+002,-3.025325e-006,0.000000e+000,2.745492e-001,0.000000e+000,3,8.535756e-001,1.825000e+000,,,,,,,,,,,,,,,,,,0,4.000000e+000,1.000000e+000,20,1,5.520020e-001,0,1,0,
1438308680.672,,9.999999e+002,2.666589e+002,-2.990990e-006,0.000000e+000,2.806014e-001,0.000000e+000,3,8.558675e-001,1.825000e+000,,,,,,,,,,,,,,,,,,0,4.000000e+000,1.000000e+000,20,1,4.450073e-001,0,1,0,
1438308872.672,,9.999999e+002,2.637940e+002,-2.977997e-006,0.000000e+000,2.894838e-001,0.000000e+000,3,8.621439e-001,1.825000e+000,,,,,,,,,,,,,,,,,,0,4.000000e+000,1.000000e+000,20,1,3.240051e-001,0,1,0,
1438309098.687,,9.999999e+002,2.607560e+002,-2.969050e-006,0.000000e+000,2.984731e-001,0.000000e+000,3,8.527306e-001,1.825000e+000,,,,,,,,,,,,,,,,,,0,4.000000e+000,1.000000e+000,20,1,3.887024e-001,0,1,0,
1438309294.515,,9.999999e+002,2.577755e+002,-2.949710e-006,0.000000e+000,2.968388e-001,0.000000e+000,3,8.488498e-001,1.825000e+000,,,,,,,,,,,,,,,,,,0,4.000000e+000,1.000000e+000,20,1,4.241028e-001,0,1,0,
1438309489.062,,9.999999e+002,2.547495e+002,-2.938064e-006,0.000000e+000,2.985297e-001,0.000000e+000,3,8.584903e-001,1.825000e+000,,,,,,,,,,,,,,,,,,0,4.000000e+000,1.000000e+000,20,1,4.229126e-001,0,0,0,
1438309660.062,,9.999999e+002,2.516039e+002,-2.893644e-006,0.000000e+000,3.097526e-001,0.000000e+000,3,8.527156e-001,1.825000e+000,,,,,,,,,,,,,,,,,,0,4.000000e+000,1.000000e+000,20,1,4.631042e-001,0,0,0,
1438309797.000,,9.999999e+002,2.486908e+002,-2.867237e-006,0.000000e+000,3.139365e-001,0.000000e+000,3,8.569226e-001,1.825000e+000,,,,,,,,,,,,,,,,,,0,4.000000e+000,1.000000e+000,20,1,5.511932e-001,0,1,0,
1438309964.781,,9.999999e+002,2.457796e+002,-2.865550e-006,0.000000e+000,3.129415e-001,0.000000e+000,3,8.540680e-001,1.825000e+000,,,,,,,,,,,,,,,,,,0,4.000000e+000,1.000000e+000,20,1,3.616028e-001,0,1,0,
1438310192.812,,9.999999e+002,2.427240e+002,-2.807225e-006,0.000000e+000,3.282967e-001,0.000000e+000,3,8.448418e-001,1.825000e+000,,,,,,,,,,,,,,,,,,0,4.000000e+000,1.000000e+000,20,1,3.840027e-001,0,1,0,
1438310397.750,,9.999999e+002,2.397585e+002,-2.752474e-006,0.000000e+000,3.388040e-001,0.000000e+000,3,8.362606e-001,1.825000e+000,,,,,,,,,,,,,,,,,,0,4.000000e+000,1.000000e+000,20,1,4.207001e-001,0,1,0,
1438310582.593,,9.999999e+002,2.366707e+002,-2.715368e-006,0.000000e+000,3.451982e-001,0.000000e+000,3,8.390151e-001,1.825000e+000,,,,,,,,,,,,,,,,,,0,4.000000e+000,1.000000e+000,20,1,5.440979e-001,0,0,0,
1438310727.812,,9.999999e+002,2.335851e+002,-2.661052e-006,0.000000e+000,3.579430e-001,0.000000e+000,3,8.317833e-001,1.825000e+000,,,,,,,,,,,,,,,,,,0,4.000000e+000,1.000000e+000,20,1,6.242981e-001,0,1,0,
1438310876.531,,9.999999e+002,2.307310e+002,-2.652743e-006,0.000000e+000,3.698590e-001,0.000000e+000,3,8.280693e-001,1.825000e+000,,,,,,,,,,,,,,,,,,0,4.000000e+000,1.000000e+000,20,1,4.676056e-001,0,1,0,
1438311095.547,,9.999999e+002,2.277712e+002,-2.621226e-006,0.000000e+000,3.793130e-001,0.000000e+000,3,8.292758e-001,1.825000e+000,,,,,,,,,,,,,,,,,,0,4.000000e+000,1.000000e+000,20,1,3.730927e-001,0,1,0,
1438311311.343,,9.999999e+002,2.247838e+002,-2.575497e-006,0.000000e+000,3.935350e-001,0.000000e+000,3,8.169896e-001,1.825000e+000,,,,,,,,,,,,,,,,,,0,4.000000e+000,1.000000e+000,20,1,3.905029e-001,0,1,0,
1438311513.312,,9.999999e+002,2.216226e+002,-2.517156e-006,0.000000e+000,4.044325e-001,0.000000e+000,3,8.088321e-001,1.825000e+000,,,,,,,,,,,,,,,,,,0,4.000000e+000,1.000000e+000,20,1,4.061127e-001,0,0,0,
1438311679.000,,9.999999e+002,2.186173e+002,-2.497460e-006,0.000000e+000,4.123954e-001,0.000000e+000,3,8.100654e-001,1.825000e+000,,,,,,,,,,,,,,,,,,0,4.000000e+000,1.000000e+000,20,1,5.229034e-001,0,0,0,
1438311819.484,,9.999999e+002,2.156657e+002,-2.462866e-006,0.000000e+000,4.231519e-001,0.000000e+000,3,8.093641e-001,1.825000e+000,,,,,,,,,,,,,,,,,,0,4.000000e+000,1.000000e+000,20,1,4.967957e-001,0,1,0,
1438311993.609,,9.999999e+002,2.128059e+002,-2.404445e-006,0.000000e+000,4.335586e-001,0.000000e+000,3,8.023950e-001,1.825000e+000,,,,,,,,,,,,,,,,,,0,4.000000e+000,1.000000e+000,20,1,3.328094e-001,0,1,0,
1438312215.250,,9.999999e+002,2.097809e+002,-2.398783e-006,0.000000e+000,4.459919e-001,0.000000e+000,3,7.948877e-001,1.825000e+000,,,,,,,,,,,,,,,,,,0,4.000000e+000,1.000000e+000,20,1,3.470917e-001,0,1,0,
1438312424.609,,9.999999e+002,2.067388e+002,-2.397131e-006,0.000000e+000,4.688421e-001,0.000000e+000,3,7.908281e-001,1.825000e+000,,,,,,,,,,,,,,,,,,0,4.000000e+000,1.000000e+000,20,1,3.659973e-001,0,1,0,
1438312610.093,,9.999999e+002,2.036985e+002,-2.329692e-006,0.000000e+000,4.781168e-001,0.000000e+000,3,7.841281e-001,1.825000e+000,,,,,,,,,,,,,,,,,,0,4.000000e+000,1.000000e+000,20,1,4.279022e-001,0,0,0,
1438312756.843,,9.999999e+002,2.006884e+002,-2.283704e-006,0.000000e+000,4.903234e-001,0.000000e+000,3,7.745580e-001,1.825000e+000,,,,,,,,,,,,,,,,,,0,4.000000e+000,1.000000e+000,20,1,5.724945e-001,0,1,0,
1438312910.547,,9.999999e+002,1.977300e+002,-2.263554e-006,0.000000e+000,5.077724e-001,0.000000e+000,3,7.682526e-001,1.825000e+000,,,,,,,,,,,,,,,,,,0,4.000000e+000,1.000000e+000,20,1,4.463043e-001,0,1,0,
1438313126.093,,9.999999e+002,1.948003e+002,-2.249667e-006,0.000000e+000,5.246605e-001,0.000000e+000,3,7.690271e-001,1.825000e+000,,,,,,,,,,,,,,,,,,0,4.000000e+000,1.000000e+000,20,1,3.419037e-001,0,1,0,
1438313336.703,,9.999999e+002,1.917988e+002,-2.224795e-006,0.000000e+000,5.357493e-001,0.000000e+000,3,7.604061e-001,1.825000e+000,,,,,,,,,,,,,,,,,,0,4.000000e+000,1.000000e+000,20,1,4.013062e-001,0,1,0,
1438313522.718,,9.999999e+002,1.886992e+002,-2.192551e-006,0.000000e+000,5.565745e-001,0.000000e+000,3,7.490733e-001,1.825000e+000,,,,,,,,,,,,,,,,,,0,4.000000e+000,1.000000e+000,20,1,5.762939e-001,0,0,0,
1438313667.468,,9.999999e+002,1.857076e+002,-2.168971e-006,0.000000e+000,5.710228e-001,0.000000e+000,3,7.382721e-001,1.825000e+000,,,,,,,,,,,,,,,,,,0,4.000000e+000,1.000000e+000,20,1,5.543060e-001,0,1,0,
1438313836.687,,9.999999e+002,1.827595e+002,-2.146592e-006,0.000000e+000,5.903725e-001,0.000000e+000,3,7.390239e-001,1.825000e+000,,,,,,,,,,,,,,,,,,0,4.000000e+000,1.000000e+000,20,1,3.889923e-001,0,1,0,
1438314050.437,,9.999999e+002,1.797809e+002,-2.145603e-006,0.000000e+000,6.130279e-001,0.000000e+000,3,7.254971e-001,1.825000e+000,,,,,,,,,,,,,,,,,,0,4.000000e+000,1.000000e+000,20,1,3.722992e-001,0,1,0,
1438314262.093,,9.999999e+002,1.767574e+002,-2.113011e-006,0.000000e+000,6.247568e-001,0.000000e+000,3,7.209609e-001,1.825000e+000,,,,,,,,,,,,,,,,,,0,4.000000e+000,1.000000e+000,20,1,4.326935e-001,0,0,0,
1438314440.937,,9.999999e+002,1.736152e+002,-2.092904e-006,0.000000e+000,6.440997e-001,0.000000e+000,3,7.062486e-001,1.825000e+000,,,,,,,,,,,,,,,,,,0,4.000000e+000,1.000000e+000,20,1,4.552002e-001,0,0,0,
1438314581.718,,9.999999e+002,1.707277e+002,-2.075474e-006,0.000000e+000,6.596941e-001,0.000000e+000,3,7.031761e-001,1.825000e+000,,,,,,,,,,,,,,,,,,0,4.000000e+000,1.000000e+000,20,1,5.164032e-001,0,1,0,
1438314750.828,,9.999999e+002,1.677390e+002,-2.067113e-006,0.000000e+000,6.805661e-001,0.000000e+000,3,6.978277e-001,1.825000e+000,,,,,,,,,,,,,,,,,,0,4.000000e+000,1.000000e+000,20,1,3.842010e-001,0,1,0,
1438314959.812,,9.999999e+002,1.648217e+002,-2.076927e-006,0.000000e+000,6.964541e-001,0.000000e+000,3,6.869972e-001,1.825000e+000,,,,,,,,,,,,,,,,,,0,4.000000e+000,1.000000e+000,20,1,3.493042e-001,0,1,0,
1438315174.953,,9.999999e+002,1.617561e+002,-2.044773e-006,0.000000e+000,7.132294e-001,0.000000e+000,3,6.737483e-001,1.825000e+000,,,,,,,,,,,,,,,,,,0,4.000000e+000,1.000000e+000,20,1,3.908997e-001,0,0,0,
1438315351.734,,9.999999e+002,1.587198e+002,-2.076584e-006,0.000000e+000,7.279156e-001,0.000000e+000,3,6.807531e-001,1.825000e+000,,,,,,,,,,,,,,,,,,0,4.000000e+000,1.000000e+000,20,1,5.195007e-001,0,0,0,
1438315495.859,,9.999999e+002,1.557256e+002,-2.050244e-006,0.000000e+000,7.467560e-001,0.000000e+000,3,6.609781e-001,1.825000e+000,,,,,,,,,,,,,,,,,,0,4.000000e+000,1.000000e+000,20,1,4.880981e-001,0,1,0,
1438315668.812,,9.999999e+002,1.527619e+002,-2.044811e-006,0.000000e+000,7.681978e-001,0.000000e+000,3,6.580675e-001,1.825000e+000,,,,,,,,,,,,,,,,,,0,4.000000e+000,1.000000e+000,20,1,3.774109e-001,0,1,0,
1438315881.218,,9.999999e+002,1.497657e+002,-2.024597e-006,0.000000e+000,7.764170e-001,0.000000e+000,3,6.429068e-001,1.825000e+000,,,,,,,,,,,,,,,,,,0,4.000000e+000,1.000000e+000,20,1,3.825073e-001,0,1,0,
1438316087.234,,9.999999e+002,1.467328e+002,-2.053487e-006,0.000000e+000,7.963778e-001,0.000000e+000,3,6.444890e-001,1.825000e+000,,,,,,,,,,,,,,,,,,0,4.000000e+000,1.000000e+000,20,1,3.683014e-001,0,0,0,
1438316264.703,,9.999999e+002,1.436950e+002,-2.039508e-006,0.000000e+000,8.031526e-001,0.000000e+000,3,6.392351e-001,1.825000e+000,,,,,,,,,,,,,,,,,,0,4.000000e+000,1.000000e+000,20,1,5.012054e-001,0,0,0,
1438316412.453,,9.999999e+002,1.406902e+002,-2.038828e-006,0.000000e+000,8.205501e-001,0.000000e+000,3,6.327906e-001,1.825000e+000,,,,,,,,,,,,,,,,,,0,4.000000e+000,1.000000e+000,20,1,5.377045e-001,0,1,0,
1438316582.109,,9.999999e+002,1.377328e+002,-2.045730e-006,0.000000e+000,8.275560e-001,0.000000e+000,3,6.314937e-001,1.825000e+000,,,,,,,,,,,,,,,,,,0,4.000000e+000,1.000000e+000,20,1,3.973999e-001,0,1,0,
1438316790.484,,9.999999e+002,1.347266e+002,-2.059224e-006,0.000000e+000,8.506486e-001,0.000000e+000,3,6.270782e-001,1.825000e+000,,,,,,,,,,,,,,,,,,0,4.000000e+000,1.000000e+000,20,1,3.282013e-001,0,1,0,
1438316992.406,,9.999999e+002,1.317860e+002,-2.050870e-006,0.000000e+000,8.565173e-001,0.000000e+000,3,6.155021e-001,1.825000e+000,,,,,,,,,,,,,,,,,,0,4.000000e+000,1.000000e+000,20,1,4.237976e-001,0,0,0,
1438317171.672,,9.999999e+002,1.286040e+002,-2.037277e-006,0.000000e+000,8.623894e-001,0.000000e+000,3,6.090739e-001,1.825000e+000,,,,,,,,,,,,,,,,,,0,4.000000e+000,1.000000e+000,20,1,5.425110e-001,0,0,0,
1438317315.390,,9.999999e+002,1.256755e+002,-3.153067e-007,0.000000e+000,0.000000e+000,0.000000e+000,3,0.000000e+000,1.825000e+000,,,,,,,,,,,,,,,,,,0,4.000000e+000,1.000000e+000,20,1,4.479980e-001,0,1,0,
1438317492.375,,9.999999e+002,1.227800e+002,-2.042598e-006,0.000000e+000,8.585709e-001,0.000000e+000,3,6.071337e-001,1.825000e+000,,,,,,,,,,,,,,,,,,0,4.000000e+000,1.000000e+000,20,1,3.990021e-001,0,1,0,
1438317703.312,,9.999999e+002,1.198165e+002,-2.051808e-006,0.000000e+000,8.623029e-001,0.000000e+000,3,6.146390e-001,1.825000e+000,,,,,,,,,,,,,,,,,,0,4.000000e+000,1.000000e+000,20,1,3.360977e-001,0,1,0,
1438317899.078,,9.999999e+002,1.167090e+002,-2.023302e-006,0.000000e+000,8.613215e-001,0.000000e+000,3,6.109455e-001,1.825000e+000,,,,,,,,,,,,,,,,,,0,4.000000e+000,1.000000e+000,20,1,4.787064e-001,0,0,0,
1438318055.047,,9.999999e+002,1.136348e+002,-2.017755e-006,0.000000e+000,8.541197e-001,0.000000e+000,3,6.148921e-001,1.825000e+000,,,,,,,,,,,,,,,,,,0,4.000000e+000,1.000000e+000,20,1,5.920029e-001,0,1,0,
1438318215.734,,9.999999e+002,1.106373e+002,-2.028899e-006,0.000000e+000,8.308300e-001,0.000000e+000,3,6.281706e-001,1.825000e+000,,,,,,,,,,,,,,,,,,0,4.000000e+000,1.000000e+000,20,1,3.554993e-001,0,1,0,
1438318413.406,,9.999999e+002,1.077775e+002,-2.030197e-006,0.000000e+000,8.111317e-001,0.000000e+000,3,6.348831e-001,1.825000e+000,,,,,,,,,,,,,,,,,,0,4.000000e+000,1.000000e+000,20,1,3.971939e-001,0,1,0,
1438318622.297,,9.999999e+002,1.047399e+002,-2.033600e-006,0.000000e+000,7.893645e-001,0.000000e+000,3,6.398425e-001,1.825000e+000,,,,,,,,,,,,,,,,,,0,4.000000e+000,1.000000e+000,20,1,3.478012e-001,0,0,0,
1438318794.250,,9.999999e+002,1.016542e+002,-2.036232e-006,0.000000e+000,7.580205e-001,0.000000e+000,3,6.631221e-001,1.825000e+000,,,,,,,,,,,,,,,,,,0,4.000000e+000,1.000000e+000,20,1,4.372025e-001,0,0,0,
1438318945.484,,9.999999e+002,9.869802e+001,-2.043538e-006,0.000000e+000,7.112142e-001,0.000000e+000,3,6.909350e-001,1.825000e+000,,,,,,,,,,,,,,,,,,0,4.000000e+000,1.000000e+000,20,1,4.668579e-001,0,1,0,
1438319131.328,,9.999999e+002,9.573534e+001,-2.067055e-006,0.000000e+000,6.634316e-001,0.000000e+000,3,7.020091e-001,1.825000e+000,,,,,,,,,,,,,,,,,,0,4.000000e+000,1.000000e+000,20,1,3.973999e-001,0,1,0,
1438324285.672,,9.999999e+002,2.022554e+002,-2.337684e-006,0.000000e+000,-1.630109e-002,0.000000e+000,3,8.327355e-001,1.825000e+000,,,,,,,,,,,,,,,,,,0,4.000000e+000,1.000000e+000,20,1,5.043945e-001,0,1,0,
1438324443.500,,9.999999e+002,2.053026e+002,-2.391536e-006,0.000000e+000,-3.405825e-002,0.000000e+000,3,8.341182e-001,1.825000e+000,,,,,,,,,,,,,,,,,,0,4.000000e+000,1.000000e+000,20,1,4.062042e-001,0,1,0,
1438324622.968,,9.999999e+002,2.082592e+002,-2.434557e-006,0.000000e+000,-3.598176e-002,0.000000e+000,3,8.375967e-001,1.825000e+000,,,,,,,,,,,,,,,,,,0,4.000000e+000,1.000000e+000,20,1,4.291992e-001,0,0,0,
1438324809.703,,9.999999e+002,2.112918e+002,-2.471867e-006,0.000000e+000,-5.094949e-002,0.000000e+000,3,8.442361e-001,1.825000e+000,,,,,,,,,,,,,,,,,,0,4.000000e+000,1.000000e+000,20,1,3.759003e-001,0,0,0,
1438324998.172,,9.999999e+002,2.142863e+002,-2.525001e-006,0.000000e+000,-6.217796e-002,0.000000e+000,3,8.495517e-001,1.825000e+000,,,,,,,,,,,,,,,,,,0,4.000000e+000,1.000000e+000,20,1,4.231873e-001,0,0,0,
1438325171.609,,9.999999e+002,2.172261e+002,-2.540759e-006,0.000000e+000,-7.137097e-002,0.000000e+000,3,8.501052e-001,1.825000e+000,,,,,,,,,,,,,,,,,,0,4.000000e+000,1.000000e+000,20,1,4.472046e-001,0,1,0,
1438325353.062,,9.999999e+002,2.202198e+002,-2.585638e-006,0.000000e+000,-7.801287e-002,0.000000e+000,3,8.490897e-001,1.825000e+000,,,,,,,,,,,,,,,,,,0,4.000000e+000,1.000000e+000,20,1,4.333954e-001,0,1,0,
1438325537.484,,9.999999e+002,2.232321e+002,-2.583603e-006,0.000000e+000,-8.561803e-002,0.000000e+000,3,8.484299e-001,1.825000e+000,,,,,,,,,,,,,,,,,,0,4.000000e+000,1.000000e+000,20,1,4.384003e-001,0,1,0,
1438325723.593,,9.999999e+002,2.263293e+002,-2.684492e-006,0.000000e+000,-9.465525e-002,0.000000e+000,3,8.646382e-001,1.825000e+000,,,,,,,,,,,,,,,,,,0,4.000000e+000,1.000000e+000,20,1,4.367981e-001,0,0,0,
1438325901.781,,9.999999e+002,2.292418e+002,-2.706693e-006,0.000000e+000,-1.041371e-001,0.000000e+000,3,8.646041e-001,1.825000e+000,,,,,,,,,,,,,,,,,,0,4.000000e+000,1.000000e+000,20,1,4.408112e-001,0,0,0,
1438326087.953,,9.999999e+002,2.322391e+002,-2.764717e-006,0.000000e+000,-1.097246e-001,0.000000e+000,3,8.685758e-001,1.825000e+000,,,,,,,,,,,,,,,,,,0,4.000000e+000,1.000000e+000,20,1,4.377899e-001,0,0,0,
1438326273.422,,9.999999e+002,2.353257e+002,-2.797773e-006,0.000000e+000,-1.224990e-001,0.000000e+000,3,8.729626e-001,1.825000e+000,,,,,,,,,,,,,,,,,,0,4.000000e+000,1.000000e+000,20,1,4.862976e-001,0,1,0,
1438326448.406,,9.999999e+002,2.383027e+002,-2.784152e-006,0.000000e+000,-1.302826e-001,0.000000e+000,3,8.586679e-001,1.825000e+000,,,,,,,,,,,,,,,,,,0,4.000000e+000,1.000000e+000,20,1,4.533081e-001,0,1,0,
1438326629.812,,9.999999e+002,2.412863e+002,-2.876545e-006,0.000000e+000,-1.374305e-001,0.000000e+000,3,8.686520e-001,1.825000e+000,,,,,,,,,,,,,,,,,,0,4.000000e+000,1.000000e+000,20,1,3.717957e-001,0,1,0,
1438326820.047,,9.999999e+002,2.443455e+002,-2.909699e-006,0.000000e+000,-1.415758e-001,0.000000e+000,3,8.764976e-001,1.825000e+000,,,,,,,,,,,,,,,,,,0,4.000000e+000,1.000000e+000,20,1,4.129944e-001,0,0,0,
1438327006.172,,9.999999e+002,2.472348e+002,-2.933653e-006,0.000000e+000,-1.486930e-001,0.000000e+000,3,8.779010e-001,1.825000e+000,,,,,,,,,,,,,,,,,,0,4.000000e+000,1.000000e+000,20,1,3.984985e-001,0,0,0,
1438327185.859,,9.999999e+002,2.503137e+002,-2.978520e-006,0.000000e+000,-1.559338e-001,0.000000e+000,3,8.810164e-001,1.825000e+000,,,,,,,,,,,,,,,,,,0,4.000000e+000,1.000000e+000,20,1,4.416962e-001,0,0,0,
1438327371.078,,9.999999e+002,2.532906e+002,-3.016033e-006,0.000000e+000,-1.638888e-001,0.000000e+000,3,8.751623e-001,1.825000e+000,,,,,,,,,,,,,,,,,,0,4.000000e+000,1.000000e+000,20,1,4.693146e-001,0,1,0,
1438327557.031,,9.999999e+002,2.562383e+002,-3.074539e-006,0.000000e+000,-1.698732e-001,0.000000e+000,3,8.698547e-001,1.825000e+000,,,,,,,,,,,,,,,,,,0,4.000000e+000,1.000000e+000,20,1,4.191284e-001,0,1,0,
1438327682.781,,9.999999e+002,2.582623e+002,-3.049804e-006,0.000000e+000,-1.790695e-001,0.000000e+000,3,8.557059e-001,1.825000e+000,,,,,,,,,,,,,,,,,,0,4.000000e+000,1.000000e+000,20,1,4.257813e-001,0,0,0,