File: !!!Рисунки/Магнитная восприимчивость/Cu3SbS3_206_4_m_68_45_T_2K_m_H_rso.dat
[Header]
TITLE,MPMS RSO Measurement
BYAPP,MPMS Measurement,1.1,Summary
FILEOPENTIME, 1438425046.406000 8/1/2015, 3:30:46 PM

INFO, APPNAME, MPMS MultiVu Application, Revision 1.58,  Build 076

INFO, NAME, Unnamed
INFO, WEIGHT, 1.000
INFO, AREA, 1.000
INFO, LENGTH, 1.000
INFO, SHAPE, 0
INFO, COMMENT,
INFO, SEQUENCE FILE: m(T).seq


INFO, BACKGROUND DATA FILE:, None


STARTUPAXIS,X,4,LINEAR,AUTO,0.000000,0.000000
STARTUPAXIS,Y1,5,LINEAR,AUTO,0.000000,0.000000


STARTUPGROUP,Longitudinal
FIELDGROUP,Longitudinal,1,2,3,4,5,6,7,8,9,10,11,19,20,21,22,23,35
FIELDGROUP,Transverse,1,2,3,4,12,13,14,15,16,17,18,24,25,26,27,28,35

PLOT_APPEARANCE,ALL,HORZ_GRID_ON,VERT_GRID_ON,MARKERS_AND_LINES

[Data]
Time,Comment,Field (Oe),Temperature (K),Long Moment (emu),Long Scan Std Dev,Long Offset (cm),Long Offset Std Dev,Long Algorithm,Long Reg Fit,Long Reg Factor,Trans Moment (emu),Trans Scan Std Dev,Trans Offset (cm),Trans Offset Std Dev,Trans Algorithm,Trans Reg Fit,Trans Reg Factor,Long Moment [w/o ABS] (emu),Long Scan Std Dev [w/o ABS],Long Offset [w/o ABS] (cm),Long Offset Std Dev [w/o ABS],Long Reg Fit [w/o ABS],Trans Moment [w/o ABS] (emu),Trans Scan Std Dev [w/o ABS],Trans Offset [w/o ABS] (cm),Trans Offset Std Dev [w/o ABS],Trans Reg Fit [w/o ABS],RSO Position (deg),Amplitude (cm),Frequency,Cycles to Average,Scans per Measurement,Delta Temp (K),Error,EC Comp. Running,Using ABS,
1438425046.406,,7.000000e+004,2.002041e+000,-1.251335e-004,0.000000e+000,-3.406757e-003,0.000000e+000,3,6.448285e-001,1.825000e+000,,,,,,,,,,,,,,,,,,0,4.000000e+000,1.000000e+000,20,1,9.703636e-005,0,1,0,
1438425241.593,,6.627490e+004,1.998468e+000,-8.264175e-005,0.000000e+000,-2.293207e-002,0.000000e+000,3,9.251729e-001,1.825000e+000,,,,,,,,,,,,,,,,,,0,4.000000e+000,1.000000e+000,20,1,4.804134e-005,0,1,0,
1438425420.265,,6.225837e+004,2.000698e+000,-3.213627e-005,0.000000e+000,-4.816171e-002,0.000000e+000,3,7.902966e-001,1.825000e+000,,,,,,,,,,,,,,,,,,0,4.000000e+000,1.000000e+000,20,1,4.670620e-004,0,1,0,
1438425515.906,,5.823899e+004,2.000191e+000,1.366928e-005,0.000000e+000,1.286308e-001,0.000000e+000,3,6.246262e-001,1.825000e+000,,,,,,,,,,,,,,,,,,0,4.000000e+000,1.000000e+000,20,1,8.029938e-004,0,1,0,
1438425610.765,,5.422388e+004,1.999838e+000,5.821862e-005,0.000000e+000,2.986578e-002,0.000000e+000,3,9.047923e-001,1.825000e+000,,,,,,,,,,,,,,,,,,0,4.000000e+000,1.000000e+000,20,1,7.699728e-004,0,1,0,
1438425738.265,,5.020592e+004,2.000681e+000,9.829772e-005,0.000000e+000,1.609743e-002,0.000000e+000,3,9.344193e-001,1.825000e+000,,,,,,,,,,,,,,,,,,0,4.000000e+000,1.000000e+000,20,1,3.700256e-004,0,1,0,
1438425829.640,,4.618796e+004,2.000521e+000,1.379571e-004,0.000000e+000,8.328821e-003,0.000000e+000,3,9.586595e-001,1.825000e+000,,,,,,,,,,,,,,,,,,0,4.000000e+000,1.000000e+000,20,1,1.108050e-003,0,0,0,
1438425982.062,,4.216928e+004,2.000753e+000,1.736799e-004,0.000000e+000,1.009300e-002,0.000000e+000,3,9.644339e-001,1.825000e+000,,,,,,,,,,,,,,,,,,0,4.000000e+000,1.000000e+000,20,1,6.110668e-004,0,0,0,
1438426073.703,,3.815060e+004,1.999862e+000,2.074669e-004,0.000000e+000,-3.877287e-003,0.000000e+000,3,9.738460e-001,1.825000e+000,,,,,,,,,,,,,,,,,,0,4.000000e+000,1.000000e+000,20,1,7.219315e-004,0,1,0,
1438426191.656,,3.413479e+004,1.999533e+000,2.316670e-004,0.000000e+000,4.590625e-003,0.000000e+000,3,9.671965e-001,1.825000e+000,,,,,,,,,,,,,,,,,,0,4.000000e+000,1.000000e+000,20,1,1.929998e-004,0,1,0,
1438426335.312,,3.011754e+004,1.999614e+000,2.509613e-004,0.000000e+000,-6.802925e-004,0.000000e+000,3,9.741016e-001,1.825000e+000,,,,,,,,,,,,,,,,,,0,4.000000e+000,1.000000e+000,20,1,8.978844e-004,0,1,0,
1438426428.718,,2.610316e+004,1.999887e+000,2.637756e-004,0.000000e+000,-2.981984e-003,0.000000e+000,3,9.735830e-001,1.825000e+000,,,,,,,,,,,,,,,,,,0,4.000000e+000,1.000000e+000,20,1,1.186967e-003,0,1,0,
1438426566.109,,2.209021e+004,2.000320e+000,2.691390e-004,0.000000e+000,-1.892978e-004,0.000000e+000,3,9.829240e-001,1.825000e+000,,,,,,,,,,,,,,,,,,0,4.000000e+000,1.000000e+000,20,1,8.349419e-004,0,0,0,
1438426770.781,,1.957827e+004,2.002484e+000,2.657446e-004,0.000000e+000,-1.686532e-003,0.000000e+000,3,9.803542e-001,1.825000e+000,,,,,,,,,,,,,,,,,,0,4.000000e+000,1.000000e+000,20,1,2.739429e-004,0,0,0,
1438426849.109,,1.857592e+004,2.001245e+000,2.619510e-004,0.000000e+000,1.052890e-003,0.000000e+000,3,9.729313e-001,1.825000e+000,,,,,,,,,,,,,,,,,,0,4.000000e+000,1.000000e+000,20,1,2.088547e-004,0,1,0,
1438426954.515,,1.757214e+004,1.999341e+000,2.591498e-004,0.000000e+000,1.271424e-003,0.000000e+000,3,9.804522e-001,1.825000e+000,,,,,,,,,,,,,,,,,,0,4.000000e+000,1.000000e+000,20,1,2.560616e-004,0,1,0,
1438427033.203,,1.656808e+004,1.998020e+000,2.561073e-004,0.000000e+000,1.104461e-003,0.000000e+000,3,9.742814e-001,1.825000e+000,,,,,,,,,,,,,,,,,,0,4.000000e+000,1.000000e+000,20,1,7.520914e-004,0,1,0,
1438427231.218,,1.556445e+004,2.000898e+000,2.507565e-004,0.000000e+000,-3.097203e-004,0.000000e+000,3,9.752989e-001,1.825000e+000,,,,,,,,,,,,,,,,,,0,4.000000e+000,1.000000e+000,20,1,1.289845e-004,0,1,0,
1438427308.062,,1.456053e+004,1.999702e+000,2.463885e-004,0.000000e+000,-3.931487e-003,0.000000e+000,3,9.832235e-001,1.825000e+000,,,,,,,,,,,,,,,,,,0,4.000000e+000,1.000000e+000,20,1,4.980564e-004,0,1,0,
1438427386.422,,1.355547e+004,1.999854e+000,2.379654e-004,0.000000e+000,-1.999404e-003,0.000000e+000,3,9.784939e-001,1.825000e+000,,,,,,,,,,,,,,,,,,0,4.000000e+000,1.000000e+000,20,1,9.629726e-004,0,0,0,
1438427535.718,,1.255298e+004,2.001670e+000,2.300782e-004,0.000000e+000,-2.443313e-003,0.000000e+000,3,9.824798e-001,1.825000e+000,,,,,,,,,,,,,,,,,,0,4.000000e+000,1.000000e+000,20,1,9.703636e-005,0,0,0,
1438427611.828,,1.154907e+004,2.000432e+000,2.206169e-004,0.000000e+000,-5.340606e-003,0.000000e+000,3,9.747083e-001,1.825000e+000,,,,,,,,,,,,,,,,,,0,4.000000e+000,1.000000e+000,20,1,5.459785e-004,0,0,0,
1438427711.234,,1.054658e+004,2.000223e+000,2.113166e-004,0.000000e+000,-2.789714e-003,0.000000e+000,3,9.806347e-001,1.825000e+000,,,,,,,,,,,,,,,,,,0,4.000000e+000,1.000000e+000,20,1,3.194809e-005,0,1,0,
1438427849.609,,9.543233e+003,1.999004e+000,1.990555e-004,0.000000e+000,-1.587607e-003,0.000000e+000,3,9.666080e-001,1.825000e+000,,,,,,,,,,,,,,,,,,0,4.000000e+000,1.000000e+000,20,1,1.919270e-004,0,1,0,
1438427976.312,,8.538741e+003,2.000320e+000,1.857220e-004,0.000000e+000,-3.948871e-003,0.000000e+000,3,9.730072e-001,1.825000e+000,,,,,,,,,,,,,,,,,,0,4.000000e+000,1.000000e+000,20,1,4.179478e-004,0,1,0,
1438428140.281,,7.536540e+003,2.000416e+000,1.711750e-004,0.000000e+000,-6.618707e-003,0.000000e+000,3,9.813263e-001,1.825000e+000,,,,,,,,,,,,,,,,,,0,4.000000e+000,1.000000e+000,20,1,0.000000e+000,0,1,0,
1438428317.875,,6.530905e+003,2.001655e+000,1.562450e-004,0.000000e+000,-1.247454e-002,0.000000e+000,3,9.796500e-001,1.825000e+000,,,,,,,,,,,,,,,,,,0,4.000000e+000,1.000000e+000,20,1,9.703636e-005,0,0,0,
1438428509.750,,5.526988e+003,2.000264e+000,1.371057e-004,0.000000e+000,-9.390531e-003,0.000000e+000,3,9.758772e-001,1.825000e+000,,,,,,,,,,,,,,,,,,0,4.000000e+000,1.000000e+000,20,1,3.049374e-004,0,1,0,
1438428640.797,,4.524214e+003,1.998476e+000,1.183157e-004,0.000000e+000,-1.132617e-002,0.000000e+000,3,9.795067e-001,1.825000e+000,,,,,,,,,,,,,,,,,,0,4.000000e+000,1.000000e+000,20,1,5.439520e-004,0,1,0,
1438428840.609,,3.519866e+003,2.000698e+000,9.813165e-005,0.000000e+000,-1.852619e-002,0.000000e+000,3,9.727898e-001,1.825000e+000,,,,,,,,,,,,,,,,,,0,4.000000e+000,1.000000e+000,20,1,1.502037e-005,0,1,0,
1438428992.187,,2.515805e+003,2.000409e+000,7.631921e-005,0.000000e+000,-2.557796e-002,0.000000e+000,3,9.825758e-001,1.825000e+000,,,,,,,,,,,,,,,,,,0,4.000000e+000,1.000000e+000,20,1,2.410412e-004,0,0,0,
1438429218.437,,1.963335e+003,2.002041e+000,6.286897e-005,0.000000e+000,-3.292155e-002,0.000000e+000,3,9.706468e-001,1.825000e+000,,,,,,,,,,,,,,,,,,0,4.000000e+000,1.000000e+000,20,1,4.508495e-004,0,0,0,
1438429355.281,,1.862314e+003,2.000464e+000,6.070495e-005,0.000000e+000,-2.932252e-002,0.000000e+000,3,9.504046e-001,1.825000e+000,,,,,,,,,,,,,,,,,,0,4.000000e+000,1.000000e+000,20,1,6.430149e-004,0,1,0,
1438429473.812,,1.762724e+003,1.997820e+000,5.849407e-005,0.000000e+000,-3.157396e-002,0.000000e+000,3,9.802912e-001,1.825000e+000,,,,,,,,,,,,,,,,,,0,4.000000e+000,1.000000e+000,20,1,4.479885e-004,0,1,0,
1438429571.953,,1.662703e+003,1.999373e+000,5.626954e-005,0.000000e+000,-3.480000e-002,0.000000e+000,3,9.677960e-001,1.825000e+000,,,,,,,,,,,,,,,,,,0,4.000000e+000,1.000000e+000,20,1,8.019209e-004,0,1,0,
1438429644.031,,1.562255e+003,2.000384e+000,5.363837e-005,0.000000e+000,-3.722058e-002,0.000000e+000,3,9.676654e-001,1.825000e+000,,,,,,,,,,,,,,,,,,0,4.000000e+000,1.000000e+000,20,1,9.319782e-004,0,1,0,
1438429715.125,,1.461662e+003,2.000609e+000,5.109020e-005,0.000000e+000,-4.070664e-002,0.000000e+000,3,9.736708e-001,1.825000e+000,,,,,,,,,,,,,,,,,,0,4.000000e+000,1.000000e+000,20,1,4.818439e-004,0,1,0,
1438429849.453,,1.362072e+003,2.000721e+000,4.844912e-005,0.000000e+000,-3.926752e-002,0.000000e+000,3,9.685989e-001,1.825000e+000,,,,,,,,,,,,,,,,,,0,4.000000e+000,1.000000e+000,20,1,1.609325e-004,0,0,0,
1438430026.453,,1.261479e+003,2.000793e+000,4.586195e-005,0.000000e+000,-4.356649e-002,0.000000e+000,3,9.775606e-001,1.825000e+000,,,,,,,,,,,,,,,,,,0,4.000000e+000,1.000000e+000,20,1,1.449585e-004,0,0,0,
1438430124.656,,1.160745e+003,2.000593e+000,4.358666e-005,0.000000e+000,-5.027986e-002,0.000000e+000,3,9.817978e-001,1.825000e+000,,,,,,,,,,,,,,,,,,0,4.000000e+000,1.000000e+000,20,1,3.194809e-005,0,1,0,
1438430243.312,,1.060725e+003,1.999445e+000,4.095126e-005,0.000000e+000,-4.366332e-002,0.000000e+000,3,9.612722e-001,1.825000e+000,,,,,,,,,,,,,,,,,,0,4.000000e+000,1.000000e+000,20,1,1.440048e-004,0,1,0,
1438430373.047,,9.597029e+002,1.999012e+000,3.838965e-005,0.000000e+000,-5.615623e-002,0.000000e+000,3,9.730132e-001,1.825000e+000,,,,,,,,,,,,,,,,,,0,4.000000e+000,1.000000e+000,20,1,8.169413e-004,0,1,0,
1438430445.156,,8.585388e+002,1.999694e+000,3.585253e-005,0.000000e+000,-4.975672e-002,0.000000e+000,3,9.660100e-001,1.825000e+000,,,,,,,,,,,,,,,,,,0,4.000000e+000,1.000000e+000,20,1,9.939671e-004,0,1,0,
1438430568.812,,7.583760e+002,1.999902e+000,3.247441e-005,0.000000e+000,-5.844809e-002,0.000000e+000,3,9.725894e-001,1.825000e+000,,,,,,,,,,,,,,,,,,0,4.000000e+000,1.000000e+000,20,1,1.059055e-003,0,1,0,
1438430733.703,,6.576407e+002,2.001308e+000,2.975167e-005,0.000000e+000,-6.268374e-002,0.000000e+000,3,9.746073e-001,1.825000e+000,,,,,,,,,,,,,,,,,,0,4.000000e+000,1.000000e+000,20,1,1.769066e-004,0,0,0,
1438430847.125,,5.579071e+002,2.000504e+000,2.675612e-005,0.000000e+000,-7.501248e-002,0.000000e+000,3,9.716417e-001,1.825000e+000,,,,,,,,,,,,,,,,,,0,4.000000e+000,1.000000e+000,20,1,4.911423e-005,0,0,0,
1438430980.343,,4.583166e+002,2.000232e+000,2.332390e-005,0.000000e+000,-5.070183e-002,0.000000e+000,3,8.513815e-001,1.825000e+000,,,,,,,,,,,,,,,,,,0,4.000000e+000,1.000000e+000,20,1,2.732277e-004,0,1,0,
1438431096.953,,3.594416e+002,1.998652e+000,1.886924e-005,0.000000e+000,-2.638011e-002,0.000000e+000,3,6.944693e-001,1.825000e+000,,,,,,,,,,,,,,,,,,0,4.000000e+000,1.000000e+000,20,1,2.560616e-004,0,1,0,
1438431383.406,,2.579909e+002,2.000232e+000,1.680116e-005,0.000000e+000,-8.669839e-002,0.000000e+000,3,9.570559e-001,1.825000e+000,,,,,,,,,,,,,,,,,,0,4.000000e+000,1.000000e+000,20,1,4.911423e-005,0,1,0,
1438431534.703,,1.555387e+002,2.000818e+000,1.324832e-005,0.000000e+000,-1.065331e-001,0.000000e+000,3,9.506074e-001,1.825000e+000,,,,,,,,,,,,,,,,,,0,4.000000e+000,1.000000e+000,20,1,1.940727e-004,0,0,0,
1438431649.828,,5.423103e+001,2.001188e+000,8.941371e-006,0.000000e+000,-1.224858e-001,0.000000e+000,3,9.654055e-001,1.825000e+000,,,,,,,,,,,,,,,,,,0,4.000000e+000,1.000000e+000,20,1,9.584427e-005,0,0,0,
1438431729.937,,-5.322940e+001,2.000328e+000,5.353977e-006,0.000000e+000,1.743998e-001,0.000000e+000,3,1.265095e-001,1.825000e+000,,,,,,,,,,,,,,,,,,0,4.000000e+000,1.000000e+000,20,1,5.939007e-004,0,1,0,
1438431858.781,,-1.566834e+002,1.999445e+000,3.324776e-006,0.000000e+000,1.251589e+000,0.000000e+000,3,0.000000e+000,1.825000e+000,,,,,,,,,,,,,,,,,,0,4.000000e+000,1.000000e+000,20,1,1.440048e-004,0,1,0,
1438432011.437,,-2.571324e+002,1.999348e+000,-4.411010e-006,0.000000e+000,3.439864e-001,0.000000e+000,3,1.953315e-001,1.825000e+000,,,,,,,,,,,,,,,,,,0,4.000000e+000,1.000000e+000,20,1,4.969835e-004,0,1,0,
1438432085.781,,-3.572952e+002,1.999742e+000,-8.538565e-006,0.000000e+000,-2.042965e-001,0.000000e+000,3,2.992401e-001,1.825000e+000,,,,,,,,,,,,,,,,,,0,4.000000e+000,1.000000e+000,20,1,9.938478e-004,0,1,0,
1438432158.375,,-4.560272e+002,2.000313e+000,-1.156511e-005,0.000000e+000,7.345705e-002,0.000000e+000,3,4.445302e-001,1.825000e+000,,,,,,,,,,,,,,,,,,0,4.000000e+000,1.000000e+000,20,1,7.549524e-004,0,1,0,
1438432229.500,,-5.570486e+002,2.000432e+000,-1.482817e-005,0.000000e+000,-2.595958e-002,0.000000e+000,3,9.018242e-001,1.825000e+000,,,,,,,,,,,,,,,,,,0,4.000000e+000,1.000000e+000,20,1,6.752014e-004,0,0,0,
1438432299.640,,-6.566391e+002,2.000520e+000,-1.731712e-005,0.000000e+000,-2.247622e-002,0.000000e+000,3,9.289563e-001,1.825000e+000,,,,,,,,,,,,,,,,,,0,4.000000e+000,1.000000e+000,20,1,7.228851e-004,0,0,0,
1438432415.797,,-7.566590e+002,2.000713e+000,-2.022850e-005,0.000000e+000,-1.068639e-002,0.000000e+000,3,9.406015e-001,1.825000e+000,,,,,,,,,,,,,,,,,,0,4.000000e+000,1.000000e+000,20,1,3.368855e-004,0,0,0,
1438432544.922,,-8.575373e+002,2.000971e+000,-2.375898e-005,0.000000e+000,-1.787282e-002,0.000000e+000,3,9.387744e-001,1.825000e+000,,,,,,,,,,,,,,,,,,0,4.000000e+000,1.000000e+000,20,1,7.987022e-005,0,1,0,
1438432641.078,,-9.591309e+002,2.000015e+000,-2.642360e-005,0.000000e+000,-1.836625e-002,0.000000e+000,3,8.879817e-001,1.825000e+000,,,,,,,,,,,,,,,,,,0,4.000000e+000,1.000000e+000,20,1,1.931190e-004,0,1,0,
1438432748.890,,-1.060725e+003,1.998972e+000,-2.908493e-005,0.000000e+000,-9.686173e-003,0.000000e+000,3,9.193820e-001,1.825000e+000,,,,,,,,,,,,,,,,,,0,4.000000e+000,1.000000e+000,20,1,1.279116e-004,0,1,0,
1438432847.343,,-1.159600e+003,1.999293e+000,-2.983057e-005,0.000000e+000,-3.705633e-002,0.000000e+000,3,9.150469e-001,1.825000e+000,,,,,,,,,,,,,,,,,,0,4.000000e+000,1.000000e+000,20,1,7.699728e-004,0,1,0,
1438432918.718,,-1.260764e+003,1.999966e+000,-3.436535e-005,0.000000e+000,-7.761830e-003,0.000000e+000,3,9.357784e-001,1.825000e+000,,,,,,,,,,,,,,,,,,0,4.000000e+000,1.000000e+000,20,1,7.389784e-004,0,1,0,
1438432991.843,,-1.360498e+003,2.000167e+000,-3.727797e-005,0.000000e+000,-1.810711e-002,0.000000e+000,3,9.731468e-001,1.825000e+000,,,,,,,,,,,,,,,,,,0,4.000000e+000,1.000000e+000,20,1,5.940199e-004,0,1,0,
1438433064.937,,-1.461662e+003,2.000167e+000,-3.923309e-005,0.000000e+000,-1.563506e-002,0.000000e+000,3,9.426445e-001,1.825000e+000,,,,,,,,,,,,,,,,,,0,4.000000e+000,1.000000e+000,20,1,6.259680e-004,0,0,0,
1438433218.734,,-1.561539e+003,2.000922e+000,-4.144178e-005,0.000000e+000,8.842823e-003,0.000000e+000,3,9.335057e-001,1.825000e+000,,,,,,,,,,,,,,,,,,0,4.000000e+000,1.000000e+000,20,1,4.911423e-005,0,0,0,
1438433292.328,,-1.661988e+003,2.000328e+000,-4.519166e-005,0.000000e+000,-1.617506e-002,0.000000e+000,3,9.689220e-001,1.825000e+000,,,,,,,,,,,,,,,,,,0,4.000000e+000,1.000000e+000,20,1,6.260872e-004,0,0,0,
1438433399.031,,-1.761292e+003,2.000520e+000,-4.879915e-005,0.000000e+000,-3.036332e-002,0.000000e+000,3,9.524105e-001,1.825000e+000,,,,,,,,,,,,,,,,,,0,4.000000e+000,1.000000e+000,20,1,6.270409e-004,0,1,0,
1438433580.234,,-1.862886e+003,1.998868e+000,-4.952215e-005,0.000000e+000,-1.148671e-002,0.000000e+000,3,9.275422e-001,1.825000e+000,,,,,,,,,,,,,,,,,,0,4.000000e+000,1.000000e+000,20,1,1.120567e-004,0,1,0,
1438433652.593,,-1.963621e+003,1.998524e+000,-5.090062e-005,0.000000e+000,-1.670632e-002,0.000000e+000,3,9.520136e-001,1.825000e+000,,,,,,,,,,,,,,,,,,0,4.000000e+000,1.000000e+000,20,1,9.599924e-004,0,1,0,
1438433859.625,,-3.017478e+003,2.001808e+000,-7.641154e-005,0.000000e+000,-3.494908e-003,0.000000e+000,3,9.754531e-001,1.825000e+000,,,,,,,,,,,,,,,,,,0,4.000000e+000,1.000000e+000,20,1,2.410412e-004,0,1,0,
1438434025.875,,-4.023542e+003,2.000593e+000,-9.776623e-005,0.000000e+000,-1.776898e-003,0.000000e+000,3,9.784080e-001,1.825000e+000,,,,,,,,,,,,,,,,,,0,4.000000e+000,1.000000e+000,20,1,9.608269e-005,0,0,0,
1438434324.078,,-5.028748e+003,1.999910e+000,-1.175158e-004,0.000000e+000,1.451286e-003,0.000000e+000,3,9.758932e-001,1.825000e+000,,,,,,,,,,,,,,,,,,0,4.000000e+000,1.000000e+000,20,1,2.729893e-004,0,1,0,
1438434512.484,,-6.033525e+003,1.999670e+000,-1.356706e-004,0.000000e+000,3.842452e-004,0.000000e+000,3,9.793750e-001,1.825000e+000,,,,,,,,,,,,,,,,,,0,4.000000e+000,1.000000e+000,20,1,4.009008e-004,0,1,0,
1438434589.843,,-7.036298e+003,1.999894e+000,-1.540183e-004,0.000000e+000,2.091390e-003,0.000000e+000,3,9.837884e-001,1.825000e+000,,,,,,,,,,,,,,,,,,0,4.000000e+000,1.000000e+000,20,1,9.149313e-004,0,1,0,
1438434750.890,,-8.038929e+003,2.000625e+000,-1.691258e-004,0.000000e+000,3.968366e-003,0.000000e+000,3,9.811411e-001,1.825000e+000,,,,,,,,,,,,,,,,,,0,4.000000e+000,1.000000e+000,20,1,6.413460e-005,0,1,0,
1438434859.281,,-9.042131e+003,2.000240e+000,-1.835704e-004,0.000000e+000,4.736796e-003,0.000000e+000,3,9.823847e-001,1.825000e+000,,,,,,,,,,,,,,,,,,0,4.000000e+000,1.000000e+000,20,1,6.740093e-004,0,0,0,
1438434935.937,,-1.004547e+004,2.000473e+000,-1.958568e-004,0.000000e+000,5.477256e-003,0.000000e+000,3,9.813777e-001,1.825000e+000,,,,,,,,,,,,,,,,,,0,4.000000e+000,1.000000e+000,20,1,8.509159e-004,0,0,0,
1438435192.375,,-1.105082e+004,1.999406e+000,-2.066747e-004,0.000000e+000,7.175324e-003,0.000000e+000,3,9.796607e-001,1.825000e+000,,,,,,,,,,,,,,,,,,0,4.000000e+000,1.000000e+000,20,1,3.209114e-004,0,1,0,
1438435301.047,,-1.205475e+004,1.998780e+000,-2.169212e-004,0.000000e+000,5.784308e-003,0.000000e+000,3,9.772183e-001,1.825000e+000,,,,,,,,,,,,,,,,,,0,4.000000e+000,1.000000e+000,20,1,4.160404e-004,0,1,0,
1438435377.390,,-1.305666e+004,1.999509e+000,-2.256557e-004,0.000000e+000,5.042331e-003,0.000000e+000,3,9.813000e-001,1.825000e+000,,,,,,,,,,,,,,,,,,0,4.000000e+000,1.000000e+000,20,1,1.170874e-003,0,1,0,
1438435450.781,,-1.406086e+004,2.000320e+000,-2.337963e-004,0.000000e+000,6.273803e-003,0.000000e+000,3,9.803611e-001,1.825000e+000,,,,,,,,,,,,,,,,,,0,4.000000e+000,1.000000e+000,20,1,7.699728e-004,0,1,0,
1438435582.953,,-1.506392e+004,2.000681e+000,-2.395627e-004,0.000000e+000,6.422221e-003,0.000000e+000,3,9.793214e-001,1.825000e+000,,,,,,,,,,,,,,,,,,0,4.000000e+000,1.000000e+000,20,1,1.692772e-005,0,1,0,
1438435766.797,,-1.606956e+004,2.000785e+000,-2.454204e-004,0.000000e+000,5.783635e-003,0.000000e+000,3,9.800638e-001,1.825000e+000,,,,,,,,,,,,,,,,,,0,4.000000e+000,1.000000e+000,20,1,1.609325e-004,0,0,0,
1438436020.250,,-1.707133e+004,1.999974e+000,-2.504560e-004,0.000000e+000,6.775334e-003,0.000000e+000,3,9.795192e-001,1.825000e+000,,,,,,,,,,,,,,,,,,0,4.000000e+000,1.000000e+000,20,1,5.289316e-004,0,1,0,
1438436156.265,,-1.807653e+004,1.998820e+000,-2.530984e-004,0.000000e+000,6.659759e-003,0.000000e+000,3,9.781105e-001,1.825000e+000,,,,,,,,,,,,,,,,,,0,4.000000e+000,1.000000e+000,20,1,3.999472e-004,0,1,0,
1438436321.172,,-1.908031e+004,2.000785e+000,-2.575865e-004,0.000000e+000,6.399824e-003,0.000000e+000,3,9.796059e-001,1.825000e+000,,,,,,,,,,,,,,,,,,0,4.000000e+000,1.000000e+000,20,1,1.609325e-004,0,1,0,
1438436509.562,,-2.008266e+004,2.000649e+000,-2.593102e-004,0.000000e+000,6.618083e-003,0.000000e+000,3,9.810409e-001,1.825000e+000,,,,,,,,,,,,,,,,,,0,4.000000e+000,1.000000e+000,20,1,2.090931e-004,0,0,0,
1438436708.375,,-2.409275e+004,2.001510e+000,-2.601400e-004,0.000000e+000,1.805948e-002,0.000000e+000,3,9.552827e-001,1.825000e+000,,,,,,,,,,,,,,,,,,0,4.000000e+000,1.000000e+000,20,1,9.019375e-004,0,0,0,
1438436932.468,,-2.810999e+004,1.998732e+000,-2.558672e-004,0.000000e+000,7.238396e-003,0.000000e+000,3,9.805593e-001,1.825000e+000,,,,,,,,,,,,,,,,,,0,4.000000e+000,1.000000e+000,20,1,2.880096e-004,0,1,0,
1438437104.797,,-3.212509e+004,2.000520e+000,-2.412926e-004,0.000000e+000,7.004611e-003,0.000000e+000,3,9.758183e-001,1.825000e+000,,,,,,,,,,,,,,,,,,0,4.000000e+000,1.000000e+000,20,1,4.010201e-004,0,1,0,
1438437226.812,,-3.614091e+004,2.000151e+000,-2.186316e-004,0.000000e+000,-1.055166e-002,0.000000e+000,3,9.254835e-001,1.825000e+000,,,,,,,,,,,,,,,,,,0,4.000000e+000,1.000000e+000,20,1,6.898642e-004,0,1,0,
1438437402.953,,-4.015815e+004,2.000922e+000,-1.879446e-004,0.000000e+000,8.149014e-003,0.000000e+000,3,9.709747e-001,1.825000e+000,,,,,,,,,,,,,,,,,,0,4.000000e+000,1.000000e+000,20,1,1.769066e-004,0,0,0,
1438437531.625,,-4.417611e+004,2.000441e+000,-1.580440e-004,0.000000e+000,1.487860e-002,0.000000e+000,3,9.327167e-001,1.825000e+000,,,,,,,,,,,,,,,,,,0,4.000000e+000,1.000000e+000,20,1,8.828640e-004,0,0,0,
1438437736.765,,-4.819409e+004,1.998604e+000,-1.179623e-004,0.000000e+000,1.428959e-002,0.000000e+000,3,9.467364e-001,1.825000e+000,,,,,,,,,,,,,,,,,,0,4.000000e+000,1.000000e+000,20,1,3.839731e-004,0,1,0,
1438437868.672,,-5.220918e+004,1.999774e+000,-7.568170e-005,0.000000e+000,2.173254e-002,0.000000e+000,3,9.103179e-001,1.825000e+000,,,,,,,,,,,,,,,,,,0,4.000000e+000,1.000000e+000,20,1,6.098747e-004,0,1,0,
1438438103.265,,-5.622714e+004,2.000368e+000,-3.135002e-005,0.000000e+000,-7.918953e-003,0.000000e+000,3,7.097249e-001,1.825000e+000,,,,,,,,,,,,,,,,,,0,4.000000e+000,1.000000e+000,20,1,2.238750e-004,0,1,0,
1438438302.297,,-6.024367e+004,2.001132e+000,9.682357e-006,0.000000e+000,-3.127158e-001,0.000000e+000,3,3.002749e-001,1.825000e+000,,,,,,,,,,,,,,,,,,0,4.000000e+000,1.000000e+000,20,1,3.061295e-004,0,0,0,
1438438459.125,,-6.426163e+004,2.001333e+000,6.170448e-005,0.000000e+000,-2.293549e-002,0.000000e+000,3,7.721294e-001,1.825000e+000,,,,,,,,,,,,,,,,,,0,4.000000e+000,1.000000e+000,20,1,6.484985e-005,0,1,0,
1438438648.875,,-6.828102e+004,1.998836e+000,1.092315e-004,0.000000e+000,-2.875130e-002,0.000000e+000,3,9.387535e-001,1.825000e+000,,,,,,,,,,,,,,,,,,0,4.000000e+000,1.000000e+000,20,1,4.804134e-005,0,1,0,
1438438841.828,,-6.827244e+004,2.001559e+000,1.069127e-004,0.000000e+000,-1.483980e-002,0.000000e+000,3,9.619290e-001,1.825000e+000,,,,,,,,,,,,,,,,,,0,4.000000e+000,1.000000e+000,20,1,7.729530e-004,0,1,0,
1438439046.125,,-6.425304e+004,1.999565e+000,5.820923e-005,0.000000e+000,-2.430874e-002,0.000000e+000,3,9.050500e-001,1.825000e+000,,,,,,,,,,,,,,,,,,0,4.000000e+000,1.000000e+000,20,1,1.289845e-004,0,1,0,
1438439138.750,,-6.023509e+004,1.999045e+000,1.113303e-005,0.000000e+000,-3.366553e-001,0.000000e+000,3,3.764720e-001,1.825000e+000,,,,,,,,,,,,,,,,,,0,4.000000e+000,1.000000e+000,20,1,1.330018e-003,0,0,0,
1438439232.093,,-5.621999e+004,2.000866e+000,-3.454793e-005,0.000000e+000,5.010503e-002,0.000000e+000,3,7.948058e-001,1.825000e+000,,,,,,,,,,,,,,,,,,0,4.000000e+000,1.000000e+000,20,1,1.286983e-003,0,0,0,
1438439383.593,,-5.219916e+004,2.001879e+000,-7.769823e-005,0.000000e+000,2.883817e-002,0.000000e+000,3,9.071665e-001,1.825000e+000,,,,,,,,,,,,,,,,,,0,4.000000e+000,1.000000e+000,20,1,1.931190e-004,0,0,0,
1438439476.437,,-4.818406e+004,1.999686e+000,-1.194253e-004,0.000000e+000,1.434481e-002,0.000000e+000,3,9.568567e-001,1.825000e+000,,,,,,,,,,,,,,,,,,0,4.000000e+000,1.000000e+000,20,1,4.650354e-004,0,1,0,
1438439595.109,,-4.416467e+004,1.998476e+000,-1.549980e-004,0.000000e+000,1.185639e-002,0.000000e+000,3,9.598132e-001,1.825000e+000,,,,,,,,,,,,,,,,,,0,4.000000e+000,1.000000e+000,20,1,7.040501e-004,0,1,0,
1438439723.765,,-4.014957e+004,1.999614e+000,-1.914828e-004,0.000000e+000,1.312739e-002,0.000000e+000,3,9.690486e-001,1.825000e+000,,,,,,,,,,,,,,,,,,0,4.000000e+000,1.000000e+000,20,1,9.940863e-004,0,1,0,
1438439814.922,,-3.613304e+004,2.000360e+000,-2.211926e-004,0.000000e+000,3.597300e-003,0.000000e+000,3,9.743564e-001,1.825000e+000,,,,,,,,,,,,,,,,,,0,4.000000e+000,1.000000e+000,20,1,9.479523e-004,0,1,0,
1438440020.781,,-3.211794e+004,2.000256e+000,-2.420556e-004,0.000000e+000,3.898309e-004,0.000000e+000,3,9.768293e-001,1.825000e+000,,,,,,,,,,,,,,,,,,0,4.000000e+000,1.000000e+000,20,1,1.928806e-004,0,0,0,
1438440161.515,,-2.810070e+004,2.000352e+000,-2.593777e-004,0.000000e+000,3.019422e-003,0.000000e+000,3,9.774792e-001,1.825000e+000,,,,,,,,,,,,,,,,,,0,4.000000e+000,1.000000e+000,20,1,9.319782e-004,0,0,0,
1438440322.531,,-2.408487e+004,2.001357e+000,-2.683116e-004,0.000000e+000,-2.133471e-003,0.000000e+000,3,9.827611e-001,1.825000e+000,,,,,,,,,,,,,,,,,,0,4.000000e+000,1.000000e+000,20,1,2.100468e-004,0,1,0,
1438440442.156,,-2.007263e+004,1.998356e+000,-2.667047e-004,0.000000e+000,7.973964e-004,0.000000e+000,3,9.760399e-001,1.825000e+000,,,,,,,,,,,,,,,,,,0,4.000000e+000,1.000000e+000,20,1,5.919933e-004,0,1,0,
1438440604.765,,-1.907673e+004,2.000489e+000,-2.645717e-004,0.000000e+000,-1.058989e-003,0.000000e+000,3,9.806568e-001,1.825000e+000,,,,,,,,,,,,,,,,,,0,4.000000e+000,1.000000e+000,20,1,1.398087e-003,0,1,0,
1438440683.172,,-1.807296e+004,2.001414e+000,-2.621627e-004,0.000000e+000,5.515739e-004,0.000000e+000,3,9.790270e-001,1.825000e+000,,,,,,,,,,,,,,,,,,0,4.000000e+000,1.000000e+000,20,1,5.149841e-004,0,1,0,
1438440809.343,,-1.706847e+004,2.000062e+000,-2.588973e-004,0.000000e+000,-1.165148e-003,0.000000e+000,3,9.791131e-001,1.825000e+000,,,,,,,,,,,,,,,,,,0,4.000000e+000,1.000000e+000,20,1,3.528595e-004,0,0,0,
1438440885.203,,-1.606612e+004,1.999582e+000,-2.543393e-004,0.000000e+000,-3.579203e-003,0.000000e+000,3,9.827429e-001,1.825000e+000,,,,,,,,,,,,,,,,,,0,4.000000e+000,1.000000e+000,20,1,7.060766e-004,0,0,0,
1438440962.797,,-1.506192e+004,2.000063e+000,-2.483905e-004,0.000000e+000,1.736846e-003,0.000000e+000,3,9.736087e-001,1.825000e+000,,,,,,,,,,,,,,,,,,0,4.000000e+000,1.000000e+000,20,1,9.320974e-004,0,0,0,
1438441143.265,,-1.405800e+004,2.000754e+000,-2.411694e-004,0.000000e+000,-3.376537e-003,0.000000e+000,3,9.828502e-001,1.825000e+000,,,,,,,,,,,,,,,,,,0,4.000000e+000,1.000000e+000,20,1,4.498959e-004,0,1,0,
1438441303.234,,-1.305437e+004,1.998068e+000,-2.347088e-004,0.000000e+000,-2.948789e-003,0.000000e+000,3,9.805328e-001,1.825000e+000,,,,,,,,,,,,,,,,,,0,4.000000e+000,1.000000e+000,20,1,7.200241e-004,0,1,0,
1438441476.609,,-1.205103e+004,2.000770e+000,-2.251930e-004,0.000000e+000,-1.272173e-003,0.000000e+000,3,9.800348e-001,1.825000e+000,,,,,,,,,,,,,,,,,,0,4.000000e+000,1.000000e+000,20,1,2.567768e-004,0,1,0,
1438441627.687,,-1.104768e+004,2.000520e+000,-2.163990e-004,0.000000e+000,-2.536973e-003,0.000000e+000,3,9.768850e-001,1.825000e+000,,,,,,,,,,,,,,,,,,0,4.000000e+000,1.000000e+000,20,1,1.449585e-004,0,0,0,
1438441895.218,,-1.004233e+004,2.000898e+000,-2.040574e-004,0.000000e+000,-4.191272e-003,0.000000e+000,3,9.819101e-001,1.825000e+000,,,,,,,,,,,,,,,,,,0,4.000000e+000,1.000000e+000,20,1,6.508827e-005,0,0,0,
1438442063.484,,-9.040127e+003,1.999076e+000,-1.924100e-004,0.000000e+000,-3.991916e-003,0.000000e+000,3,9.813815e-001,1.825000e+000,,,,,,,,,,,,,,,,,,0,4.000000e+000,1.000000e+000,20,1,8.106232e-005,0,1,0,
1438442164.625,,-8.036354e+003,1.998765e+000,-1.783088e-004,0.000000e+000,-6.475664e-003,0.000000e+000,3,9.777604e-001,1.825000e+000,,,,,,,,,,,,,,,,,,0,4.000000e+000,1.000000e+000,20,1,8.969307e-004,0,1,0,
1438442322.812,,-7.032864e+003,2.000681e+000,-1.628103e-004,0.000000e+000,-7.617177e-003,0.000000e+000,3,9.820563e-001,1.825000e+000,,,,,,,,,,,,,,,,,,0,4.000000e+000,1.000000e+000,20,1,7.987022e-005,0,1,0,
1438442496.093,,-6.028374e+003,2.000561e+000,-1.458810e-004,0.000000e+000,-7.750688e-003,0.000000e+000,3,9.799374e-001,1.825000e+000,,,,,,,,,,,,,,,,,,0,4.000000e+000,1.000000e+000,20,1,1.931190e-004,0,0,0,
1438442749.125,,-5.025886e+003,2.000874e+000,-1.278236e-004,0.000000e+000,-1.005195e-002,0.000000e+000,3,9.798099e-001,1.825000e+000,,,,,,,,,,,,,,,,,,0,4.000000e+000,1.000000e+000,20,1,1.597404e-005,0,0,0,
1438442967.781,,-4.021253e+003,1.998988e+000,-1.085597e-004,0.000000e+000,-1.477176e-002,0.000000e+000,3,9.791695e-001,1.825000e+000,,,,,,,,,,,,,,,,,,0,4.000000e+000,1.000000e+000,20,1,3.194809e-005,0,1,0,
1438443075.343,,-3.015618e+003,1.999309e+000,-8.594133e-005,0.000000e+000,-1.981751e-002,0.000000e+000,3,9.711006e-001,1.825000e+000,,,,,,,,,,,,,,,,,,0,4.000000e+000,1.000000e+000,20,1,9.299517e-004,0,1,0,
1438443153.187,,-2.011700e+003,2.000063e+000,-6.456691e-005,0.000000e+000,-4.322891e-002,0.000000e+000,3,9.493514e-001,1.825000e+000,,,,,,,,,,,,,,,,,,0,4.000000e+000,1.000000e+000,20,1,8.659363e-004,0,1,0,
1438443333.422,,-1.911966e+003,2.001647e+000,-6.180389e-005,0.000000e+000,-2.415073e-002,0.000000e+000,3,9.606326e-001,1.825000e+000,,,,,,,,,,,,,,,,,,0,4.000000e+000,1.000000e+000,20,1,7.569790e-004,0,0,0,
1438443447.203,,-1.812375e+003,2.000625e+000,-5.935676e-005,0.000000e+000,-3.154458e-002,0.000000e+000,3,9.694912e-001,1.825000e+000,,,,,,,,,,,,,,,,,,0,4.000000e+000,1.000000e+000,20,1,2.582073e-004,0,0,0,
1438443611.968,,-1.712785e+003,2.000561e+000,-5.736053e-005,0.000000e+000,-3.278622e-002,0.000000e+000,3,9.433371e-001,1.825000e+000,,,,,,,,,,,,,,,,,,0,4.000000e+000,1.000000e+000,20,1,9.584427e-005,0,1,0,
1438443720.484,,-1.612908e+003,1.998828e+000,-5.676787e-005,0.000000e+000,-2.678390e-002,0.000000e+000,3,9.319338e-001,1.825000e+000,,,,,,,,,,,,,,,,,,0,4.000000e+000,1.000000e+000,20,1,4.159212e-004,0,1,0,
1438443854.437,,-1.511458e+003,1.999181e+000,-5.252246e-005,0.000000e+000,-3.461553e-002,0.000000e+000,3,9.540410e-001,1.825000e+000,,,,,,,,,,,,,,,,,,0,4.000000e+000,1.000000e+000,20,1,7.050037e-004,0,1,0,
1438443924.843,,-1.410579e+003,1.999798e+000,-4.937297e-005,0.000000e+000,-3.430933e-002,0.000000e+000,3,9.519356e-001,1.825000e+000,,,,,,,,,,,,,,,,,,0,4.000000e+000,1.000000e+000,20,1,8.499622e-004,0,1,0,
1438443999.187,,-1.309701e+003,2.000135e+000,-4.684330e-005,0.000000e+000,-4.254697e-002,0.000000e+000,3,9.800568e-001,1.825000e+000,,,,,,,,,,,,,,,,,,0,4.000000e+000,1.000000e+000,20,1,6.899834e-004,0,1,0,
1438444073.828,,-1.208823e+003,2.000095e+000,-4.964438e-005,0.000000e+000,-9.795932e-002,0.000000e+000,3,7.121866e-001,1.825000e+000,,,,,,,,,,,,,,,,,,0,4.000000e+000,1.000000e+000,20,1,6.740093e-004,0,1,0,
1438444147.734,,-1.109232e+003,2.000216e+000,-4.170619e-005,0.000000e+000,-4.564076e-002,0.000000e+000,3,9.738501e-001,1.825000e+000,,,,,,,,,,,,,,,,,,0,4.000000e+000,1.000000e+000,20,1,8.511543e-004,0,0,0,
1438444268.125,,-1.008784e+003,2.001179e+000,-3.943083e-005,0.000000e+000,-5.019016e-002,0.000000e+000,3,9.698505e-001,1.825000e+000,,,,,,,,,,,,,,,,,,0,4.000000e+000,1.000000e+000,20,1,1.130104e-004,0,0,0,
1438444341.218,,-9.077617e+002,2.000432e+000,-3.668776e-005,0.000000e+000,-5.341618e-002,0.000000e+000,3,9.715106e-001,1.825000e+000,,,,,,,,,,,,,,,,,,0,4.000000e+000,1.000000e+000,20,1,4.820824e-004,0,0,0,
1438444500.422,,-8.073127e+002,2.000706e+000,-3.365820e-005,0.000000e+000,-6.112118e-002,0.000000e+000,3,9.428411e-001,1.825000e+000,,,,,,,,,,,,,,,,,,0,4.000000e+000,1.000000e+000,20,1,1.289845e-004,0,1,0,
1438444615.922,,-7.072930e+002,1.999093e+000,-3.131363e-005,0.000000e+000,-6.072652e-002,0.000000e+000,3,9.756457e-001,1.825000e+000,,,,,,,,,,,,,,,,,,0,4.000000e+000,1.000000e+000,20,1,1.450777e-004,0,1,0,
1438444754.937,,-6.064146e+002,1.999245e+000,-2.835625e-005,0.000000e+000,-6.580369e-002,0.000000e+000,3,9.301450e-001,1.825000e+000,,,,,,,,,,,,,,,,,,0,4.000000e+000,1.000000e+000,20,1,8.660555e-004,0,1,0,
1438444901.406,,-5.076826e+002,2.000175e+000,-2.476447e-005,0.000000e+000,-5.882064e-002,0.000000e+000,3,9.507890e-001,1.825000e+000,,,,,,,,,,,,,,,,,,0,4.000000e+000,1.000000e+000,20,1,5.779266e-004,0,1,0,
1438444976.000,,-4.069474e+002,2.000063e+000,-2.186944e-005,0.000000e+000,-6.710768e-002,0.000000e+000,3,9.324371e-001,1.825000e+000,,,,,,,,,,,,,,,,,,0,4.000000e+000,1.000000e+000,20,1,6.740093e-004,0,0,0,
1438445091.906,,-3.060691e+002,2.001091e+000,-1.836685e-005,0.000000e+000,-8.004590e-002,0.000000e+000,3,9.589524e-001,1.825000e+000,,,,,,,,,,,,,,,,,,0,4.000000e+000,1.000000e+000,20,1,2.570152e-004,0,0,0,
1438445164.547,,-2.057631e+002,2.000633e+000,-1.549827e-005,0.000000e+000,-1.002638e-001,0.000000e+000,3,9.458631e-001,1.825000e+000,,,,,,,,,,,,,,,,,,0,4.000000e+000,1.000000e+000,20,1,5.631447e-004,0,0,0,
1438445281.109,,-1.048848e+002,2.000488e+000,-1.050613e-005,0.000000e+000,-1.054179e-001,0.000000e+000,3,7.890231e-001,1.825000e+000,,,,,,,,,,,,,,,,,,0,4.000000e+000,1.000000e+000,20,1,4.990101e-004,0,0,0,
1438445416.468,,-4.865055e+000,1.999862e+000,-6.541195e-006,0.000000e+000,-1.153170e-001,0.000000e+000,3,8.658176e-001,1.825000e+000,,,,,,,,,,,,,,,,,,0,4.000000e+000,1.000000e+000,20,1,1.770258e-004,0,1,0,
1438445593.484,,1.070312e+002,1.999717e+000,-2.271647e-006,0.000000e+000,-1.959432e-001,0.000000e+000,3,6.615163e-001,1.825000e+000,,,,,,,,,,,,,,,,,,0,4.000000e+000,1.000000e+000,20,1,2.410412e-004,0,1,0,
1438445863.937,,2.076233e+002,1.999878e+000,2.113389e-006,0.000000e+000,-3.404224e-001,0.000000e+000,3,0.000000e+000,1.825000e+000,,,,,,,,,,,,,,,,,,0,4.000000e+000,1.000000e+000,20,1,6.898642e-004,0,0,0,
1438446052.515,,3.080723e+002,2.001221e+000,5.777903e-006,0.000000e+000,2.764133e-002,0.000000e+000,3,8.646909e-001,1.825000e+000,,,,,,,,,,,,,,,,,,0,4.000000e+000,1.000000e+000,20,1,1.289845e-004,0,0,0,
1438446123.625,,4.089507e+002,2.000296e+000,1.032080e-005,0.000000e+000,1.074554e-002,0.000000e+000,3,7.856644e-001,1.825000e+000,,,,,,,,,,,,,,,,,,0,4.000000e+000,1.000000e+000,20,1,3.049374e-004,0,0,0,
1438446194.125,,5.098289e+002,1.999895e+000,1.322519e-005,0.000000e+000,2.870707e-002,0.000000e+000,3,8.286206e-001,1.825000e+000,,,,,,,,,,,,,,,,,,0,4.000000e+000,1.000000e+000,20,1,4.650354e-004,0,1,0,
1438446266.031,,6.089902e+002,1.999260e+000,1.598215e-005,0.000000e+000,-3.748121e-002,0.000000e+000,3,9.202010e-001,1.825000e+000,,,,,,,,,,,,,,,,,,0,4.000000e+000,1.000000e+000,20,1,4.490614e-004,0,1,0,
1438446395.125,,7.087239e+002,1.999429e+000,1.973239e-005,0.000000e+000,-3.672608e-002,0.000000e+000,3,7.071286e-001,1.825000e+000,,,,,,,,,,,,,,,,,,0,4.000000e+000,1.000000e+000,20,1,2.080202e-004,0,1,0,
1438446492.375,,8.086005e+002,1.999710e+000,2.285552e-005,0.000000e+000,-1.433368e-002,0.000000e+000,3,8.527550e-001,1.825000e+000,,,,,,,,,,,,,,,,,,0,4.000000e+000,1.000000e+000,20,1,8.341074e-004,0,1,0,
1438446590.703,,9.090494e+002,2.000144e+000,2.468202e-005,0.000000e+000,-3.524643e-002,0.000000e+000,3,8.697984e-001,1.825000e+000,,,,,,,,,,,,,,,,,,0,4.000000e+000,1.000000e+000,20,1,8.670092e-004,0,1,0,
1438446712.734,,1.010214e+003,2.000906e+000,2.801789e-005,0.000000e+000,-1.572629e-002,0.000000e+000,3,9.493457e-001,1.825000e+000,,,,,,,,,,,,,,,,,,0,4.000000e+000,1.000000e+000,20,1,2.410412e-004,0,0,0,
1438446818.937,,1.111379e+003,2.000424e+000,3.014410e-005,0.000000e+000,-1.518048e-002,0.000000e+000,3,9.422427e-001,1.825000e+000,,,,,,,,,,,,,,,,,,0,4.000000e+000,1.000000e+000,20,1,5.309582e-004,0,0,0,
1438446953.797,,1.211971e+003,2.000504e+000,3.377959e-005,0.000000e+000,-1.589831e-002,0.000000e+000,3,9.656153e-001,1.825000e+000,,,,,,,,,,,,,,,,,,0,4.000000e+000,1.000000e+000,20,1,4.010201e-004,0,0,0,
1438447084.047,,1.312849e+003,2.000256e+000,3.693728e-005,0.000000e+000,-3.165113e-002,0.000000e+000,3,8.988008e-001,1.825000e+000,,,,,,,,,,,,,,,,,,0,4.000000e+000,1.000000e+000,20,1,1.928806e-004,0,1,0,
1438447210.375,,1.413584e+003,1.999068e+000,3.860885e-005,0.000000e+000,1.059231e-003,0.000000e+000,3,9.126019e-001,1.825000e+000,,,,,,,,,,,,,,,,,,0,4.000000e+000,1.000000e+000,20,1,1.289845e-004,0,1,0,
1438447283.718,,1.513890e+003,1.998989e+000,4.150073e-005,0.000000e+000,-2.791078e-002,0.000000e+000,3,9.363506e-001,1.825000e+000,,,,,,,,,,,,,,,,,,0,4.000000e+000,1.000000e+000,20,1,8.330345e-004,0,1,0,
1438447355.843,,1.614339e+003,1.999918e+000,4.417937e-005,0.000000e+000,-2.251383e-002,0.000000e+000,3,9.775074e-001,1.825000e+000,,,,,,,,,,,,,,,,,,0,4.000000e+000,1.000000e+000,20,1,9.630919e-004,0,1,0,
1438447426.687,,1.714931e+003,2.000319e+000,4.610358e-005,0.000000e+000,-1.307938e-002,0.000000e+000,3,9.721116e-001,1.825000e+000,,,,,,,,,,,,,,,,,,0,4.000000e+000,1.000000e+000,20,1,8.029938e-004,0,1,0,
1438447498.593,,1.813806e+003,2.000376e+000,4.849251e-005,0.000000e+000,-1.242823e-002,0.000000e+000,3,9.732118e-001,1.825000e+000,,,,,,,,,,,,,,,,,,0,4.000000e+000,1.000000e+000,20,1,4.978180e-004,0,0,0,
1438447570.922,,1.913969e+003,2.000360e+000,5.088775e-005,0.000000e+000,-9.368916e-003,0.000000e+000,3,9.675740e-001,1.825000e+000,,,,,,,,,,,,,,,,,,0,4.000000e+000,1.000000e+000,20,1,7.549524e-004,0,0,0,
1438447641.765,,2.014847e+003,2.000537e+000,5.329987e-005,0.000000e+000,-1.041805e-002,0.000000e+000,3,9.723288e-001,1.825000e+000,,,,,,,,,,,,,,,,,,0,4.000000e+000,1.000000e+000,20,1,7.560253e-004,0,0,0,
1438447895.515,,3.018623e+003,2.001261e+000,7.617436e-005,0.000000e+000,2.164088e-003,0.000000e+000,3,9.648746e-001,1.825000e+000,,,,,,,,,,,,,,,,,,0,4.000000e+000,1.000000e+000,20,1,5.631447e-004,0,1,0,
1438448148.625,,4.024688e+003,1.999750e+000,9.772382e-005,0.000000e+000,1.514668e-003,0.000000e+000,3,9.761089e-001,1.825000e+000,,,,,,,,,,,,,,,,,,0,4.000000e+000,1.000000e+000,20,1,4.659891e-004,0,1,0,
1438448290.922,,5.027173e+003,2.000713e+000,1.178363e-004,0.000000e+000,1.564049e-003,0.000000e+000,3,9.791258e-001,1.825000e+000,,,,,,,,,,,,,,,,,,0,4.000000e+000,1.000000e+000,20,1,2.729893e-004,0,1,0,
1438448458.156,,6.031951e+003,2.000947e+000,1.363068e-004,0.000000e+000,1.866806e-003,0.000000e+000,3,9.816559e-001,1.825000e+000,,,,,,,,,,,,,,,,,,0,4.000000e+000,1.000000e+000,20,1,6.389618e-005,0,0,0,
1438448643.515,,7.036155e+003,2.000818e+000,1.530173e-004,0.000000e+000,3.399359e-003,0.000000e+000,3,9.796926e-001,1.825000e+000,,,,,,,,,,,,,,,,,,0,4.000000e+000,1.000000e+000,20,1,6.389618e-005,0,0,0,
1438448950.984,,8.040646e+003,1.999478e+000,1.691881e-004,0.000000e+000,3.537431e-003,0.000000e+000,3,9.796996e-001,1.825000e+000,,,,,,,,,,,,,,,,,,0,4.000000e+000,1.000000e+000,20,1,3.690720e-004,0,1,0,
1438449069.765,,9.043562e+003,2.000143e+000,1.831554e-004,0.000000e+000,6.201588e-003,0.000000e+000,3,9.815682e-001,1.825000e+000,,,,,,,,,,,,,,,,,,0,4.000000e+000,1.000000e+000,20,1,5.780458e-004,0,1,0,
1438449182.109,,1.004748e+004,2.000633e+000,1.959392e-004,0.000000e+000,5.356081e-003,0.000000e+000,3,9.814810e-001,1.825000e+000,,,,,,,,,,,,,,,,,,0,4.000000e+000,1.000000e+000,20,1,2.741814e-004,0,0,0,
1438449330.187,,1.105225e+004,2.000826e+000,2.067030e-004,0.000000e+000,6.798989e-003,0.000000e+000,3,9.793896e-001,1.825000e+000,,,,,,,,,,,,,,,,,,0,4.000000e+000,1.000000e+000,20,1,4.980564e-004,0,0,0,
1438449449.343,,1.205589e+004,2.001100e+000,2.168042e-004,0.000000e+000,5.286150e-003,0.000000e+000,3,9.815854e-001,1.825000e+000,,,,,,,,,,,,,,,,,,0,4.000000e+000,1.000000e+000,20,1,1.130104e-004,0,0,0,
1438449526.437,,1.305923e+004,2.000360e+000,2.229276e-004,0.000000e+000,1.096969e-002,0.000000e+000,3,9.462651e-001,1.825000e+000,,,,,,,,,,,,,,,,,,0,4.000000e+000,1.000000e+000,20,1,7.549524e-004,0,1,0,
1438449603.797,,1.406201e+004,2.000184e+000,2.335898e-004,0.000000e+000,5.394448e-003,0.000000e+000,3,9.811145e-001,1.825000e+000,,,,,,,,,,,,,,,,,,0,4.000000e+000,1.000000e+000,20,1,2.410412e-004,0,1,0,
1438449731.453,,1.506564e+004,1.999357e+000,2.400313e-004,0.000000e+000,5.019843e-003,0.000000e+000,3,9.810421e-001,1.825000e+000,,,,,,,,,,,,,,,,,,0,4.000000e+000,1.000000e+000,20,1,3.194809e-005,0,1,0,
1438449838.718,,1.607013e+004,1.999189e+000,2.454525e-004,0.000000e+000,6.454828e-003,0.000000e+000,3,9.808869e-001,1.825000e+000,,,,,,,,,,,,,,,,,,0,4.000000e+000,1.000000e+000,20,1,9.779930e-004,0,1,0,
1438449914.328,,1.707204e+004,1.999799e+000,2.509116e-004,0.000000e+000,4.696829e-003,0.000000e+000,3,9.822416e-001,1.825000e+000,,,,,,,,,,,,,,,,,,0,4.000000e+000,1.000000e+000,20,1,9.790659e-004,0,1,0,
1438449990.203,,1.807797e+004,2.000207e+000,2.546599e-004,0.000000e+000,8.639093e-003,0.000000e+000,3,9.808834e-001,1.825000e+000,,,,,,,,,,,,,,,,,,0,4.000000e+000,1.000000e+000,20,1,7.389784e-004,0,1,0,
1438450064.109,,1.908246e+004,2.000360e+000,2.571483e-004,0.000000e+000,7.495832e-003,0.000000e+000,3,9.796866e-001,1.825000e+000,,,,,,,,,,,,,,,,,,0,4.000000e+000,1.000000e+000,20,1,6.899834e-004,0,0,0,
1438450140.953,,2.008480e+004,2.000424e+000,2.590129e-004,0.000000e+000,7.185215e-003,0.000000e+000,3,9.802315e-001,1.825000e+000,,,,,,,,,,,,,,,,,,0,4.000000e+000,1.000000e+000,20,1,8.829832e-004,0,0,0,
1438450299.078,,2.409489e+004,2.001365e+000,2.612215e-004,0.000000e+000,7.622411e-003,0.000000e+000,3,9.807755e-001,1.825000e+000,,,,,,,,,,,,,,,,,,0,4.000000e+000,1.000000e+000,20,1,1.221895e-003,0,0,0,
1438450439.718,,2.810856e+004,2.001469e+000,2.557389e-004,0.000000e+000,9.229347e-003,0.000000e+000,3,9.758546e-001,1.825000e+000,,,,,,,,,,,,,,,,,,0,4.000000e+000,1.000000e+000,20,1,3.378391e-004,0,1,0,
1438450618.547,,3.212653e+004,1.998508e+000,2.400519e-004,0.000000e+000,5.934007e-003,0.000000e+000,3,9.745265e-001,1.825000e+000,,,,,,,,,,,,,,,,,,0,4.000000e+000,1.000000e+000,20,1,2.880096e-004,0,1,0,
1438450732.218,,3.614162e+004,1.999702e+000,2.164740e-004,0.000000e+000,6.254811e-003,0.000000e+000,3,9.676643e-001,1.825000e+000,,,,,,,,,,,,,,,,,,0,4.000000e+000,1.000000e+000,20,1,1.204014e-003,0,1,0,
1438450823.609,,4.015816e+004,2.000424e+000,1.889373e-004,0.000000e+000,1.046193e-002,0.000000e+000,3,9.645917e-001,1.825000e+000,,,,,,,,,,,,,,,,,,0,4.000000e+000,1.000000e+000,20,1,1.013041e-003,0,1,0,
1438450915.453,,4.417326e+004,2.000304e+000,1.549975e-004,0.000000e+000,1.100742e-002,0.000000e+000,3,9.634267e-001,1.825000e+000,,,,,,,,,,,,,,,,,,0,4.000000e+000,1.000000e+000,20,1,8.679628e-004,0,0,0,
1438451004.547,,4.819408e+004,2.000385e+000,1.182939e-004,0.000000e+000,1.740750e-002,0.000000e+000,3,9.653859e-001,1.825000e+000,,,,,,,,,,,,,,,,,,0,4.000000e+000,1.000000e+000,20,1,7.710457e-004,0,0,0,
1438451161.750,,5.221061e+004,2.001534e+000,7.605103e-005,0.000000e+000,3.265982e-002,0.000000e+000,3,9.022032e-001,1.825000e+000,,,,,,,,,,,,,,,,,,0,4.000000e+000,1.000000e+000,20,1,1.597404e-005,0,0,0,
1438451294.172,,5.622714e+004,1.999774e+000,3.430125e-005,0.000000e+000,2.706015e-002,0.000000e+000,3,7.838281e-001,1.825000e+000,,,,,,,,,,,,,,,,,,0,4.000000e+000,1.000000e+000,20,1,5.140305e-004,0,1,0,
1438451385.593,,6.024511e+004,1.998805e+000,-1.321669e-005,0.000000e+000,-4.054043e-001,0.000000e+000,3,3.566108e-001,1.825000e+000,,,,,,,,,,,,,,,,,,0,4.000000e+000,1.000000e+000,20,1,7.210970e-004,0,1,0,
1438451475.437,,6.426163e+004,1.999077e+000,-5.890957e-005,0.000000e+000,-6.280930e-002,0.000000e+000,3,8.953544e-001,1.825000e+000,,,,,,,,,,,,,,,,,,0,4.000000e+000,1.000000e+000,20,1,1.073956e-003,0,1,0,
1438451675.718,,6.828103e+004,2.000681e+000,-1.088827e-004,0.000000e+000,-1.877864e-002,0.000000e+000,3,9.425182e-001,1.825000e+000,,,,,,,,,,,,,,,,,,0,4.000000e+000,1.000000e+000,20,1,4.792213e-005,0,1,0,
1438451757.218,,7.028858e+004,2.000055e+000,-1.302095e-004,0.000000e+000,-2.358660e-002,0.000000e+000,3,9.573602e-001,1.825000e+000,,,,,,,,,,,,,,,,,,0,4.000000e+000,1.000000e+000,20,1,1.597404e-005,0,1,0,